[2016-11-20 16:28:33,422] [INFO] [base._load_session] -> No session loaded
[2016-11-20 16:28:33,437] [INFO] [graph.hash] -> hash of template HTTP_GET_MONKEY_1 is -5043506593668091100
[2016-11-20 16:28:33,438] [INFO] [graph.hash] -> hash of model is -7523290697974137846
[2016-11-20 16:28:33,455] [INFO] [base._start_message] -> 
                 --------------------------------------------------
                 Starting fuzzing session
                 Target: TcpTarget
                 UI: WebInterface listening on 0.0.0.0:26000
                 Log: ./kittylogs/kitty_20161120-162832.log

                 Total possible mutation count: 864
                 Fuzzing the mutation range: 0 to 863
                 --------------------------------------------------
                                 Happy hacking
                 --------------------------------------------------
            
[2016-11-20 16:28:33,456] [INFO] [base.start] -> Performing environment test
[2016-11-20 16:28:33,474] [ERROR] [tcp.pre_test] -> Error: Traceback (most recent call last):
  File "/usr/local/lib/python2.7/dist-packages/katnip/targets/tcp.py", line 57, in pre_test
    sock.connect((self.host, self.port))
  File "/usr/lib/python2.7/socket.py", line 224, in meth
    return getattr(self._sock,name)(*args)
error: [Errno 111] Connection refused

[2016-11-20 16:28:33,476] [ERROR] [tcp.pre_test] -> Failed to connect to target server, retrying...
[2016-11-20 16:28:34,480] [INFO] [base._test_info] -> Current test: -1
[2016-11-20 16:28:34,481] [INFO] [server.transmit] -> request(50): 474554202f696e6465782e68746d6c20485454502f312e310d0a486f73743a203132372e302e302e313a383038380d0a0d0a ...
[2016-11-20 16:28:34,483] [INFO] [server._start] -> should keep running? True
[2016-11-20 16:28:34,504] [INFO] [base._test_info] -> Current test: 0
[2016-11-20 16:28:34,506] [INFO] [server.transmit] -> request(53): 474554474554202f696e6465782e68746d6c20485454502f312e310d0a486f73743a203132372e302e302e313a383038380d ...
[2016-11-20 16:28:35,456] [ERROR] [tcp.pre_test] -> Error: Traceback (most recent call last):
  File "/usr/local/lib/python2.7/dist-packages/katnip/targets/tcp.py", line 57, in pre_test
    sock.connect((self.host, self.port))
  File "/usr/lib/python2.7/socket.py", line 224, in meth
    return getattr(self._sock,name)(*args)
error: [Errno 111] Connection refused

[2016-11-20 16:28:35,457] [ERROR] [tcp.pre_test] -> Failed to connect to target server, retrying...
[2016-11-20 16:28:36,461] [INFO] [base._test_info] -> Current test: 1
[2016-11-20 16:28:36,463] [INFO] [server.transmit] -> request(77): 474554474554474554474554474554474554474554474554474554474554202f696e6465782e68746d6c20485454502f312e ...
[2016-11-20 16:28:36,880] [INFO] [base._test_info] -> Current test: 2
[2016-11-20 16:28:36,882] [INFO] [server.transmit] -> request(347): 4745544745544745544745544745544745544745544745544745544745544745544745544745544745544745544745544745 ...
[2016-11-20 16:28:37,810] [ERROR] [tcp.pre_test] -> Error: Traceback (most recent call last):
  File "/usr/local/lib/python2.7/dist-packages/katnip/targets/tcp.py", line 57, in pre_test
    sock.connect((self.host, self.port))
  File "/usr/lib/python2.7/socket.py", line 224, in meth
    return getattr(self._sock,name)(*args)
error: [Errno 111] Connection refused

[2016-11-20 16:28:37,812] [ERROR] [tcp.pre_test] -> Failed to connect to target server, retrying...
[2016-11-20 16:28:38,815] [INFO] [base._test_info] -> Current test: 3
[2016-11-20 16:28:38,817] [INFO] [server.transmit] -> request(51): 474554fe202f696e6465782e68746d6c20485454502f312e310d0a486f73743a203132372e302e302e313a383038380d0a0d ...
[2016-11-20 16:28:39,235] [INFO] [base._test_info] -> Current test: 4
[2016-11-20 16:28:39,239] [INFO] [server.transmit] -> request(51): 00474554202f696e6465782e68746d6c20485454502f312e310d0a486f73743a203132372e302e302e313a383038380d0a0d ...
