[2016-11-20 16:28:44,212] [INFO] [base._load_session] -> No session loaded
[2016-11-20 16:28:44,228] [INFO] [graph.hash] -> hash of template HTTP_GET_MONKEY_1 is -5043506593668091100
[2016-11-20 16:28:44,229] [INFO] [graph.hash] -> hash of model is -7523290697974137846
[2016-11-20 16:28:44,239] [INFO] [base._start_message] -> 
                 --------------------------------------------------
                 Starting fuzzing session
                 Target: TcpTarget
                 UI: WebInterface listening on 0.0.0.0:26000
                 Log: ./kittylogs/kitty_20161120-162843.log

                 Total possible mutation count: 864
                 Fuzzing the mutation range: 0 to 863
                 --------------------------------------------------
                                 Happy hacking
                 --------------------------------------------------
            
[2016-11-20 16:28:44,240] [INFO] [base.start] -> Performing environment test
[2016-11-20 16:28:44,261] [ERROR] [tcp.pre_test] -> Error: Traceback (most recent call last):
  File "/usr/local/lib/python2.7/dist-packages/katnip/targets/tcp.py", line 57, in pre_test
    sock.connect((self.host, self.port))
  File "/usr/lib/python2.7/socket.py", line 224, in meth
    return getattr(self._sock,name)(*args)
error: [Errno 111] Connection refused

[2016-11-20 16:28:44,267] [ERROR] [tcp.pre_test] -> Failed to connect to target server, retrying...
[2016-11-20 16:28:45,272] [INFO] [base._test_info] -> Current test: -1
[2016-11-20 16:28:45,273] [INFO] [server.transmit] -> request(50): 474554202f696e6465782e68746d6c20485454502f312e310d0a486f73743a203132372e302e302e313a383038380d0a0d0a ...
[2016-11-20 16:28:45,275] [INFO] [server._start] -> should keep running? True
[2016-11-20 16:28:45,293] [INFO] [base._test_info] -> Current test: 0
[2016-11-20 16:28:45,297] [INFO] [server.transmit] -> request(53): 474554474554202f696e6465782e68746d6c20485454502f312e310d0a486f73743a203132372e302e302e313a383038380d ...
[2016-11-20 16:28:46,234] [ERROR] [tcp.pre_test] -> Error: Traceback (most recent call last):
  File "/usr/local/lib/python2.7/dist-packages/katnip/targets/tcp.py", line 57, in pre_test
    sock.connect((self.host, self.port))
  File "/usr/lib/python2.7/socket.py", line 224, in meth
    return getattr(self._sock,name)(*args)
error: [Errno 111] Connection refused

[2016-11-20 16:28:46,236] [ERROR] [tcp.pre_test] -> Failed to connect to target server, retrying...
[2016-11-20 16:28:47,241] [INFO] [base._test_info] -> Current test: 1
[2016-11-20 16:28:47,243] [INFO] [server.transmit] -> request(77): 474554474554474554474554474554474554474554474554474554474554202f696e6465782e68746d6c20485454502f312e ...
[2016-11-20 16:28:47,661] [INFO] [base._test_info] -> Current test: 2
[2016-11-20 16:28:47,663] [INFO] [server.transmit] -> request(347): 4745544745544745544745544745544745544745544745544745544745544745544745544745544745544745544745544745 ...
