[2016-11-20 17:19:33,904] [INFO] [base._load_session] -> No session loaded
[2016-11-20 17:19:33,914] [INFO] [graph.hash] -> hash of template HTTP_GET_MONKEY_2 is -7009377807649187563
[2016-11-20 17:19:33,914] [INFO] [graph.hash] -> hash of model is 1860891210470903011
[2016-11-20 17:19:33,916] [INFO] [base._start_message] -> 
                 --------------------------------------------------
                 Starting fuzzing session
                 Target: TcpTarget
                 UI: WebInterface listening on 0.0.0.0:26000
                 Log: ./kittylogs/kitty_20161120-171933.log

                 Total possible mutation count: 1064
                 Fuzzing the mutation range: 0 to 1063
                 --------------------------------------------------
                                 Happy hacking
                 --------------------------------------------------
            
[2016-11-20 17:19:33,917] [INFO] [base.start] -> Performing environment test
[2016-11-20 17:19:33,937] [INFO] [base._test_info] -> Current test: -1
[2016-11-20 17:19:33,938] [INFO] [server.transmit] -> request(87): 474554202f696d67732f6d6f6e6b65795f6c6f676f2e706e6720485454502f312e310d0a486f73743a203132372e302e302e ...
[2016-11-20 17:19:34,460] [INFO] [server._start] -> should keep running? True
[2016-11-20 17:19:34,475] [ERROR] [tcp.pre_test] -> Error: Traceback (most recent call last):
  File "/usr/local/lib/python2.7/dist-packages/katnip/targets/tcp.py", line 57, in pre_test
    sock.connect((self.host, self.port))
  File "/usr/lib/python2.7/socket.py", line 224, in meth
    return getattr(self._sock,name)(*args)
error: [Errno 111] Connection refused

[2016-11-20 17:19:34,479] [ERROR] [tcp.pre_test] -> Failed to connect to target server, retrying...
[2016-11-20 17:19:35,493] [INFO] [base._test_info] -> Current test: 0
[2016-11-20 17:19:35,496] [INFO] [server.transmit] -> request(90): 474554474554202f696d67732f6d6f6e6b65795f6c6f676f2e706e6720485454502f312e310d0a486f73743a203132372e30 ...
[2016-11-20 17:19:35,916] [INFO] [base._test_info] -> Current test: 1
[2016-11-20 17:19:35,918] [INFO] [server.transmit] -> request(114): 474554474554474554474554474554474554474554474554474554474554202f696d67732f6d6f6e6b65795f6c6f676f2e70 ...
[2016-11-20 17:19:36,846] [INFO] [base._test_info] -> Current test: 2
[2016-11-20 17:19:36,852] [INFO] [server.transmit] -> request(384): 4745544745544745544745544745544745544745544745544745544745544745544745544745544745544745544745544745 ...
[2016-11-20 17:19:37,788] [ERROR] [tcp.pre_test] -> Error: Traceback (most recent call last):
  File "/usr/local/lib/python2.7/dist-packages/katnip/targets/tcp.py", line 57, in pre_test
    sock.connect((self.host, self.port))
  File "/usr/lib/python2.7/socket.py", line 224, in meth
    return getattr(self._sock,name)(*args)
error: [Errno 111] Connection refused

[2016-11-20 17:19:37,789] [ERROR] [tcp.pre_test] -> Failed to connect to target server, retrying...
[2016-11-20 17:19:38,794] [INFO] [base._test_info] -> Current test: 3
[2016-11-20 17:19:38,796] [INFO] [server.transmit] -> request(88): 474554fe202f696d67732f6d6f6e6b65795f6c6f676f2e706e6720485454502f312e310d0a486f73743a203132372e302e30 ...
[2016-11-20 17:19:39,221] [INFO] [base._test_info] -> Current test: 4
[2016-11-20 17:19:39,223] [INFO] [server.transmit] -> request(88): 00474554202f696d67732f6d6f6e6b65795f6c6f676f2e706e6720485454502f312e310d0a486f73743a203132372e302e30 ...
[2016-11-20 17:19:40,152] [ERROR] [tcp.pre_test] -> Error: Traceback (most recent call last):
  File "/usr/local/lib/python2.7/dist-packages/katnip/targets/tcp.py", line 57, in pre_test
    sock.connect((self.host, self.port))
  File "/usr/lib/python2.7/socket.py", line 224, in meth
    return getattr(self._sock,name)(*args)
error: [Errno 111] Connection refused

[2016-11-20 17:19:40,153] [ERROR] [tcp.pre_test] -> Failed to connect to target server, retrying...
[2016-11-20 17:19:41,162] [INFO] [base._test_info] -> Current test: 5
[2016-11-20 17:19:41,163] [INFO] [server.transmit] -> request(88): 47004554202f696d67732f6d6f6e6b65795f6c6f676f2e706e6720485454502f312e310d0a486f73743a203132372e302e30 ...
[2016-11-20 17:19:41,581] [INFO] [base._test_info] -> Current test: 6
[2016-11-20 17:19:41,584] [INFO] [server.transmit] -> request(88): 47455400202f696d67732f6d6f6e6b65795f6c6f676f2e706e6720485454502f312e310d0a486f73743a203132372e302e30 ...
[2016-11-20 17:19:42,520] [ERROR] [tcp.pre_test] -> Error: Traceback (most recent call last):
  File "/usr/local/lib/python2.7/dist-packages/katnip/targets/tcp.py", line 57, in pre_test
    sock.connect((self.host, self.port))
  File "/usr/lib/python2.7/socket.py", line 224, in meth
    return getattr(self._sock,name)(*args)
error: [Errno 111] Connection refused

[2016-11-20 17:19:42,520] [ERROR] [tcp.pre_test] -> Failed to connect to target server, retrying...
[2016-11-20 17:19:43,525] [INFO] [base._test_info] -> Current test: 7
[2016-11-20 17:19:43,527] [INFO] [server.transmit] -> request(84): 202f696d67732f6d6f6e6b65795f6c6f676f2e706e6720485454502f312e310d0a486f73743a203132372e302e302e313a38 ...
[2016-11-20 17:19:43,946] [INFO] [base._test_info] -> Current test: 8
[2016-11-20 17:19:43,948] [INFO] [server.transmit] -> request(2132): 2573257325732573257325732573257325732573257325732573257325732573257325732573257325732573257325732573 ...
[2016-11-20 17:19:44,881] [ERROR] [tcp.pre_test] -> Error: Traceback (most recent call last):
  File "/usr/local/lib/python2.7/dist-packages/katnip/targets/tcp.py", line 57, in pre_test
    sock.connect((self.host, self.port))
  File "/usr/lib/python2.7/socket.py", line 224, in meth
    return getattr(self._sock,name)(*args)
error: [Errno 111] Connection refused

[2016-11-20 17:19:44,883] [ERROR] [tcp.pre_test] -> Failed to connect to target server, retrying...
[2016-11-20 17:19:45,888] [INFO] [base._test_info] -> Current test: 9
[2016-11-20 17:19:45,891] [INFO] [server.transmit] -> request(340): 2573257325732573257325732573257325732573257325732573257325732573257325732573257325732573257325732573 ...
[2016-11-20 17:19:46,317] [INFO] [base._test_info] -> Current test: 10
[2016-11-20 17:19:46,322] [INFO] [server.transmit] -> request(116): 2573257325732573257325732573257325732573257325732573257325732573202f696d67732f6d6f6e6b65795f6c6f676f ...
[2016-11-20 17:19:47,249] [ERROR] [tcp.pre_test] -> Error: Traceback (most recent call last):
  File "/usr/local/lib/python2.7/dist-packages/katnip/targets/tcp.py", line 57, in pre_test
    sock.connect((self.host, self.port))
  File "/usr/lib/python2.7/socket.py", line 224, in meth
    return getattr(self._sock,name)(*args)
error: [Errno 111] Connection refused

[2016-11-20 17:19:47,251] [ERROR] [tcp.pre_test] -> Failed to connect to target server, retrying...
[2016-11-20 17:19:48,257] [INFO] [base._test_info] -> Current test: 11
[2016-11-20 17:19:48,259] [INFO] [server.transmit] -> request(88): 25732573202f696d67732f6d6f6e6b65795f6c6f676f2e706e6720485454502f312e310d0a486f73743a203132372e302e30 ...
[2016-11-20 17:19:48,686] [INFO] [base._test_info] -> Current test: 12
[2016-11-20 17:19:48,691] [INFO] [server.transmit] -> request(3156): 2525732525732525732525732525732525732525732525732525732525732525732525732525732525732525732525732525 ...
[2016-11-20 17:19:49,667] [ERROR] [tcp.pre_test] -> Error: Traceback (most recent call last):
  File "/usr/local/lib/python2.7/dist-packages/katnip/targets/tcp.py", line 57, in pre_test
    sock.connect((self.host, self.port))
  File "/usr/lib/python2.7/socket.py", line 224, in meth
    return getattr(self._sock,name)(*args)
error: [Errno 111] Connection refused

[2016-11-20 17:19:49,670] [ERROR] [tcp.pre_test] -> Failed to connect to target server, retrying...
[2016-11-20 17:19:50,684] [INFO] [base._test_info] -> Current test: 13
[2016-11-20 17:19:50,686] [INFO] [server.transmit] -> request(468): 2525732525732525732525732525732525732525732525732525732525732525732525732525732525732525732525732525 ...
[2016-11-20 17:19:51,111] [INFO] [base._test_info] -> Current test: 14
[2016-11-20 17:19:51,118] [INFO] [server.transmit] -> request(132): 252573252573252573252573252573252573252573252573252573252573252573252573252573252573252573252573202f ...
[2016-11-20 17:19:52,073] [ERROR] [tcp.pre_test] -> Error: Traceback (most recent call last):
  File "/usr/local/lib/python2.7/dist-packages/katnip/targets/tcp.py", line 57, in pre_test
    sock.connect((self.host, self.port))
  File "/usr/lib/python2.7/socket.py", line 224, in meth
    return getattr(self._sock,name)(*args)
error: [Errno 111] Connection refused

[2016-11-20 17:19:52,077] [ERROR] [tcp.pre_test] -> Failed to connect to target server, retrying...
[2016-11-20 17:19:52,874] [ERROR] [server._start] -> Error occurred while fuzzing: AttributeError("'WebInterface' object has no attribute '_server'",)
[2016-11-20 17:19:52,877] [ERROR] [server._start] -> Traceback (most recent call last):
  File "/usr/local/lib/python2.7/dist-packages/kitty/fuzzers/server.py", line 43, in _start
    self._run_sequence(sequence)
  File "/usr/local/lib/python2.7/dist-packages/kitty/fuzzers/server.py", line 64, in _run_sequence
    self._pre_test()
  File "/usr/local/lib/python2.7/dist-packages/kitty/fuzzers/base.py", line 332, in _pre_test
    self.target.pre_test(self.model.current_index())
  File "/usr/local/lib/python2.7/dist-packages/katnip/targets/tcp.py", line 63, in pre_test
    time.sleep(1)
  File "/usr/local/lib/python2.7/dist-packages/kitty/fuzzers/base.py", line 504, in _exit_now
    self.stop()
  File "/usr/local/lib/python2.7/dist-packages/kitty/fuzzers/base.py", line 440, in stop
    self.user_interface.stop()
  File "/usr/local/lib/python2.7/dist-packages/kitty/interfaces/base.py", line 101, in stop
    self._stop()
  File "/usr/local/lib/python2.7/dist-packages/kitty/interfaces/web.py", line 297, in _stop
    self._server.shutdown()
AttributeError: 'WebInterface' object has no attribute '_server'

[2016-11-20 17:19:52,880] [INFO] [base._end_message] -> 
                         --------------------------------------------------
                         Finished fuzzing session
                         Target: TcpTarget

                         Tested 16 mutations
                         Mutation range: 0 to 15
                         Failure count: 0
                         --------------------------------------------------
            
