[2016-11-18 14:53:28,915] [INFO] [base._load_session] -> No session loaded
[2016-11-18 14:53:28,916] [INFO] [graph.hash] -> hash of template HTTP_GET_REQUEST_BYTE_RANGE is -3389487266823754318
[2016-11-18 14:53:28,916] [INFO] [graph.hash] -> hash of model is -7253090768596029706
[2016-11-18 14:53:28,917] [INFO] [base._start_message] -> 
                 --------------------------------------------------
                 Starting fuzzing session
                 Target: TcpTarget
                 UI: WebInterface listening on 0.0.0.0:26000
                 Log: ./kittylogs/kitty_20161118-145328.log

                 Total possible mutation count: 338
                 Fuzzing the mutation range: 0 to 337
                 --------------------------------------------------
                                 Happy hacking
                 --------------------------------------------------
            
[2016-11-18 14:53:28,918] [INFO] [base.start] -> Performing environment test
[2016-11-18 14:53:28,922] [ERROR] [tcp.pre_test] -> Error: Traceback (most recent call last):
  File "/usr/local/lib/python2.7/dist-packages/katnip/targets/tcp.py", line 57, in pre_test
    sock.connect((self.host, self.port))
  File "/usr/lib/python2.7/socket.py", line 224, in meth
    return getattr(self._sock,name)(*args)
error: [Errno 111] Connection refused

[2016-11-18 14:53:28,922] [ERROR] [tcp.pre_test] -> Failed to connect to target server, retrying...
[2016-11-18 14:53:29,924] [ERROR] [tcp.pre_test] -> Error: Traceback (most recent call last):
  File "/usr/local/lib/python2.7/dist-packages/katnip/targets/tcp.py", line 57, in pre_test
    sock.connect((self.host, self.port))
  File "/usr/lib/python2.7/socket.py", line 224, in meth
    return getattr(self._sock,name)(*args)
error: [Errno 111] Connection refused

[2016-11-18 14:53:29,924] [ERROR] [tcp.pre_test] -> Failed to connect to target server, retrying...
[2016-11-18 14:53:30,926] [ERROR] [tcp.pre_test] -> Error: Traceback (most recent call last):
  File "/usr/local/lib/python2.7/dist-packages/katnip/targets/tcp.py", line 57, in pre_test
    sock.connect((self.host, self.port))
  File "/usr/lib/python2.7/socket.py", line 224, in meth
    return getattr(self._sock,name)(*args)
error: [Errno 111] Connection refused

[2016-11-18 14:53:30,927] [ERROR] [tcp.pre_test] -> Failed to connect to target server, retrying...
[2016-11-18 14:53:31,929] [ERROR] [tcp.pre_test] -> Error: Traceback (most recent call last):
  File "/usr/local/lib/python2.7/dist-packages/katnip/targets/tcp.py", line 57, in pre_test
    sock.connect((self.host, self.port))
  File "/usr/lib/python2.7/socket.py", line 224, in meth
    return getattr(self._sock,name)(*args)
error: [Errno 111] Connection refused

[2016-11-18 14:53:31,930] [ERROR] [tcp.pre_test] -> Failed to connect to target server, retrying...
[2016-11-18 14:53:32,932] [ERROR] [tcp.pre_test] -> Error: Traceback (most recent call last):
  File "/usr/local/lib/python2.7/dist-packages/katnip/targets/tcp.py", line 57, in pre_test
    sock.connect((self.host, self.port))
  File "/usr/lib/python2.7/socket.py", line 224, in meth
    return getattr(self._sock,name)(*args)
error: [Errno 111] Connection refused

[2016-11-18 14:53:32,932] [ERROR] [tcp.pre_test] -> Failed to connect to target server, retrying...
[2016-11-18 14:53:33,934] [ERROR] [tcp.pre_test] -> Error: Traceback (most recent call last):
  File "/usr/local/lib/python2.7/dist-packages/katnip/targets/tcp.py", line 57, in pre_test
    sock.connect((self.host, self.port))
  File "/usr/lib/python2.7/socket.py", line 224, in meth
    return getattr(self._sock,name)(*args)
error: [Errno 111] Connection refused

[2016-11-18 14:53:33,934] [ERROR] [tcp.pre_test] -> Failed to connect to target server, retrying...
[2016-11-18 14:53:34,935] [ERROR] [tcp.pre_test] -> Error: Traceback (most recent call last):
  File "/usr/local/lib/python2.7/dist-packages/katnip/targets/tcp.py", line 57, in pre_test
    sock.connect((self.host, self.port))
  File "/usr/lib/python2.7/socket.py", line 224, in meth
    return getattr(self._sock,name)(*args)
error: [Errno 111] Connection refused

[2016-11-18 14:53:34,935] [ERROR] [tcp.pre_test] -> Failed to connect to target server, retrying...
[2016-11-18 14:53:35,937] [ERROR] [tcp.pre_test] -> Error: Traceback (most recent call last):
  File "/usr/local/lib/python2.7/dist-packages/katnip/targets/tcp.py", line 57, in pre_test
    sock.connect((self.host, self.port))
  File "/usr/lib/python2.7/socket.py", line 224, in meth
    return getattr(self._sock,name)(*args)
error: [Errno 111] Connection refused

[2016-11-18 14:53:35,937] [ERROR] [tcp.pre_test] -> Failed to connect to target server, retrying...
[2016-11-18 14:53:36,336] [INFO] [server._test_environment] -> Environment test failed
