[2016-11-20 16:24:02,633] [INFO] [base._load_session] -> No session loaded
[2016-11-20 16:24:02,643] [INFO] [graph.hash] -> hash of template HTTP_GET_MONKEY_0 is 8838694776458258670
[2016-11-20 16:24:02,643] [INFO] [graph.hash] -> hash of model is -1278885161537104449
[2016-11-20 16:24:02,645] [INFO] [base._start_message] -> 
                 --------------------------------------------------
                 Starting fuzzing session
                 Target: TcpTarget
                 UI: WebInterface listening on 0.0.0.0:26000
                 Log: ./kittylogs/kitty_20161120-162401.log

                 Total possible mutation count: 247
                 Fuzzing the mutation range: 0 to 246
                 --------------------------------------------------
                                 Happy hacking
                 --------------------------------------------------
            
[2016-11-20 16:24:02,646] [INFO] [base.start] -> Performing environment test
[2016-11-20 16:24:02,669] [INFO] [base._test_info] -> Current test: -1
[2016-11-20 16:24:02,671] [INFO] [server.transmit] -> request(28): 474554202f696e6465782e68746d6c20485454502f312e310d0a0d0a
[2016-11-20 16:24:03,191] [INFO] [server._start] -> should keep running? True
[2016-11-20 16:24:03,202] [ERROR] [tcp.pre_test] -> Error: Traceback (most recent call last):
  File "/usr/local/lib/python2.7/dist-packages/katnip/targets/tcp.py", line 57, in pre_test
    sock.connect((self.host, self.port))
  File "/usr/lib/python2.7/socket.py", line 224, in meth
    return getattr(self._sock,name)(*args)
error: [Errno 111] Connection refused

[2016-11-20 16:24:03,210] [ERROR] [tcp.pre_test] -> Failed to connect to target server, retrying...
[2016-11-20 16:24:04,215] [INFO] [base._test_info] -> Current test: 0
[2016-11-20 16:24:04,217] [INFO] [server.transmit] -> request(29): 47455420202f696e6465782e68746d6c20485454502f312e310d0a0d0a
[2016-11-20 16:24:04,633] [INFO] [base._test_info] -> Current test: 1
[2016-11-20 16:24:04,636] [INFO] [server.transmit] -> request(37): 474554202020202020202020202f696e6465782e68746d6c20485454502f312e310d0a0d0a
[2016-11-20 16:24:05,558] [ERROR] [tcp.pre_test] -> Error: Traceback (most recent call last):
  File "/usr/local/lib/python2.7/dist-packages/katnip/targets/tcp.py", line 57, in pre_test
    sock.connect((self.host, self.port))
  File "/usr/lib/python2.7/socket.py", line 224, in meth
    return getattr(self._sock,name)(*args)
error: [Errno 111] Connection refused

[2016-11-20 16:24:05,559] [ERROR] [tcp.pre_test] -> Failed to connect to target server, retrying...
[2016-11-20 16:24:06,563] [INFO] [base._test_info] -> Current test: 2
[2016-11-20 16:24:06,564] [INFO] [server.transmit] -> request(127): 4745542020202020202020202020202020202020202020202020202020202020202020202020202020202020202020202020 ...
[2016-11-20 16:24:06,984] [INFO] [base._test_info] -> Current test: 3
[2016-11-20 16:24:06,986] [INFO] [server.transmit] -> request(29): 47455420fe2f696e6465782e68746d6c20485454502f312e310d0a0d0a
[2016-11-20 16:24:07,919] [ERROR] [tcp.pre_test] -> Error: Traceback (most recent call last):
  File "/usr/local/lib/python2.7/dist-packages/katnip/targets/tcp.py", line 57, in pre_test
    sock.connect((self.host, self.port))
  File "/usr/lib/python2.7/socket.py", line 224, in meth
    return getattr(self._sock,name)(*args)
error: [Errno 111] Connection refused

[2016-11-20 16:24:07,921] [ERROR] [tcp.pre_test] -> Failed to connect to target server, retrying...
[2016-11-20 16:24:08,925] [INFO] [base._test_info] -> Current test: 4
[2016-11-20 16:24:08,927] [INFO] [server.transmit] -> request(29): 47455400202f696e6465782e68746d6c20485454502f312e310d0a0d0a
[2016-11-20 16:24:09,347] [INFO] [base._test_info] -> Current test: 6
[2016-11-20 16:24:09,352] [INFO] [server.transmit] -> request(29): 47455420002f696e6465782e68746d6c20485454502f312e310d0a0d0a
[2016-11-20 16:24:10,281] [ERROR] [tcp.pre_test] -> Error: Traceback (most recent call last):
  File "/usr/local/lib/python2.7/dist-packages/katnip/targets/tcp.py", line 57, in pre_test
    sock.connect((self.host, self.port))
  File "/usr/lib/python2.7/socket.py", line 224, in meth
    return getattr(self._sock,name)(*args)
error: [Errno 111] Connection refused

[2016-11-20 16:24:10,283] [ERROR] [tcp.pre_test] -> Failed to connect to target server, retrying...
[2016-11-20 16:24:11,287] [INFO] [base._test_info] -> Current test: 7
[2016-11-20 16:24:11,288] [INFO] [server.transmit] -> request(31): 474554202020202f696e6465782e68746d6c20485454502f312e310d0a0d0a
[2016-11-20 16:24:11,703] [INFO] [base._test_info] -> Current test: 8
[2016-11-20 16:24:11,707] [INFO] [server.transmit] -> request(31): 474554090909092f696e6465782e68746d6c20485454502f312e310d0a0d0a
[2016-11-20 16:24:12,640] [INFO] [base._test_info] -> Current test: 9
[2016-11-20 16:24:12,642] [INFO] [server.transmit] -> request(31): 474554212121212f696e6465782e68746d6c20485454502f312e310d0a0d0a
[2016-11-20 16:24:13,566] [ERROR] [tcp.pre_test] -> Error: Traceback (most recent call last):
  File "/usr/local/lib/python2.7/dist-packages/katnip/targets/tcp.py", line 57, in pre_test
    sock.connect((self.host, self.port))
  File "/usr/lib/python2.7/socket.py", line 224, in meth
    return getattr(self._sock,name)(*args)
error: [Errno 111] Connection refused

[2016-11-20 16:24:13,567] [ERROR] [tcp.pre_test] -> Failed to connect to target server, retrying...
[2016-11-20 16:24:14,572] [INFO] [base._test_info] -> Current test: 10
[2016-11-20 16:24:14,575] [INFO] [server.transmit] -> request(31): 474554404040402f696e6465782e68746d6c20485454502f312e310d0a0d0a
[2016-11-20 16:24:14,993] [INFO] [base._test_info] -> Current test: 11
[2016-11-20 16:24:14,995] [INFO] [server.transmit] -> request(31): 474554232323232f696e6465782e68746d6c20485454502f312e310d0a0d0a
[2016-11-20 16:24:15,926] [ERROR] [tcp.pre_test] -> Error: Traceback (most recent call last):
  File "/usr/local/lib/python2.7/dist-packages/katnip/targets/tcp.py", line 57, in pre_test
    sock.connect((self.host, self.port))
  File "/usr/lib/python2.7/socket.py", line 224, in meth
    return getattr(self._sock,name)(*args)
error: [Errno 111] Connection refused

[2016-11-20 16:24:15,927] [ERROR] [tcp.pre_test] -> Failed to connect to target server, retrying...
[2016-11-20 16:24:16,930] [INFO] [base._test_info] -> Current test: 12
[2016-11-20 16:24:16,932] [INFO] [server.transmit] -> request(31): 474554242424242f696e6465782e68746d6c20485454502f312e310d0a0d0a
[2016-11-20 16:24:17,350] [INFO] [base._test_info] -> Current test: 13
[2016-11-20 16:24:17,352] [INFO] [server.transmit] -> request(31): 474554252525252f696e6465782e68746d6c20485454502f312e310d0a0d0a
[2016-11-20 16:24:18,273] [ERROR] [tcp.pre_test] -> Error: Traceback (most recent call last):
  File "/usr/local/lib/python2.7/dist-packages/katnip/targets/tcp.py", line 57, in pre_test
    sock.connect((self.host, self.port))
  File "/usr/lib/python2.7/socket.py", line 224, in meth
    return getattr(self._sock,name)(*args)
error: [Errno 111] Connection refused

[2016-11-20 16:24:18,275] [ERROR] [tcp.pre_test] -> Failed to connect to target server, retrying...
[2016-11-20 16:24:19,279] [INFO] [base._test_info] -> Current test: 14
[2016-11-20 16:24:19,282] [INFO] [server.transmit] -> request(31): 4745545e5e5e5e2f696e6465782e68746d6c20485454502f312e310d0a0d0a
[2016-11-20 16:24:19,701] [INFO] [base._test_info] -> Current test: 15
[2016-11-20 16:24:19,705] [INFO] [server.transmit] -> request(31): 474554262626262f696e6465782e68746d6c20485454502f312e310d0a0d0a
[2016-11-20 16:24:20,633] [ERROR] [tcp.pre_test] -> Error: Traceback (most recent call last):
  File "/usr/local/lib/python2.7/dist-packages/katnip/targets/tcp.py", line 57, in pre_test
    sock.connect((self.host, self.port))
  File "/usr/lib/python2.7/socket.py", line 224, in meth
    return getattr(self._sock,name)(*args)
error: [Errno 111] Connection refused

[2016-11-20 16:24:20,635] [ERROR] [tcp.pre_test] -> Failed to connect to target server, retrying...
[2016-11-20 16:24:21,639] [INFO] [base._test_info] -> Current test: 16
[2016-11-20 16:24:21,640] [INFO] [server.transmit] -> request(31): 4745542a2a2a2a2f696e6465782e68746d6c20485454502f312e310d0a0d0a
[2016-11-20 16:24:22,055] [INFO] [base._test_info] -> Current test: 17
[2016-11-20 16:24:22,057] [INFO] [server.transmit] -> request(31): 474554282828282f696e6465782e68746d6c20485454502f312e310d0a0d0a
[2016-11-20 16:24:22,978] [ERROR] [tcp.pre_test] -> Error: Traceback (most recent call last):
  File "/usr/local/lib/python2.7/dist-packages/katnip/targets/tcp.py", line 57, in pre_test
    sock.connect((self.host, self.port))
  File "/usr/lib/python2.7/socket.py", line 224, in meth
    return getattr(self._sock,name)(*args)
error: [Errno 111] Connection refused

[2016-11-20 16:24:22,980] [ERROR] [tcp.pre_test] -> Failed to connect to target server, retrying...
[2016-11-20 16:24:23,983] [INFO] [base._test_info] -> Current test: 18
[2016-11-20 16:24:23,984] [INFO] [server.transmit] -> request(31): 474554292929292f696e6465782e68746d6c20485454502f312e310d0a0d0a
[2016-11-20 16:24:24,398] [INFO] [base._test_info] -> Current test: 19
[2016-11-20 16:24:24,399] [INFO] [server.transmit] -> request(31): 4745542d2d2d2d2f696e6465782e68746d6c20485454502f312e310d0a0d0a
[2016-11-20 16:24:25,324] [ERROR] [tcp.pre_test] -> Error: Traceback (most recent call last):
  File "/usr/local/lib/python2.7/dist-packages/katnip/targets/tcp.py", line 57, in pre_test
    sock.connect((self.host, self.port))
  File "/usr/lib/python2.7/socket.py", line 224, in meth
    return getattr(self._sock,name)(*args)
error: [Errno 111] Connection refused

[2016-11-20 16:24:25,326] [ERROR] [tcp.pre_test] -> Failed to connect to target server, retrying...
[2016-11-20 16:24:26,331] [INFO] [base._test_info] -> Current test: 20
[2016-11-20 16:24:26,332] [INFO] [server.transmit] -> request(31): 4745545f5f5f5f2f696e6465782e68746d6c20485454502f312e310d0a0d0a
[2016-11-20 16:24:26,755] [INFO] [base._test_info] -> Current test: 21
[2016-11-20 16:24:26,759] [INFO] [server.transmit] -> request(31): 4745542b2b2b2b2f696e6465782e68746d6c20485454502f312e310d0a0d0a
[2016-11-20 16:24:27,683] [ERROR] [tcp.pre_test] -> Error: Traceback (most recent call last):
  File "/usr/local/lib/python2.7/dist-packages/katnip/targets/tcp.py", line 57, in pre_test
    sock.connect((self.host, self.port))
  File "/usr/lib/python2.7/socket.py", line 224, in meth
    return getattr(self._sock,name)(*args)
error: [Errno 111] Connection refused

[2016-11-20 16:24:27,684] [ERROR] [tcp.pre_test] -> Failed to connect to target server, retrying...
[2016-11-20 16:24:28,690] [INFO] [base._test_info] -> Current test: 22
[2016-11-20 16:24:28,691] [INFO] [server.transmit] -> request(31): 4745543d3d3d3d2f696e6465782e68746d6c20485454502f312e310d0a0d0a
[2016-11-20 16:24:29,112] [INFO] [base._test_info] -> Current test: 23
[2016-11-20 16:24:29,114] [INFO] [server.transmit] -> request(31): 4745543a3a3a3a2f696e6465782e68746d6c20485454502f312e310d0a0d0a
[2016-11-20 16:24:30,043] [INFO] [base._test_info] -> Current test: 24
[2016-11-20 16:24:30,045] [INFO] [server.transmit] -> request(31): 4745543b3b3b3b2f696e6465782e68746d6c20485454502f312e310d0a0d0a
[2016-11-20 16:24:30,976] [ERROR] [tcp.pre_test] -> Error: Traceback (most recent call last):
  File "/usr/local/lib/python2.7/dist-packages/katnip/targets/tcp.py", line 57, in pre_test
    sock.connect((self.host, self.port))
  File "/usr/lib/python2.7/socket.py", line 224, in meth
    return getattr(self._sock,name)(*args)
error: [Errno 111] Connection refused

[2016-11-20 16:24:30,977] [ERROR] [tcp.pre_test] -> Failed to connect to target server, retrying...
[2016-11-20 16:24:31,982] [INFO] [base._test_info] -> Current test: 25
[2016-11-20 16:24:31,983] [INFO] [server.transmit] -> request(31): 474554272727272f696e6465782e68746d6c20485454502f312e310d0a0d0a
[2016-11-20 16:24:32,400] [INFO] [base._test_info] -> Current test: 26
[2016-11-20 16:24:32,402] [INFO] [server.transmit] -> request(31): 474554222222222f696e6465782e68746d6c20485454502f312e310d0a0d0a
[2016-11-20 16:24:33,326] [ERROR] [tcp.pre_test] -> Error: Traceback (most recent call last):
  File "/usr/local/lib/python2.7/dist-packages/katnip/targets/tcp.py", line 57, in pre_test
    sock.connect((self.host, self.port))
  File "/usr/lib/python2.7/socket.py", line 224, in meth
    return getattr(self._sock,name)(*args)
error: [Errno 111] Connection refused

[2016-11-20 16:24:33,328] [ERROR] [tcp.pre_test] -> Failed to connect to target server, retrying...
[2016-11-20 16:24:34,331] [INFO] [base._test_info] -> Current test: 27
[2016-11-20 16:24:34,332] [INFO] [server.transmit] -> request(31): 4745542f2f2f2f2f696e6465782e68746d6c20485454502f312e310d0a0d0a
[2016-11-20 16:24:34,747] [INFO] [base._test_info] -> Current test: 28
[2016-11-20 16:24:34,751] [INFO] [server.transmit] -> request(31): 4745545c5c5c5c2f696e6465782e68746d6c20485454502f312e310d0a0d0a
[2016-11-20 16:24:35,675] [INFO] [base._test_info] -> Current test: 29
[2016-11-20 16:24:35,677] [INFO] [server.transmit] -> request(31): 4745543f3f3f3f2f696e6465782e68746d6c20485454502f312e310d0a0d0a
[2016-11-20 16:24:36,599] [ERROR] [tcp.pre_test] -> Error: Traceback (most recent call last):
  File "/usr/local/lib/python2.7/dist-packages/katnip/targets/tcp.py", line 57, in pre_test
    sock.connect((self.host, self.port))
  File "/usr/lib/python2.7/socket.py", line 224, in meth
    return getattr(self._sock,name)(*args)
error: [Errno 111] Connection refused

[2016-11-20 16:24:36,600] [ERROR] [tcp.pre_test] -> Failed to connect to target server, retrying...
[2016-11-20 16:24:37,605] [INFO] [base._test_info] -> Current test: 30
[2016-11-20 16:24:37,606] [INFO] [server.transmit] -> request(31): 4745543c3c3c3c2f696e6465782e68746d6c20485454502f312e310d0a0d0a
[2016-11-20 16:24:38,026] [INFO] [base._test_info] -> Current test: 31
[2016-11-20 16:24:38,028] [INFO] [server.transmit] -> request(31): 4745543e3e3e3e2f696e6465782e68746d6c20485454502f312e310d0a0d0a
[2016-11-20 16:24:38,950] [ERROR] [tcp.pre_test] -> Error: Traceback (most recent call last):
  File "/usr/local/lib/python2.7/dist-packages/katnip/targets/tcp.py", line 57, in pre_test
    sock.connect((self.host, self.port))
  File "/usr/lib/python2.7/socket.py", line 224, in meth
    return getattr(self._sock,name)(*args)
error: [Errno 111] Connection refused

[2016-11-20 16:24:38,952] [ERROR] [tcp.pre_test] -> Failed to connect to target server, retrying...
[2016-11-20 16:24:39,956] [INFO] [base._test_info] -> Current test: 32
[2016-11-20 16:24:39,958] [INFO] [server.transmit] -> request(31): 4745542e2e2e2e2f696e6465782e68746d6c20485454502f312e310d0a0d0a
[2016-11-20 16:24:40,376] [INFO] [base._test_info] -> Current test: 33
[2016-11-20 16:24:40,378] [INFO] [server.transmit] -> request(31): 4745542c2c2c2c2f696e6465782e68746d6c20485454502f312e310d0a0d0a
[2016-11-20 16:24:41,301] [ERROR] [tcp.pre_test] -> Error: Traceback (most recent call last):
  File "/usr/local/lib/python2.7/dist-packages/katnip/targets/tcp.py", line 57, in pre_test
    sock.connect((self.host, self.port))
  File "/usr/lib/python2.7/socket.py", line 224, in meth
    return getattr(self._sock,name)(*args)
error: [Errno 111] Connection refused

[2016-11-20 16:24:41,303] [ERROR] [tcp.pre_test] -> Failed to connect to target server, retrying...
[2016-11-20 16:24:42,308] [INFO] [base._test_info] -> Current test: 34
[2016-11-20 16:24:42,311] [INFO] [server.transmit] -> request(31): 4745540d0d0d0d2f696e6465782e68746d6c20485454502f312e310d0a0d0a
[2016-11-20 16:24:42,728] [INFO] [base._test_info] -> Current test: 35
[2016-11-20 16:24:42,729] [INFO] [server.transmit] -> request(31): 4745540a0a0a0a2f696e6465782e68746d6c20485454502f312e310d0a0d0a
[2016-11-20 16:24:43,651] [INFO] [base._test_info] -> Current test: 36
[2016-11-20 16:24:43,655] [INFO] [server.transmit] -> request(43): 4745540d0a0d0a0d0a0d0a0d0a0d0a0d0a0d0a2f696e6465782e68746d6c20485454502f312e310d0a0d0a
[2016-11-20 16:24:44,584] [ERROR] [tcp.pre_test] -> Error: Traceback (most recent call last):
  File "/usr/local/lib/python2.7/dist-packages/katnip/targets/tcp.py", line 57, in pre_test
    sock.connect((self.host, self.port))
  File "/usr/lib/python2.7/socket.py", line 224, in meth
    return getattr(self._sock,name)(*args)
error: [Errno 111] Connection refused

[2016-11-20 16:24:44,585] [ERROR] [tcp.pre_test] -> Failed to connect to target server, retrying...
[2016-11-20 16:24:45,590] [INFO] [base._test_info] -> Current test: 37
[2016-11-20 16:24:45,593] [INFO] [server.transmit] -> request(51): 474554090d0a090d0a090d0a090d0a090d0a090d0a090d0a090d0a2f696e6465782e68746d6c20485454502f312e310d0a0d ...
[2016-11-20 16:24:46,011] [INFO] [base._test_info] -> Current test: 38
[2016-11-20 16:24:46,014] [INFO] [server.transmit] -> request(27): 4745542f696e6465782e68746d6c20485454502f312e310d0a0d0a
[2016-11-20 16:24:46,939] [ERROR] [tcp.pre_test] -> Error: Traceback (most recent call last):
  File "/usr/local/lib/python2.7/dist-packages/katnip/targets/tcp.py", line 57, in pre_test
    sock.connect((self.host, self.port))
  File "/usr/lib/python2.7/socket.py", line 224, in meth
    return getattr(self._sock,name)(*args)
error: [Errno 111] Connection refused

[2016-11-20 16:24:46,941] [ERROR] [tcp.pre_test] -> Failed to connect to target server, retrying...
[2016-11-20 16:24:47,944] [INFO] [base._test_info] -> Current test: 39
[2016-11-20 16:24:47,947] [INFO] [server.transmit] -> request(29): 474554202f696e6465782e68746d6c2020485454502f312e310d0a0d0a
[2016-11-20 16:24:48,367] [INFO] [base._test_info] -> Current test: 40
[2016-11-20 16:24:48,369] [INFO] [server.transmit] -> request(37): 474554202f696e6465782e68746d6c20202020202020202020485454502f312e310d0a0d0a
[2016-11-20 16:24:49,297] [ERROR] [tcp.pre_test] -> Error: Traceback (most recent call last):
  File "/usr/local/lib/python2.7/dist-packages/katnip/targets/tcp.py", line 57, in pre_test
    sock.connect((self.host, self.port))
  File "/usr/lib/python2.7/socket.py", line 224, in meth
    return getattr(self._sock,name)(*args)
error: [Errno 111] Connection refused

[2016-11-20 16:24:49,300] [ERROR] [tcp.pre_test] -> Failed to connect to target server, retrying...
[2016-11-20 16:24:50,305] [INFO] [base._test_info] -> Current test: 41
[2016-11-20 16:24:50,306] [INFO] [server.transmit] -> request(127): 474554202f696e6465782e68746d6c2020202020202020202020202020202020202020202020202020202020202020202020 ...
[2016-11-20 16:24:50,724] [INFO] [base._test_info] -> Current test: 42
[2016-11-20 16:24:50,727] [INFO] [server.transmit] -> request(29): 474554202f696e6465782e68746d6c20fe485454502f312e310d0a0d0a
[2016-11-20 16:24:51,658] [ERROR] [tcp.pre_test] -> Error: Traceback (most recent call last):
  File "/usr/local/lib/python2.7/dist-packages/katnip/targets/tcp.py", line 57, in pre_test
    sock.connect((self.host, self.port))
  File "/usr/lib/python2.7/socket.py", line 224, in meth
    return getattr(self._sock,name)(*args)
error: [Errno 111] Connection refused

[2016-11-20 16:24:51,659] [ERROR] [tcp.pre_test] -> Failed to connect to target server, retrying...
[2016-11-20 16:24:52,663] [INFO] [base._test_info] -> Current test: 43
[2016-11-20 16:24:52,665] [INFO] [server.transmit] -> request(29): 474554202f696e6465782e68746d6c0020485454502f312e310d0a0d0a
[2016-11-20 16:24:53,081] [INFO] [base._test_info] -> Current test: 45
[2016-11-20 16:24:53,085] [INFO] [server.transmit] -> request(29): 474554202f696e6465782e68746d6c2000485454502f312e310d0a0d0a
[2016-11-20 16:24:54,015] [ERROR] [tcp.pre_test] -> Error: Traceback (most recent call last):
  File "/usr/local/lib/python2.7/dist-packages/katnip/targets/tcp.py", line 57, in pre_test
    sock.connect((self.host, self.port))
  File "/usr/lib/python2.7/socket.py", line 224, in meth
    return getattr(self._sock,name)(*args)
error: [Errno 111] Connection refused

[2016-11-20 16:24:54,016] [ERROR] [tcp.pre_test] -> Failed to connect to target server, retrying...
[2016-11-20 16:24:55,021] [INFO] [base._test_info] -> Current test: 46
[2016-11-20 16:24:55,023] [INFO] [server.transmit] -> request(31): 474554202f696e6465782e68746d6c20202020485454502f312e310d0a0d0a
[2016-11-20 16:24:55,437] [INFO] [base._test_info] -> Current test: 47
[2016-11-20 16:24:55,439] [INFO] [server.transmit] -> request(31): 474554202f696e6465782e68746d6c09090909485454502f312e310d0a0d0a
[2016-11-20 16:24:56,361] [ERROR] [tcp.pre_test] -> Error: Traceback (most recent call last):
  File "/usr/local/lib/python2.7/dist-packages/katnip/targets/tcp.py", line 57, in pre_test
    sock.connect((self.host, self.port))
  File "/usr/lib/python2.7/socket.py", line 224, in meth
    return getattr(self._sock,name)(*args)
error: [Errno 111] Connection refused

[2016-11-20 16:24:56,364] [ERROR] [tcp.pre_test] -> Failed to connect to target server, retrying...
[2016-11-20 16:24:57,368] [INFO] [base._test_info] -> Current test: 48
[2016-11-20 16:24:57,370] [INFO] [server.transmit] -> request(31): 474554202f696e6465782e68746d6c21212121485454502f312e310d0a0d0a
[2016-11-20 16:24:57,785] [INFO] [base._test_info] -> Current test: 49
[2016-11-20 16:24:57,787] [INFO] [server.transmit] -> request(31): 474554202f696e6465782e68746d6c40404040485454502f312e310d0a0d0a
[2016-11-20 16:24:58,713] [ERROR] [tcp.pre_test] -> Error: Traceback (most recent call last):
  File "/usr/local/lib/python2.7/dist-packages/katnip/targets/tcp.py", line 57, in pre_test
    sock.connect((self.host, self.port))
  File "/usr/lib/python2.7/socket.py", line 224, in meth
    return getattr(self._sock,name)(*args)
error: [Errno 111] Connection refused

[2016-11-20 16:24:58,716] [ERROR] [tcp.pre_test] -> Failed to connect to target server, retrying...
[2016-11-20 16:24:59,719] [INFO] [base._test_info] -> Current test: 50
[2016-11-20 16:24:59,720] [INFO] [server.transmit] -> request(31): 474554202f696e6465782e68746d6c23232323485454502f312e310d0a0d0a
[2016-11-20 16:25:00,136] [INFO] [base._test_info] -> Current test: 51
[2016-11-20 16:25:00,138] [INFO] [server.transmit] -> request(31): 474554202f696e6465782e68746d6c24242424485454502f312e310d0a0d0a
[2016-11-20 16:25:01,063] [ERROR] [tcp.pre_test] -> Error: Traceback (most recent call last):
  File "/usr/local/lib/python2.7/dist-packages/katnip/targets/tcp.py", line 57, in pre_test
    sock.connect((self.host, self.port))
  File "/usr/lib/python2.7/socket.py", line 224, in meth
    return getattr(self._sock,name)(*args)
error: [Errno 111] Connection refused

[2016-11-20 16:25:01,064] [ERROR] [tcp.pre_test] -> Failed to connect to target server, retrying...
[2016-11-20 16:25:02,070] [INFO] [base._test_info] -> Current test: 52
[2016-11-20 16:25:02,072] [INFO] [server.transmit] -> request(31): 474554202f696e6465782e68746d6c25252525485454502f312e310d0a0d0a
[2016-11-20 16:25:02,490] [INFO] [base._test_info] -> Current test: 53
[2016-11-20 16:25:02,492] [INFO] [server.transmit] -> request(31): 474554202f696e6465782e68746d6c5e5e5e5e485454502f312e310d0a0d0a
[2016-11-20 16:25:03,416] [ERROR] [tcp.pre_test] -> Error: Traceback (most recent call last):
  File "/usr/local/lib/python2.7/dist-packages/katnip/targets/tcp.py", line 57, in pre_test
    sock.connect((self.host, self.port))
  File "/usr/lib/python2.7/socket.py", line 224, in meth
    return getattr(self._sock,name)(*args)
error: [Errno 111] Connection refused

[2016-11-20 16:25:03,418] [ERROR] [tcp.pre_test] -> Failed to connect to target server, retrying...
[2016-11-20 16:25:04,422] [INFO] [base._test_info] -> Current test: 54
[2016-11-20 16:25:04,424] [INFO] [server.transmit] -> request(31): 474554202f696e6465782e68746d6c26262626485454502f312e310d0a0d0a
[2016-11-20 16:25:04,843] [INFO] [base._test_info] -> Current test: 55
[2016-11-20 16:25:04,847] [INFO] [server.transmit] -> request(31): 474554202f696e6465782e68746d6c2a2a2a2a485454502f312e310d0a0d0a
[2016-11-20 16:25:05,781] [ERROR] [tcp.pre_test] -> Error: Traceback (most recent call last):
  File "/usr/local/lib/python2.7/dist-packages/katnip/targets/tcp.py", line 57, in pre_test
    sock.connect((self.host, self.port))
  File "/usr/lib/python2.7/socket.py", line 224, in meth
    return getattr(self._sock,name)(*args)
error: [Errno 111] Connection refused

[2016-11-20 16:25:05,782] [ERROR] [tcp.pre_test] -> Failed to connect to target server, retrying...
[2016-11-20 16:25:06,115] [ERROR] [server._start] -> Error occurred while fuzzing: AttributeError("'WebInterface' object has no attribute '_server'",)
[2016-11-20 16:25:06,188] [ERROR] [server._start] -> Traceback (most recent call last):
  File "/usr/local/lib/python2.7/dist-packages/kitty/fuzzers/server.py", line 43, in _start
    self._run_sequence(sequence)
  File "/usr/local/lib/python2.7/dist-packages/kitty/fuzzers/server.py", line 64, in _run_sequence
    self._pre_test()
  File "/usr/local/lib/python2.7/dist-packages/kitty/fuzzers/base.py", line 332, in _pre_test
    self.target.pre_test(self.model.current_index())
  File "/usr/local/lib/python2.7/dist-packages/katnip/targets/tcp.py", line 63, in pre_test
    time.sleep(1)
  File "/usr/local/lib/python2.7/dist-packages/kitty/fuzzers/base.py", line 504, in _exit_now
    self.stop()
  File "/usr/local/lib/python2.7/dist-packages/kitty/fuzzers/base.py", line 440, in stop
    self.user_interface.stop()
  File "/usr/local/lib/python2.7/dist-packages/kitty/interfaces/base.py", line 101, in stop
    self._stop()
  File "/usr/local/lib/python2.7/dist-packages/kitty/interfaces/web.py", line 297, in _stop
    self._server.shutdown()
AttributeError: 'WebInterface' object has no attribute '_server'

[2016-11-20 16:25:06,190] [INFO] [base._end_message] -> 
                         --------------------------------------------------
                         Finished fuzzing session
                         Target: TcpTarget

                         Tested 57 mutations
                         Mutation range: 0 to 56
                         Failure count: 0
                         --------------------------------------------------
            
