[2016-11-20 16:28:51,349] [INFO] [base._load_session] -> No session loaded
[2016-11-20 16:28:51,364] [INFO] [graph.hash] -> hash of template HTTP_GET_MONKEY_0 is 4168102103642212340
[2016-11-20 16:28:51,364] [INFO] [graph.hash] -> hash of model is -8069957684332539954
[2016-11-20 16:28:51,367] [INFO] [base._start_message] -> 
                 --------------------------------------------------
                 Starting fuzzing session
                 Target: TcpTarget
                 UI: WebInterface listening on 0.0.0.0:26000
                 Log: ./kittylogs/kitty_20161120-162850.log

                 Total possible mutation count: 39
                 Fuzzing the mutation range: 0 to 38
                 --------------------------------------------------
                                 Happy hacking
                 --------------------------------------------------
            
[2016-11-20 16:28:51,368] [INFO] [base.start] -> Performing environment test
[2016-11-20 16:28:51,393] [ERROR] [tcp.pre_test] -> Error: Traceback (most recent call last):
  File "/usr/local/lib/python2.7/dist-packages/katnip/targets/tcp.py", line 57, in pre_test
    sock.connect((self.host, self.port))
  File "/usr/lib/python2.7/socket.py", line 224, in meth
    return getattr(self._sock,name)(*args)
error: [Errno 111] Connection refused

[2016-11-20 16:28:51,395] [ERROR] [tcp.pre_test] -> Failed to connect to target server, retrying...
[2016-11-20 16:28:52,399] [INFO] [base._test_info] -> Current test: -1
[2016-11-20 16:28:52,399] [INFO] [server.transmit] -> request(28): 474554202f696e6465782e68746d6c20485454502f312e310d0a0d0a
[2016-11-20 16:28:52,401] [INFO] [server._start] -> should keep running? True
[2016-11-20 16:28:52,426] [INFO] [base._test_info] -> Current test: 0
[2016-11-20 16:28:52,434] [INFO] [server.transmit] -> request(32): 474554202f696e6465782e68746d6c20485454502f312e310d0a0d0a0d0a0d0a
[2016-11-20 16:28:52,855] [INFO] [base._test_info] -> Current test: 1
[2016-11-20 16:28:52,858] [INFO] [server.transmit] -> request(64): 474554202f696e6465782e68746d6c20485454502f312e310d0a0d0a0d0a0d0a0d0a0d0a0d0a0d0a0d0a0d0a0d0a0d0a0d0a ...
[2016-11-20 16:28:53,789] [ERROR] [tcp.pre_test] -> Error: Traceback (most recent call last):
  File "/usr/local/lib/python2.7/dist-packages/katnip/targets/tcp.py", line 57, in pre_test
    sock.connect((self.host, self.port))
  File "/usr/lib/python2.7/socket.py", line 224, in meth
    return getattr(self._sock,name)(*args)
error: [Errno 111] Connection refused

[2016-11-20 16:28:53,791] [ERROR] [tcp.pre_test] -> Failed to connect to target server, retrying...
[2016-11-20 16:28:54,795] [INFO] [base._test_info] -> Current test: 2
[2016-11-20 16:28:54,796] [INFO] [server.transmit] -> request(424): 474554202f696e6465782e68746d6c20485454502f312e310d0a0d0a0d0a0d0a0d0a0d0a0d0a0d0a0d0a0d0a0d0a0d0a0d0a ...
[2016-11-20 16:28:55,212] [INFO] [base._test_info] -> Current test: 3
[2016-11-20 16:28:55,215] [INFO] [server.transmit] -> request(29): 474554202f696e6465782e68746d6c20485454502f312e310d0a0d0afe
[2016-11-20 16:28:56,146] [ERROR] [tcp.pre_test] -> Error: Traceback (most recent call last):
  File "/usr/local/lib/python2.7/dist-packages/katnip/targets/tcp.py", line 57, in pre_test
    sock.connect((self.host, self.port))
  File "/usr/lib/python2.7/socket.py", line 224, in meth
    return getattr(self._sock,name)(*args)
error: [Errno 111] Connection refused

[2016-11-20 16:28:56,148] [ERROR] [tcp.pre_test] -> Failed to connect to target server, retrying...
[2016-11-20 16:28:57,152] [INFO] [base._test_info] -> Current test: 4
[2016-11-20 16:28:57,154] [INFO] [server.transmit] -> request(29): 474554202f696e6465782e68746d6c20485454502f312e31000d0a0d0a
[2016-11-20 16:28:57,571] [INFO] [base._test_info] -> Current test: 5
[2016-11-20 16:28:57,573] [INFO] [server.transmit] -> request(29): 474554202f696e6465782e68746d6c20485454502f312e310d0a000d0a
[2016-11-20 16:28:58,495] [ERROR] [tcp.pre_test] -> Error: Traceback (most recent call last):
  File "/usr/local/lib/python2.7/dist-packages/katnip/targets/tcp.py", line 57, in pre_test
    sock.connect((self.host, self.port))
  File "/usr/lib/python2.7/socket.py", line 224, in meth
    return getattr(self._sock,name)(*args)
error: [Errno 111] Connection refused

[2016-11-20 16:28:58,497] [ERROR] [tcp.pre_test] -> Failed to connect to target server, retrying...
[2016-11-20 16:28:59,501] [INFO] [base._test_info] -> Current test: 6
[2016-11-20 16:28:59,504] [INFO] [server.transmit] -> request(29): 474554202f696e6465782e68746d6c20485454502f312e310d0a0d0a00
[2016-11-20 16:28:59,920] [INFO] [base._test_info] -> Current test: 7
[2016-11-20 16:28:59,925] [INFO] [server.transmit] -> request(28): 474554202f696e6465782e68746d6c20485454502f312e3120202020
[2016-11-20 16:29:00,858] [INFO] [base._test_info] -> Current test: 8
[2016-11-20 16:29:00,859] [INFO] [server.transmit] -> request(28): 474554202f696e6465782e68746d6c20485454502f312e3109090909
[2016-11-20 16:29:01,787] [INFO] [base._test_info] -> Current test: 9
[2016-11-20 16:29:01,789] [INFO] [server.transmit] -> request(28): 474554202f696e6465782e68746d6c20485454502f312e3121212121
[2016-11-20 16:29:02,715] [ERROR] [tcp.pre_test] -> Error: Traceback (most recent call last):
  File "/usr/local/lib/python2.7/dist-packages/katnip/targets/tcp.py", line 57, in pre_test
    sock.connect((self.host, self.port))
  File "/usr/lib/python2.7/socket.py", line 224, in meth
    return getattr(self._sock,name)(*args)
error: [Errno 111] Connection refused

[2016-11-20 16:29:02,716] [ERROR] [tcp.pre_test] -> Failed to connect to target server, retrying...
[2016-11-20 16:29:03,720] [INFO] [base._test_info] -> Current test: 10
[2016-11-20 16:29:03,721] [INFO] [server.transmit] -> request(28): 474554202f696e6465782e68746d6c20485454502f312e3140404040
[2016-11-20 16:29:04,139] [INFO] [base._test_info] -> Current test: 11
[2016-11-20 16:29:04,142] [INFO] [server.transmit] -> request(28): 474554202f696e6465782e68746d6c20485454502f312e3123232323
[2016-11-20 16:29:05,072] [INFO] [base._test_info] -> Current test: 12
[2016-11-20 16:29:05,075] [INFO] [server.transmit] -> request(28): 474554202f696e6465782e68746d6c20485454502f312e3124242424
[2016-11-20 16:29:06,024] [ERROR] [tcp.pre_test] -> Error: Traceback (most recent call last):
  File "/usr/local/lib/python2.7/dist-packages/katnip/targets/tcp.py", line 57, in pre_test
    sock.connect((self.host, self.port))
  File "/usr/lib/python2.7/socket.py", line 224, in meth
    return getattr(self._sock,name)(*args)
error: [Errno 111] Connection refused

[2016-11-20 16:29:06,028] [ERROR] [tcp.pre_test] -> Failed to connect to target server, retrying...
[2016-11-20 16:29:07,034] [INFO] [base._test_info] -> Current test: 13
[2016-11-20 16:29:07,035] [INFO] [server.transmit] -> request(28): 474554202f696e6465782e68746d6c20485454502f312e3125252525
[2016-11-20 16:29:07,450] [INFO] [base._test_info] -> Current test: 14
[2016-11-20 16:29:07,453] [INFO] [server.transmit] -> request(28): 474554202f696e6465782e68746d6c20485454502f312e315e5e5e5e
[2016-11-20 16:29:08,381] [ERROR] [tcp.pre_test] -> Error: Traceback (most recent call last):
  File "/usr/local/lib/python2.7/dist-packages/katnip/targets/tcp.py", line 57, in pre_test
    sock.connect((self.host, self.port))
  File "/usr/lib/python2.7/socket.py", line 224, in meth
    return getattr(self._sock,name)(*args)
error: [Errno 111] Connection refused

[2016-11-20 16:29:08,382] [ERROR] [tcp.pre_test] -> Failed to connect to target server, retrying...
[2016-11-20 16:29:09,387] [INFO] [base._test_info] -> Current test: 15
[2016-11-20 16:29:09,391] [INFO] [server.transmit] -> request(28): 474554202f696e6465782e68746d6c20485454502f312e3126262626
[2016-11-20 16:29:09,807] [INFO] [base._test_info] -> Current test: 16
[2016-11-20 16:29:09,810] [INFO] [server.transmit] -> request(28): 474554202f696e6465782e68746d6c20485454502f312e312a2a2a2a
[2016-11-20 16:29:10,742] [ERROR] [tcp.pre_test] -> Error: Traceback (most recent call last):
  File "/usr/local/lib/python2.7/dist-packages/katnip/targets/tcp.py", line 57, in pre_test
    sock.connect((self.host, self.port))
  File "/usr/lib/python2.7/socket.py", line 224, in meth
    return getattr(self._sock,name)(*args)
error: [Errno 111] Connection refused

[2016-11-20 16:29:10,744] [ERROR] [tcp.pre_test] -> Failed to connect to target server, retrying...
[2016-11-20 16:29:11,750] [INFO] [base._test_info] -> Current test: 17
[2016-11-20 16:29:11,751] [INFO] [server.transmit] -> request(28): 474554202f696e6465782e68746d6c20485454502f312e3128282828
[2016-11-20 16:29:12,167] [INFO] [base._test_info] -> Current test: 18
[2016-11-20 16:29:12,170] [INFO] [server.transmit] -> request(28): 474554202f696e6465782e68746d6c20485454502f312e3129292929
[2016-11-20 16:29:13,108] [ERROR] [tcp.pre_test] -> Error: Traceback (most recent call last):
  File "/usr/local/lib/python2.7/dist-packages/katnip/targets/tcp.py", line 57, in pre_test
    sock.connect((self.host, self.port))
  File "/usr/lib/python2.7/socket.py", line 224, in meth
    return getattr(self._sock,name)(*args)
error: [Errno 111] Connection refused

[2016-11-20 16:29:13,109] [ERROR] [tcp.pre_test] -> Failed to connect to target server, retrying...
[2016-11-20 16:29:14,112] [INFO] [base._test_info] -> Current test: 19
[2016-11-20 16:29:14,114] [INFO] [server.transmit] -> request(28): 474554202f696e6465782e68746d6c20485454502f312e312d2d2d2d
[2016-11-20 16:29:14,529] [INFO] [base._test_info] -> Current test: 20
[2016-11-20 16:29:14,535] [INFO] [server.transmit] -> request(28): 474554202f696e6465782e68746d6c20485454502f312e315f5f5f5f
[2016-11-20 16:29:15,466] [ERROR] [tcp.pre_test] -> Error: Traceback (most recent call last):
  File "/usr/local/lib/python2.7/dist-packages/katnip/targets/tcp.py", line 57, in pre_test
    sock.connect((self.host, self.port))
  File "/usr/lib/python2.7/socket.py", line 224, in meth
    return getattr(self._sock,name)(*args)
error: [Errno 111] Connection refused

[2016-11-20 16:29:15,468] [ERROR] [tcp.pre_test] -> Failed to connect to target server, retrying...
[2016-11-20 16:29:16,472] [INFO] [base._test_info] -> Current test: 21
[2016-11-20 16:29:16,474] [INFO] [server.transmit] -> request(28): 474554202f696e6465782e68746d6c20485454502f312e312b2b2b2b
[2016-11-20 16:29:16,888] [INFO] [base._test_info] -> Current test: 22
[2016-11-20 16:29:16,890] [INFO] [server.transmit] -> request(28): 474554202f696e6465782e68746d6c20485454502f312e313d3d3d3d
[2016-11-20 16:29:17,818] [ERROR] [tcp.pre_test] -> Error: Traceback (most recent call last):
  File "/usr/local/lib/python2.7/dist-packages/katnip/targets/tcp.py", line 57, in pre_test
    sock.connect((self.host, self.port))
  File "/usr/lib/python2.7/socket.py", line 224, in meth
    return getattr(self._sock,name)(*args)
error: [Errno 111] Connection refused

[2016-11-20 16:29:17,822] [ERROR] [tcp.pre_test] -> Failed to connect to target server, retrying...
[2016-11-20 16:29:18,827] [INFO] [base._test_info] -> Current test: 23
[2016-11-20 16:29:18,829] [INFO] [server.transmit] -> request(28): 474554202f696e6465782e68746d6c20485454502f312e313a3a3a3a
[2016-11-20 16:29:19,246] [INFO] [base._test_info] -> Current test: 24
[2016-11-20 16:29:19,248] [INFO] [server.transmit] -> request(28): 474554202f696e6465782e68746d6c20485454502f312e313b3b3b3b
[2016-11-20 16:29:20,176] [INFO] [base._test_info] -> Current test: 25
[2016-11-20 16:29:20,179] [INFO] [server.transmit] -> request(28): 474554202f696e6465782e68746d6c20485454502f312e3127272727
[2016-11-20 16:29:21,116] [ERROR] [tcp.pre_test] -> Error: Traceback (most recent call last):
  File "/usr/local/lib/python2.7/dist-packages/katnip/targets/tcp.py", line 57, in pre_test
    sock.connect((self.host, self.port))
  File "/usr/lib/python2.7/socket.py", line 224, in meth
    return getattr(self._sock,name)(*args)
error: [Errno 111] Connection refused

[2016-11-20 16:29:21,117] [ERROR] [tcp.pre_test] -> Failed to connect to target server, retrying...
[2016-11-20 16:29:22,121] [INFO] [base._test_info] -> Current test: 26
[2016-11-20 16:29:22,123] [INFO] [server.transmit] -> request(28): 474554202f696e6465782e68746d6c20485454502f312e3122222222
[2016-11-20 16:29:22,536] [INFO] [base._test_info] -> Current test: 27
[2016-11-20 16:29:22,539] [INFO] [server.transmit] -> request(28): 474554202f696e6465782e68746d6c20485454502f312e312f2f2f2f
[2016-11-20 16:29:23,463] [ERROR] [tcp.pre_test] -> Error: Traceback (most recent call last):
  File "/usr/local/lib/python2.7/dist-packages/katnip/targets/tcp.py", line 57, in pre_test
    sock.connect((self.host, self.port))
  File "/usr/lib/python2.7/socket.py", line 224, in meth
    return getattr(self._sock,name)(*args)
error: [Errno 111] Connection refused

[2016-11-20 16:29:23,466] [ERROR] [tcp.pre_test] -> Failed to connect to target server, retrying...
[2016-11-20 16:29:24,470] [INFO] [base._test_info] -> Current test: 28
[2016-11-20 16:29:24,472] [INFO] [server.transmit] -> request(28): 474554202f696e6465782e68746d6c20485454502f312e315c5c5c5c
[2016-11-20 16:29:24,887] [INFO] [base._test_info] -> Current test: 29
[2016-11-20 16:29:24,889] [INFO] [server.transmit] -> request(28): 474554202f696e6465782e68746d6c20485454502f312e313f3f3f3f
[2016-11-20 16:29:25,814] [ERROR] [tcp.pre_test] -> Error: Traceback (most recent call last):
  File "/usr/local/lib/python2.7/dist-packages/katnip/targets/tcp.py", line 57, in pre_test
    sock.connect((self.host, self.port))
  File "/usr/lib/python2.7/socket.py", line 224, in meth
    return getattr(self._sock,name)(*args)
error: [Errno 111] Connection refused

[2016-11-20 16:29:25,815] [ERROR] [tcp.pre_test] -> Failed to connect to target server, retrying...
[2016-11-20 16:29:26,818] [INFO] [base._test_info] -> Current test: 30
[2016-11-20 16:29:26,820] [INFO] [server.transmit] -> request(28): 474554202f696e6465782e68746d6c20485454502f312e313c3c3c3c
[2016-11-20 16:29:27,235] [INFO] [base._test_info] -> Current test: 31
[2016-11-20 16:29:27,238] [INFO] [server.transmit] -> request(28): 474554202f696e6465782e68746d6c20485454502f312e313e3e3e3e
[2016-11-20 16:29:28,173] [ERROR] [tcp.pre_test] -> Error: Traceback (most recent call last):
  File "/usr/local/lib/python2.7/dist-packages/katnip/targets/tcp.py", line 57, in pre_test
    sock.connect((self.host, self.port))
  File "/usr/lib/python2.7/socket.py", line 224, in meth
    return getattr(self._sock,name)(*args)
error: [Errno 111] Connection refused

[2016-11-20 16:29:28,174] [ERROR] [tcp.pre_test] -> Failed to connect to target server, retrying...
[2016-11-20 16:29:29,179] [INFO] [base._test_info] -> Current test: 32
[2016-11-20 16:29:29,180] [INFO] [server.transmit] -> request(28): 474554202f696e6465782e68746d6c20485454502f312e312e2e2e2e
[2016-11-20 16:29:29,595] [INFO] [base._test_info] -> Current test: 33
[2016-11-20 16:29:29,597] [INFO] [server.transmit] -> request(28): 474554202f696e6465782e68746d6c20485454502f312e312c2c2c2c
[2016-11-20 16:29:30,527] [INFO] [base._test_info] -> Current test: 34
[2016-11-20 16:29:30,529] [INFO] [server.transmit] -> request(28): 474554202f696e6465782e68746d6c20485454502f312e310d0d0d0d
[2016-11-20 16:29:31,459] [INFO] [base._test_info] -> Current test: 35
[2016-11-20 16:29:31,462] [INFO] [server.transmit] -> request(28): 474554202f696e6465782e68746d6c20485454502f312e310a0a0a0a
[2016-11-20 16:29:32,391] [INFO] [base._test_info] -> Current test: 36
[2016-11-20 16:29:32,393] [INFO] [server.transmit] -> request(40): 474554202f696e6465782e68746d6c20485454502f312e310d0a0d0a0d0a0d0a0d0a0d0a0d0a0d0a
[2016-11-20 16:29:33,323] [INFO] [base._test_info] -> Current test: 37
[2016-11-20 16:29:33,326] [INFO] [server.transmit] -> request(48): 474554202f696e6465782e68746d6c20485454502f312e31090d0a090d0a090d0a090d0a090d0a090d0a090d0a090d0a
[2016-11-20 16:29:34,256] [INFO] [base._test_info] -> Current test: 38
[2016-11-20 16:29:34,258] [INFO] [server.transmit] -> request(24): 474554202f696e6465782e68746d6c20485454502f312e31
[2016-11-20 16:29:35,172] [INFO] [base._end_message] -> 
                         --------------------------------------------------
                         Finished fuzzing session
                         Target: TcpTarget

                         Tested 39 mutations
                         Mutation range: 0 to 38
                         Failure count: 0
                         --------------------------------------------------
            
