[2016-11-20 17:12:46,238] [INFO] [base._load_session] -> No session loaded
[2016-11-20 17:12:46,250] [INFO] [graph.hash] -> hash of template HTTP_GET_MONKEY_2 is 1812954675086888121
[2016-11-20 17:12:46,251] [INFO] [graph.hash] -> hash of model is -4467975616178308160
[2016-11-20 17:12:46,254] [INFO] [base._start_message] -> 
                 --------------------------------------------------
                 Starting fuzzing session
                 Target: TcpTarget
                 UI: WebInterface listening on 0.0.0.0:26000
                 Log: ./kittylogs/kitty_20161120-171245.log

                 Total possible mutation count: 113
                 Fuzzing the mutation range: 0 to 112
                 --------------------------------------------------
                                 Happy hacking
                 --------------------------------------------------
            
[2016-11-20 17:12:46,255] [INFO] [base.start] -> Performing environment test
[2016-11-20 17:12:46,288] [INFO] [base._test_info] -> Current test: -1
[2016-11-20 17:12:46,289] [INFO] [server.transmit] -> request(87): 474554202f696d67732f6d6f6e6b65795f6c6f676f2e706e6720485454502f312e310d0a486f73743a203132372e302e302e ...
[2016-11-20 17:12:46,815] [INFO] [server._start] -> should keep running? True
[2016-11-20 17:12:46,838] [INFO] [base._test_info] -> Current test: 0
[2016-11-20 17:12:46,840] [INFO] [server.transmit] -> request(88): 474554202f696d67732f6d6f6e6b65795f6c6f676f2e706e6720485454502f312e310d0a486f73743a20203132372e302e30 ...
[2016-11-20 17:12:47,792] [INFO] [base._test_info] -> Current test: 1
[2016-11-20 17:12:47,797] [INFO] [server.transmit] -> request(96): 474554202f696d67732f6d6f6e6b65795f6c6f676f2e706e6720485454502f312e310d0a486f73743a202020202020202020 ...
[2016-11-20 17:12:48,750] [INFO] [base._test_info] -> Current test: 2
[2016-11-20 17:12:48,752] [INFO] [server.transmit] -> request(186): 474554202f696d67732f6d6f6e6b65795f6c6f676f2e706e6720485454502f312e310d0a486f73743a202020202020202020 ...
[2016-11-20 17:12:49,712] [INFO] [base._test_info] -> Current test: 3
[2016-11-20 17:12:49,716] [INFO] [server.transmit] -> request(88): 474554202f696d67732f6d6f6e6b65795f6c6f676f2e706e6720485454502f312e310d0a486f73743a20fe3132372e302e30 ...
[2016-11-20 17:12:50,659] [INFO] [base._test_info] -> Current test: 4
[2016-11-20 17:12:50,663] [INFO] [server.transmit] -> request(88): 474554202f696d67732f6d6f6e6b65795f6c6f676f2e706e6720485454502f312e310d0a486f73743a00203132372e302e30 ...
[2016-11-20 17:12:51,603] [INFO] [base._test_info] -> Current test: 6
[2016-11-20 17:12:51,617] [INFO] [server.transmit] -> request(88): 474554202f696d67732f6d6f6e6b65795f6c6f676f2e706e6720485454502f312e310d0a486f73743a20003132372e302e30 ...
[2016-11-20 17:12:52,564] [INFO] [base._test_info] -> Current test: 7
[2016-11-20 17:12:52,571] [INFO] [server.transmit] -> request(90): 474554202f696d67732f6d6f6e6b65795f6c6f676f2e706e6720485454502f312e310d0a486f73743a202020203132372e30 ...
[2016-11-20 17:12:53,510] [INFO] [base._test_info] -> Current test: 8
[2016-11-20 17:12:53,514] [INFO] [server.transmit] -> request(90): 474554202f696d67732f6d6f6e6b65795f6c6f676f2e706e6720485454502f312e310d0a486f73743a090909093132372e30 ...
[2016-11-20 17:12:54,471] [INFO] [base._test_info] -> Current test: 9
[2016-11-20 17:12:54,474] [INFO] [server.transmit] -> request(90): 474554202f696d67732f6d6f6e6b65795f6c6f676f2e706e6720485454502f312e310d0a486f73743a212121213132372e30 ...
[2016-11-20 17:12:55,430] [INFO] [base._test_info] -> Current test: 10
[2016-11-20 17:12:55,435] [INFO] [server.transmit] -> request(90): 474554202f696d67732f6d6f6e6b65795f6c6f676f2e706e6720485454502f312e310d0a486f73743a404040403132372e30 ...
[2016-11-20 17:12:56,371] [INFO] [base._test_info] -> Current test: 11
[2016-11-20 17:12:56,377] [INFO] [server.transmit] -> request(90): 474554202f696d67732f6d6f6e6b65795f6c6f676f2e706e6720485454502f312e310d0a486f73743a232323233132372e30 ...
[2016-11-20 17:12:57,357] [INFO] [base._test_info] -> Current test: 12
[2016-11-20 17:12:57,362] [INFO] [server.transmit] -> request(90): 474554202f696d67732f6d6f6e6b65795f6c6f676f2e706e6720485454502f312e310d0a486f73743a242424243132372e30 ...
[2016-11-20 17:12:58,320] [INFO] [base._test_info] -> Current test: 13
[2016-11-20 17:12:58,328] [INFO] [server.transmit] -> request(90): 474554202f696d67732f6d6f6e6b65795f6c6f676f2e706e6720485454502f312e310d0a486f73743a252525253132372e30 ...
[2016-11-20 17:12:59,285] [INFO] [base._test_info] -> Current test: 14
[2016-11-20 17:12:59,290] [INFO] [server.transmit] -> request(90): 474554202f696d67732f6d6f6e6b65795f6c6f676f2e706e6720485454502f312e310d0a486f73743a5e5e5e5e3132372e30 ...
[2016-11-20 17:13:00,297] [INFO] [base._test_info] -> Current test: 15
[2016-11-20 17:13:00,302] [INFO] [server.transmit] -> request(90): 474554202f696d67732f6d6f6e6b65795f6c6f676f2e706e6720485454502f312e310d0a486f73743a262626263132372e30 ...
[2016-11-20 17:13:01,251] [INFO] [base._test_info] -> Current test: 16
[2016-11-20 17:13:01,254] [INFO] [server.transmit] -> request(90): 474554202f696d67732f6d6f6e6b65795f6c6f676f2e706e6720485454502f312e310d0a486f73743a2a2a2a2a3132372e30 ...
[2016-11-20 17:13:02,216] [INFO] [base._test_info] -> Current test: 17
[2016-11-20 17:13:02,219] [INFO] [server.transmit] -> request(90): 474554202f696d67732f6d6f6e6b65795f6c6f676f2e706e6720485454502f312e310d0a486f73743a282828283132372e30 ...
[2016-11-20 17:13:03,159] [INFO] [base._test_info] -> Current test: 18
[2016-11-20 17:13:03,166] [INFO] [server.transmit] -> request(90): 474554202f696d67732f6d6f6e6b65795f6c6f676f2e706e6720485454502f312e310d0a486f73743a292929293132372e30 ...
[2016-11-20 17:13:04,104] [INFO] [base._test_info] -> Current test: 19
[2016-11-20 17:13:04,110] [INFO] [server.transmit] -> request(90): 474554202f696d67732f6d6f6e6b65795f6c6f676f2e706e6720485454502f312e310d0a486f73743a2d2d2d2d3132372e30 ...
[2016-11-20 17:13:05,072] [INFO] [base._test_info] -> Current test: 20
[2016-11-20 17:13:05,080] [INFO] [server.transmit] -> request(90): 474554202f696d67732f6d6f6e6b65795f6c6f676f2e706e6720485454502f312e310d0a486f73743a5f5f5f5f3132372e30 ...
[2016-11-20 17:13:05,507] [INFO] [base._test_info] -> Current test: 21
[2016-11-20 17:13:05,511] [INFO] [server.transmit] -> request(90): 474554202f696d67732f6d6f6e6b65795f6c6f676f2e706e6720485454502f312e310d0a486f73743a2b2b2b2b3132372e30 ...
[2016-11-20 17:13:06,450] [INFO] [base._test_info] -> Current test: 22
[2016-11-20 17:13:06,452] [INFO] [server.transmit] -> request(90): 474554202f696d67732f6d6f6e6b65795f6c6f676f2e706e6720485454502f312e310d0a486f73743a3d3d3d3d3132372e30 ...
[2016-11-20 17:13:07,384] [INFO] [base._test_info] -> Current test: 23
[2016-11-20 17:13:07,393] [INFO] [server.transmit] -> request(90): 474554202f696d67732f6d6f6e6b65795f6c6f676f2e706e6720485454502f312e310d0a486f73743a3a3a3a3a3132372e30 ...
[2016-11-20 17:13:07,825] [INFO] [base._test_info] -> Current test: 24
[2016-11-20 17:13:07,828] [INFO] [server.transmit] -> request(90): 474554202f696d67732f6d6f6e6b65795f6c6f676f2e706e6720485454502f312e310d0a486f73743a3b3b3b3b3132372e30 ...
[2016-11-20 17:13:08,265] [INFO] [base._test_info] -> Current test: 25
[2016-11-20 17:13:08,268] [INFO] [server.transmit] -> request(90): 474554202f696d67732f6d6f6e6b65795f6c6f676f2e706e6720485454502f312e310d0a486f73743a272727273132372e30 ...
[2016-11-20 17:13:09,212] [INFO] [base._test_info] -> Current test: 26
[2016-11-20 17:13:09,221] [INFO] [server.transmit] -> request(90): 474554202f696d67732f6d6f6e6b65795f6c6f676f2e706e6720485454502f312e310d0a486f73743a222222223132372e30 ...
[2016-11-20 17:13:10,173] [INFO] [base._test_info] -> Current test: 27
[2016-11-20 17:13:10,183] [INFO] [server.transmit] -> request(90): 474554202f696d67732f6d6f6e6b65795f6c6f676f2e706e6720485454502f312e310d0a486f73743a2f2f2f2f3132372e30 ...
[2016-11-20 17:13:11,140] [INFO] [base._test_info] -> Current test: 28
[2016-11-20 17:13:11,145] [INFO] [server.transmit] -> request(90): 474554202f696d67732f6d6f6e6b65795f6c6f676f2e706e6720485454502f312e310d0a486f73743a5c5c5c5c3132372e30 ...
[2016-11-20 17:13:12,116] [INFO] [base._test_info] -> Current test: 29
[2016-11-20 17:13:12,123] [INFO] [server.transmit] -> request(90): 474554202f696d67732f6d6f6e6b65795f6c6f676f2e706e6720485454502f312e310d0a486f73743a3f3f3f3f3132372e30 ...
[2016-11-20 17:13:13,063] [INFO] [base._test_info] -> Current test: 30
[2016-11-20 17:13:13,066] [INFO] [server.transmit] -> request(90): 474554202f696d67732f6d6f6e6b65795f6c6f676f2e706e6720485454502f312e310d0a486f73743a3c3c3c3c3132372e30 ...
[2016-11-20 17:13:14,008] [INFO] [base._test_info] -> Current test: 31
[2016-11-20 17:13:14,012] [INFO] [server.transmit] -> request(90): 474554202f696d67732f6d6f6e6b65795f6c6f676f2e706e6720485454502f312e310d0a486f73743a3e3e3e3e3132372e30 ...
[2016-11-20 17:13:14,948] [INFO] [base._test_info] -> Current test: 32
[2016-11-20 17:13:14,954] [INFO] [server.transmit] -> request(90): 474554202f696d67732f6d6f6e6b65795f6c6f676f2e706e6720485454502f312e310d0a486f73743a2e2e2e2e3132372e30 ...
[2016-11-20 17:13:15,901] [INFO] [base._test_info] -> Current test: 33
[2016-11-20 17:13:15,905] [INFO] [server.transmit] -> request(90): 474554202f696d67732f6d6f6e6b65795f6c6f676f2e706e6720485454502f312e310d0a486f73743a2c2c2c2c3132372e30 ...
[2016-11-20 17:13:16,847] [INFO] [base._test_info] -> Current test: 34
[2016-11-20 17:13:16,851] [INFO] [server.transmit] -> request(90): 474554202f696d67732f6d6f6e6b65795f6c6f676f2e706e6720485454502f312e310d0a486f73743a0d0d0d0d3132372e30 ...
[2016-11-20 17:13:17,821] [INFO] [base._test_info] -> Current test: 35
[2016-11-20 17:13:17,825] [INFO] [server.transmit] -> request(90): 474554202f696d67732f6d6f6e6b65795f6c6f676f2e706e6720485454502f312e310d0a486f73743a0a0a0a0a3132372e30 ...
[2016-11-20 17:13:18,770] [INFO] [base._test_info] -> Current test: 36
[2016-11-20 17:13:18,773] [INFO] [server.transmit] -> request(102): 474554202f696d67732f6d6f6e6b65795f6c6f676f2e706e6720485454502f312e310d0a486f73743a0d0a0d0a0d0a0d0a0d ...
[2016-11-20 17:13:19,742] [ERROR] [tcp.pre_test] -> Error: Traceback (most recent call last):
  File "/usr/local/lib/python2.7/dist-packages/katnip/targets/tcp.py", line 57, in pre_test
    sock.connect((self.host, self.port))
  File "/usr/lib/python2.7/socket.py", line 224, in meth
    return getattr(self._sock,name)(*args)
error: [Errno 111] Connection refused

[2016-11-20 17:13:19,744] [ERROR] [tcp.pre_test] -> Failed to connect to target server, retrying...
[2016-11-20 17:13:20,750] [INFO] [base._test_info] -> Current test: 37
[2016-11-20 17:13:20,753] [INFO] [server.transmit] -> request(110): 474554202f696d67732f6d6f6e6b65795f6c6f676f2e706e6720485454502f312e310d0a486f73743a090d0a090d0a090d0a ...
[2016-11-20 17:13:21,185] [ERROR] [tcp.pre_test] -> Error: Traceback (most recent call last):
  File "/usr/local/lib/python2.7/dist-packages/katnip/targets/tcp.py", line 57, in pre_test
    sock.connect((self.host, self.port))
  File "/usr/lib/python2.7/socket.py", line 224, in meth
    return getattr(self._sock,name)(*args)
error: [Errno 111] Connection refused

[2016-11-20 17:13:21,186] [ERROR] [tcp.pre_test] -> Failed to connect to target server, retrying...
[2016-11-20 17:13:22,191] [INFO] [base._test_info] -> Current test: 38
[2016-11-20 17:13:22,192] [INFO] [server.transmit] -> request(86): 474554202f696d67732f6d6f6e6b65795f6c6f676f2e706e6720485454502f312e310d0a486f73743a3132372e302e302e31 ...
[2016-11-20 17:13:22,618] [INFO] [base._test_info] -> Current test: 39
[2016-11-20 17:13:22,622] [INFO] [server.transmit] -> request(92): 474554202f696d67732f6d6f6e6b65795f6c6f676f2e706e6720485454502f312e310d0a486f73743a203132372e302e302e ...
[2016-11-20 17:13:23,550] [ERROR] [tcp.pre_test] -> Error: Traceback (most recent call last):
  File "/usr/local/lib/python2.7/dist-packages/katnip/targets/tcp.py", line 57, in pre_test
    sock.connect((self.host, self.port))
  File "/usr/lib/python2.7/socket.py", line 224, in meth
    return getattr(self._sock,name)(*args)
error: [Errno 111] Connection refused

[2016-11-20 17:13:23,551] [ERROR] [tcp.pre_test] -> Failed to connect to target server, retrying...
[2016-11-20 17:13:24,556] [INFO] [base._test_info] -> Current test: 40
[2016-11-20 17:13:24,559] [INFO] [server.transmit] -> request(91): 474554202f696d67732f6d6f6e6b65795f6c6f676f2e706e6720485454502f312e310d0a486f73743a203132372e302e302e ...
[2016-11-20 17:13:24,980] [INFO] [base._test_info] -> Current test: 41
[2016-11-20 17:13:24,985] [INFO] [server.transmit] -> request(90): 474554202f696d67732f6d6f6e6b65795f6c6f676f2e706e6720485454502f312e310d0a486f73743a203132372e302e302e ...
[2016-11-20 17:13:25,912] [ERROR] [tcp.pre_test] -> Error: Traceback (most recent call last):
  File "/usr/local/lib/python2.7/dist-packages/katnip/targets/tcp.py", line 57, in pre_test
    sock.connect((self.host, self.port))
  File "/usr/lib/python2.7/socket.py", line 224, in meth
    return getattr(self._sock,name)(*args)
error: [Errno 111] Connection refused

[2016-11-20 17:13:25,923] [ERROR] [tcp.pre_test] -> Failed to connect to target server, retrying...
[2016-11-20 17:13:26,928] [INFO] [base._test_info] -> Current test: 42
[2016-11-20 17:13:26,931] [INFO] [server.transmit] -> request(89): 474554202f696d67732f6d6f6e6b65795f6c6f676f2e706e6720485454502f312e310d0a486f73743a203132372e302e302e ...
[2016-11-20 17:13:27,358] [INFO] [base._test_info] -> Current test: 43
[2016-11-20 17:13:27,360] [INFO] [server.transmit] -> request(88): 474554202f696d67732f6d6f6e6b65795f6c6f676f2e706e6720485454502f312e310d0a486f73743a203132372e302e302e ...
[2016-11-20 17:13:28,291] [INFO] [base._test_info] -> Current test: 44
[2016-11-20 17:13:28,295] [INFO] [server.transmit] -> request(87): 474554202f696d67732f6d6f6e6b65795f6c6f676f2e706e6720485454502f312e310d0a486f73743a203132372e302e302e ...
[2016-11-20 17:13:29,258] [ERROR] [tcp.pre_test] -> Error: Traceback (most recent call last):
  File "/usr/local/lib/python2.7/dist-packages/katnip/targets/tcp.py", line 57, in pre_test
    sock.connect((self.host, self.port))
  File "/usr/lib/python2.7/socket.py", line 224, in meth
    return getattr(self._sock,name)(*args)
error: [Errno 111] Connection refused

[2016-11-20 17:13:29,262] [ERROR] [tcp.pre_test] -> Failed to connect to target server, retrying...
[2016-11-20 17:13:30,267] [INFO] [base._test_info] -> Current test: 45
[2016-11-20 17:13:30,270] [INFO] [server.transmit] -> request(87): 474554202f696d67732f6d6f6e6b65795f6c6f676f2e706e6720485454502f312e310d0a486f73743a203132372e302e302e ...
[2016-11-20 17:13:30,691] [INFO] [base._test_info] -> Current test: 46
[2016-11-20 17:13:30,692] [INFO] [server.transmit] -> request(87): 474554202f696d67732f6d6f6e6b65795f6c6f676f2e706e6720485454502f312e310d0a486f73743a203132372e302e302e ...
[2016-11-20 17:13:31,659] [ERROR] [tcp.pre_test] -> Error: Traceback (most recent call last):
  File "/usr/local/lib/python2.7/dist-packages/katnip/targets/tcp.py", line 57, in pre_test
    sock.connect((self.host, self.port))
  File "/usr/lib/python2.7/socket.py", line 224, in meth
    return getattr(self._sock,name)(*args)
error: [Errno 111] Connection refused

[2016-11-20 17:13:31,662] [ERROR] [tcp.pre_test] -> Failed to connect to target server, retrying...
[2016-11-20 17:13:32,682] [INFO] [base._test_info] -> Current test: 47
[2016-11-20 17:13:32,683] [INFO] [server.transmit] -> request(87): 474554202f696d67732f6d6f6e6b65795f6c6f676f2e706e6720485454502f312e310d0a486f73743a203132372e302e302e ...
[2016-11-20 17:13:33,101] [INFO] [base._test_info] -> Current test: 48
[2016-11-20 17:13:33,103] [INFO] [server.transmit] -> request(87): 474554202f696d67732f6d6f6e6b65795f6c6f676f2e706e6720485454502f312e310d0a486f73743a203132372e302e302e ...
[2016-11-20 17:13:34,030] [INFO] [base._test_info] -> Current test: 49
[2016-11-20 17:13:34,034] [INFO] [server.transmit] -> request(83): 474554202f696d67732f6d6f6e6b65795f6c6f676f2e706e6720485454502f312e310d0a486f73743a203132372e302e302e ...
[2016-11-20 17:13:34,976] [ERROR] [tcp.pre_test] -> Error: Traceback (most recent call last):
  File "/usr/local/lib/python2.7/dist-packages/katnip/targets/tcp.py", line 57, in pre_test
    sock.connect((self.host, self.port))
  File "/usr/lib/python2.7/socket.py", line 224, in meth
    return getattr(self._sock,name)(*args)
error: [Errno 111] Connection refused

[2016-11-20 17:13:34,979] [ERROR] [tcp.pre_test] -> Failed to connect to target server, retrying...
[2016-11-20 17:13:35,984] [INFO] [base._test_info] -> Current test: 50
[2016-11-20 17:13:35,985] [INFO] [server.transmit] -> request(92): 474554202f696d67732f6d6f6e6b65795f6c6f676f2e706e6720485454502f312e310d0a486f73743a203132372e302e302e ...
[2016-11-20 17:13:36,425] [INFO] [base._test_info] -> Current test: 51
[2016-11-20 17:13:36,428] [INFO] [server.transmit] -> request(92): 474554202f696d67732f6d6f6e6b65795f6c6f676f2e706e6720485454502f312e310d0a486f73743a203132372e302e302e ...
[2016-11-20 17:13:36,862] [INFO] [base._test_info] -> Current test: 52
[2016-11-20 17:13:36,865] [INFO] [server.transmit] -> request(92): 474554202f696d67732f6d6f6e6b65795f6c6f676f2e706e6720485454502f312e310d0a486f73743a203132372e302e302e ...
[2016-11-20 17:13:37,825] [ERROR] [tcp.pre_test] -> Error: Traceback (most recent call last):
  File "/usr/local/lib/python2.7/dist-packages/katnip/targets/tcp.py", line 57, in pre_test
    sock.connect((self.host, self.port))
  File "/usr/lib/python2.7/socket.py", line 224, in meth
    return getattr(self._sock,name)(*args)
error: [Errno 111] Connection refused

[2016-11-20 17:13:37,832] [ERROR] [tcp.pre_test] -> Failed to connect to target server, retrying...
[2016-11-20 17:13:38,839] [INFO] [base._test_info] -> Current test: 53
[2016-11-20 17:13:38,841] [INFO] [server.transmit] -> request(92): 474554202f696d67732f6d6f6e6b65795f6c6f676f2e706e6720485454502f312e310d0a486f73743a203132372e302e302e ...
[2016-11-20 17:13:39,265] [INFO] [base._test_info] -> Current test: 54
[2016-11-20 17:13:39,268] [INFO] [server.transmit] -> request(83): 474554202f696d67732f6d6f6e6b65795f6c6f676f2e706e6720485454502f312e310d0a486f73743a203132372e302e302e ...
[2016-11-20 17:13:40,211] [ERROR] [tcp.pre_test] -> Error: Traceback (most recent call last):
  File "/usr/local/lib/python2.7/dist-packages/katnip/targets/tcp.py", line 57, in pre_test
    sock.connect((self.host, self.port))
  File "/usr/lib/python2.7/socket.py", line 224, in meth
    return getattr(self._sock,name)(*args)
error: [Errno 111] Connection refused

[2016-11-20 17:13:40,214] [ERROR] [tcp.pre_test] -> Failed to connect to target server, retrying...
[2016-11-20 17:13:41,219] [INFO] [base._test_info] -> Current test: 55
[2016-11-20 17:13:41,221] [INFO] [server.transmit] -> request(92): 474554202f696d67732f6d6f6e6b65795f6c6f676f2e706e6720485454502f312e310d0a486f73743a203132372e302e302e ...
[2016-11-20 17:13:41,644] [INFO] [base._test_info] -> Current test: 56
[2016-11-20 17:13:41,647] [INFO] [server.transmit] -> request(92): 474554202f696d67732f6d6f6e6b65795f6c6f676f2e706e6720485454502f312e310d0a486f73743a203132372e302e302e ...
[2016-11-20 17:13:42,594] [ERROR] [tcp.pre_test] -> Error: Traceback (most recent call last):
  File "/usr/local/lib/python2.7/dist-packages/katnip/targets/tcp.py", line 57, in pre_test
    sock.connect((self.host, self.port))
  File "/usr/lib/python2.7/socket.py", line 224, in meth
    return getattr(self._sock,name)(*args)
error: [Errno 111] Connection refused

[2016-11-20 17:13:42,597] [ERROR] [tcp.pre_test] -> Failed to connect to target server, retrying...
[2016-11-20 17:13:43,603] [INFO] [base._test_info] -> Current test: 57
[2016-11-20 17:13:43,605] [INFO] [server.transmit] -> request(92): 474554202f696d67732f6d6f6e6b65795f6c6f676f2e706e6720485454502f312e310d0a486f73743a203132372e302e302e ...
[2016-11-20 17:13:44,022] [INFO] [base._test_info] -> Current test: 58
[2016-11-20 17:13:44,024] [INFO] [server.transmit] -> request(92): 474554202f696d67732f6d6f6e6b65795f6c6f676f2e706e6720485454502f312e310d0a486f73743a203132372e302e302e ...
[2016-11-20 17:13:44,959] [ERROR] [tcp.pre_test] -> Error: Traceback (most recent call last):
  File "/usr/local/lib/python2.7/dist-packages/katnip/targets/tcp.py", line 57, in pre_test
    sock.connect((self.host, self.port))
  File "/usr/lib/python2.7/socket.py", line 224, in meth
    return getattr(self._sock,name)(*args)
error: [Errno 111] Connection refused

[2016-11-20 17:13:44,960] [ERROR] [tcp.pre_test] -> Failed to connect to target server, retrying...
[2016-11-20 17:13:45,966] [INFO] [base._test_info] -> Current test: 59
[2016-11-20 17:13:45,968] [INFO] [server.transmit] -> request(92): 474554202f696d67732f6d6f6e6b65795f6c6f676f2e706e6720485454502f312e310d0a486f73743a203132372e302e302e ...
[2016-11-20 17:13:46,388] [INFO] [base._test_info] -> Current test: 60
[2016-11-20 17:13:46,391] [INFO] [server.transmit] -> request(92): 474554202f696d67732f6d6f6e6b65795f6c6f676f2e706e6720485454502f312e310d0a486f73743a203132372e302e302e ...
[2016-11-20 17:13:47,344] [ERROR] [tcp.pre_test] -> Error: Traceback (most recent call last):
  File "/usr/local/lib/python2.7/dist-packages/katnip/targets/tcp.py", line 57, in pre_test
    sock.connect((self.host, self.port))
  File "/usr/lib/python2.7/socket.py", line 224, in meth
    return getattr(self._sock,name)(*args)
error: [Errno 111] Connection refused

[2016-11-20 17:13:47,345] [ERROR] [tcp.pre_test] -> Failed to connect to target server, retrying...
[2016-11-20 17:13:48,350] [INFO] [base._test_info] -> Current test: 61
[2016-11-20 17:13:48,351] [INFO] [server.transmit] -> request(92): 474554202f696d67732f6d6f6e6b65795f6c6f676f2e706e6720485454502f312e310d0a486f73743a203132372e302e302e ...
[2016-11-20 17:13:48,772] [INFO] [base._test_info] -> Current test: 62
[2016-11-20 17:13:48,774] [INFO] [server.transmit] -> request(83): 474554202f696d67732f6d6f6e6b65795f6c6f676f2e706e6720485454502f312e310d0a486f73743a203132372e302e302e ...
[2016-11-20 17:13:49,701] [ERROR] [tcp.pre_test] -> Error: Traceback (most recent call last):
  File "/usr/local/lib/python2.7/dist-packages/katnip/targets/tcp.py", line 57, in pre_test
    sock.connect((self.host, self.port))
  File "/usr/lib/python2.7/socket.py", line 224, in meth
    return getattr(self._sock,name)(*args)
error: [Errno 111] Connection refused

[2016-11-20 17:13:49,703] [ERROR] [tcp.pre_test] -> Failed to connect to target server, retrying...
[2016-11-20 17:13:50,707] [INFO] [base._test_info] -> Current test: 63
[2016-11-20 17:13:50,709] [INFO] [server.transmit] -> request(92): 474554202f696d67732f6d6f6e6b65795f6c6f676f2e706e6720485454502f312e310d0a486f73743a203132372e302e302e ...
[2016-11-20 17:13:51,128] [INFO] [base._test_info] -> Current test: 64
[2016-11-20 17:13:51,135] [INFO] [server.transmit] -> request(92): 474554202f696d67732f6d6f6e6b65795f6c6f676f2e706e6720485454502f312e310d0a486f73743a203132372e302e302e ...
[2016-11-20 17:13:52,077] [ERROR] [tcp.pre_test] -> Error: Traceback (most recent call last):
  File "/usr/local/lib/python2.7/dist-packages/katnip/targets/tcp.py", line 57, in pre_test
    sock.connect((self.host, self.port))
  File "/usr/lib/python2.7/socket.py", line 224, in meth
    return getattr(self._sock,name)(*args)
error: [Errno 111] Connection refused

[2016-11-20 17:13:52,079] [ERROR] [tcp.pre_test] -> Failed to connect to target server, retrying...
[2016-11-20 17:13:53,084] [INFO] [base._test_info] -> Current test: 65
[2016-11-20 17:13:53,085] [INFO] [server.transmit] -> request(92): 474554202f696d67732f6d6f6e6b65795f6c6f676f2e706e6720485454502f312e310d0a486f73743a203132372e302e302e ...
[2016-11-20 17:13:53,504] [INFO] [base._test_info] -> Current test: 66
[2016-11-20 17:13:53,505] [INFO] [server.transmit] -> request(92): 474554202f696d67732f6d6f6e6b65795f6c6f676f2e706e6720485454502f312e310d0a486f73743a203132372e302e302e ...
[2016-11-20 17:13:54,450] [ERROR] [tcp.pre_test] -> Error: Traceback (most recent call last):
  File "/usr/local/lib/python2.7/dist-packages/katnip/targets/tcp.py", line 57, in pre_test
    sock.connect((self.host, self.port))
  File "/usr/lib/python2.7/socket.py", line 224, in meth
    return getattr(self._sock,name)(*args)
error: [Errno 111] Connection refused

[2016-11-20 17:13:54,460] [ERROR] [tcp.pre_test] -> Failed to connect to target server, retrying...
[2016-11-20 17:13:55,470] [INFO] [base._test_info] -> Current test: 67
[2016-11-20 17:13:55,473] [INFO] [server.transmit] -> request(92): 474554202f696d67732f6d6f6e6b65795f6c6f676f2e706e6720485454502f312e310d0a486f73743a203132372e302e302e ...
[2016-11-20 17:13:55,905] [INFO] [base._test_info] -> Current test: 68
[2016-11-20 17:13:55,910] [INFO] [server.transmit] -> request(92): 474554202f696d67732f6d6f6e6b65795f6c6f676f2e706e6720485454502f312e310d0a486f73743a203132372e302e302e ...
[2016-11-20 17:13:56,849] [ERROR] [tcp.pre_test] -> Error: Traceback (most recent call last):
  File "/usr/local/lib/python2.7/dist-packages/katnip/targets/tcp.py", line 57, in pre_test
    sock.connect((self.host, self.port))
  File "/usr/lib/python2.7/socket.py", line 224, in meth
    return getattr(self._sock,name)(*args)
error: [Errno 111] Connection refused

[2016-11-20 17:13:56,852] [ERROR] [tcp.pre_test] -> Failed to connect to target server, retrying...
[2016-11-20 17:13:57,859] [INFO] [base._test_info] -> Current test: 69
[2016-11-20 17:13:57,861] [INFO] [server.transmit] -> request(92): 474554202f696d67732f6d6f6e6b65795f6c6f676f2e706e6720485454502f312e310d0a486f73743a203132372e302e302e ...
[2016-11-20 17:13:58,286] [INFO] [base._test_info] -> Current test: 70
[2016-11-20 17:13:58,292] [INFO] [server.transmit] -> request(87): 474554202f696d67732f6d6f6e6b65795f6c6f676f2e706e6720485454502f312e310d0a486f73743a203132372e302e302e ...
[2016-11-20 17:13:59,286] [ERROR] [tcp.pre_test] -> Error: Traceback (most recent call last):
  File "/usr/local/lib/python2.7/dist-packages/katnip/targets/tcp.py", line 57, in pre_test
    sock.connect((self.host, self.port))
  File "/usr/lib/python2.7/socket.py", line 224, in meth
    return getattr(self._sock,name)(*args)
error: [Errno 111] Connection refused

[2016-11-20 17:13:59,288] [ERROR] [tcp.pre_test] -> Failed to connect to target server, retrying...
[2016-11-20 17:14:00,295] [INFO] [base._test_info] -> Current test: 71
[2016-11-20 17:14:00,297] [INFO] [server.transmit] -> request(87): 474554202f696d67732f6d6f6e6b65795f6c6f676f2e706e6720485454502f312e310d0a486f73743a203132372e302e302e ...
[2016-11-20 17:14:00,715] [INFO] [base._test_info] -> Current test: 72
[2016-11-20 17:14:00,717] [INFO] [server.transmit] -> request(87): 474554202f696d67732f6d6f6e6b65795f6c6f676f2e706e6720485454502f312e310d0a486f73743a203132372e302e302e ...
[2016-11-20 17:14:01,670] [ERROR] [tcp.pre_test] -> Error: Traceback (most recent call last):
  File "/usr/local/lib/python2.7/dist-packages/katnip/targets/tcp.py", line 57, in pre_test
    sock.connect((self.host, self.port))
  File "/usr/lib/python2.7/socket.py", line 224, in meth
    return getattr(self._sock,name)(*args)
error: [Errno 111] Connection refused

[2016-11-20 17:14:01,671] [ERROR] [tcp.pre_test] -> Failed to connect to target server, retrying...
[2016-11-20 17:14:02,676] [INFO] [base._test_info] -> Current test: 73
[2016-11-20 17:14:02,679] [INFO] [server.transmit] -> request(87): 474554202f696d67732f6d6f6e6b65795f6c6f676f2e706e6720485454502f312e310d0a486f73743a203132372e302e302e ...
[2016-11-20 17:14:03,107] [INFO] [base._test_info] -> Current test: 74
[2016-11-20 17:14:03,110] [INFO] [server.transmit] -> request(91): 474554202f696d67732f6d6f6e6b65795f6c6f676f2e706e6720485454502f312e310d0a486f73743a203132372e302e302e ...
[2016-11-20 17:14:04,060] [ERROR] [tcp.pre_test] -> Error: Traceback (most recent call last):
  File "/usr/local/lib/python2.7/dist-packages/katnip/targets/tcp.py", line 57, in pre_test
    sock.connect((self.host, self.port))
  File "/usr/lib/python2.7/socket.py", line 224, in meth
    return getattr(self._sock,name)(*args)
error: [Errno 111] Connection refused

[2016-11-20 17:14:04,064] [ERROR] [tcp.pre_test] -> Failed to connect to target server, retrying...
[2016-11-20 17:14:05,074] [INFO] [base._test_info] -> Current test: 75
[2016-11-20 17:14:05,080] [INFO] [server.transmit] -> request(123): 474554202f696d67732f6d6f6e6b65795f6c6f676f2e706e6720485454502f312e310d0a486f73743a203132372e302e302e ...
[2016-11-20 17:14:05,505] [INFO] [base._test_info] -> Current test: 76
[2016-11-20 17:14:05,507] [INFO] [server.transmit] -> request(483): 474554202f696d67732f6d6f6e6b65795f6c6f676f2e706e6720485454502f312e310d0a486f73743a203132372e302e302e ...
[2016-11-20 17:14:06,458] [ERROR] [tcp.pre_test] -> Error: Traceback (most recent call last):
  File "/usr/local/lib/python2.7/dist-packages/katnip/targets/tcp.py", line 57, in pre_test
    sock.connect((self.host, self.port))
  File "/usr/lib/python2.7/socket.py", line 224, in meth
    return getattr(self._sock,name)(*args)
error: [Errno 111] Connection refused

[2016-11-20 17:14:06,459] [ERROR] [tcp.pre_test] -> Failed to connect to target server, retrying...
[2016-11-20 17:14:07,463] [INFO] [base._test_info] -> Current test: 77
[2016-11-20 17:14:07,465] [INFO] [server.transmit] -> request(88): 474554202f696d67732f6d6f6e6b65795f6c6f676f2e706e6720485454502f312e310d0a486f73743a203132372e302e302e ...
[2016-11-20 17:14:07,908] [INFO] [base._test_info] -> Current test: 78
[2016-11-20 17:14:07,914] [INFO] [server.transmit] -> request(88): 474554202f696d67732f6d6f6e6b65795f6c6f676f2e706e6720485454502f312e310d0a486f73743a203132372e302e302e ...
[2016-11-20 17:14:08,340] [INFO] [base._test_info] -> Current test: 79
[2016-11-20 17:14:08,342] [INFO] [server.transmit] -> request(88): 474554202f696d67732f6d6f6e6b65795f6c6f676f2e706e6720485454502f312e310d0a486f73743a203132372e302e302e ...
[2016-11-20 17:14:09,278] [ERROR] [tcp.pre_test] -> Error: Traceback (most recent call last):
  File "/usr/local/lib/python2.7/dist-packages/katnip/targets/tcp.py", line 57, in pre_test
    sock.connect((self.host, self.port))
  File "/usr/lib/python2.7/socket.py", line 224, in meth
    return getattr(self._sock,name)(*args)
error: [Errno 111] Connection refused

[2016-11-20 17:14:09,282] [ERROR] [tcp.pre_test] -> Failed to connect to target server, retrying...
[2016-11-20 17:14:10,287] [INFO] [base._test_info] -> Current test: 80
[2016-11-20 17:14:10,289] [INFO] [server.transmit] -> request(88): 474554202f696d67732f6d6f6e6b65795f6c6f676f2e706e6720485454502f312e310d0a486f73743a203132372e302e302e ...
[2016-11-20 17:14:10,706] [INFO] [base._test_info] -> Current test: 81
[2016-11-20 17:14:10,711] [INFO] [server.transmit] -> request(87): 474554202f696d67732f6d6f6e6b65795f6c6f676f2e706e6720485454502f312e310d0a486f73743a203132372e302e302e ...
[2016-11-20 17:14:11,636] [ERROR] [tcp.pre_test] -> Error: Traceback (most recent call last):
  File "/usr/local/lib/python2.7/dist-packages/katnip/targets/tcp.py", line 57, in pre_test
    sock.connect((self.host, self.port))
  File "/usr/lib/python2.7/socket.py", line 224, in meth
    return getattr(self._sock,name)(*args)
error: [Errno 111] Connection refused

[2016-11-20 17:14:11,637] [ERROR] [tcp.pre_test] -> Failed to connect to target server, retrying...
[2016-11-20 17:14:12,643] [INFO] [base._test_info] -> Current test: 82
[2016-11-20 17:14:12,646] [INFO] [server.transmit] -> request(87): 474554202f696d67732f6d6f6e6b65795f6c6f676f2e706e6720485454502f312e310d0a486f73743a203132372e302e302e ...
[2016-11-20 17:14:13,062] [INFO] [base._test_info] -> Current test: 83
[2016-11-20 17:14:13,065] [INFO] [server.transmit] -> request(87): 474554202f696d67732f6d6f6e6b65795f6c6f676f2e706e6720485454502f312e310d0a486f73743a203132372e302e302e ...
[2016-11-20 17:14:13,997] [INFO] [base._test_info] -> Current test: 84
[2016-11-20 17:14:13,999] [INFO] [server.transmit] -> request(87): 474554202f696d67732f6d6f6e6b65795f6c6f676f2e706e6720485454502f312e310d0a486f73743a203132372e302e302e ...
[2016-11-20 17:14:14,928] [ERROR] [tcp.pre_test] -> Error: Traceback (most recent call last):
  File "/usr/local/lib/python2.7/dist-packages/katnip/targets/tcp.py", line 57, in pre_test
    sock.connect((self.host, self.port))
  File "/usr/lib/python2.7/socket.py", line 224, in meth
    return getattr(self._sock,name)(*args)
error: [Errno 111] Connection refused

[2016-11-20 17:14:14,931] [ERROR] [tcp.pre_test] -> Failed to connect to target server, retrying...
[2016-11-20 17:14:15,936] [INFO] [base._test_info] -> Current test: 85
[2016-11-20 17:14:15,937] [INFO] [server.transmit] -> request(87): 474554202f696d67732f6d6f6e6b65795f6c6f676f2e706e6720485454502f312e310d0a486f73743a203132372e302e302e ...
[2016-11-20 17:14:16,357] [INFO] [base._test_info] -> Current test: 86
[2016-11-20 17:14:16,360] [INFO] [server.transmit] -> request(87): 474554202f696d67732f6d6f6e6b65795f6c6f676f2e706e6720485454502f312e310d0a486f73743a203132372e302e302e ...
[2016-11-20 17:14:17,312] [ERROR] [tcp.pre_test] -> Error: Traceback (most recent call last):
  File "/usr/local/lib/python2.7/dist-packages/katnip/targets/tcp.py", line 57, in pre_test
    sock.connect((self.host, self.port))
  File "/usr/lib/python2.7/socket.py", line 224, in meth
    return getattr(self._sock,name)(*args)
error: [Errno 111] Connection refused

[2016-11-20 17:14:17,314] [ERROR] [tcp.pre_test] -> Failed to connect to target server, retrying...
[2016-11-20 17:14:18,320] [INFO] [base._test_info] -> Current test: 87
[2016-11-20 17:14:18,322] [INFO] [server.transmit] -> request(87): 474554202f696d67732f6d6f6e6b65795f6c6f676f2e706e6720485454502f312e310d0a486f73743a203132372e302e302e ...
[2016-11-20 17:14:18,754] [INFO] [base._test_info] -> Current test: 88
[2016-11-20 17:14:18,762] [INFO] [server.transmit] -> request(87): 474554202f696d67732f6d6f6e6b65795f6c6f676f2e706e6720485454502f312e310d0a486f73743a203132372e302e302e ...
[2016-11-20 17:14:19,186] [INFO] [base._test_info] -> Current test: 89
[2016-11-20 17:14:19,191] [INFO] [server.transmit] -> request(87): 474554202f696d67732f6d6f6e6b65795f6c6f676f2e706e6720485454502f312e310d0a486f73743a203132372e302e302e ...
[2016-11-20 17:14:20,121] [ERROR] [tcp.pre_test] -> Error: Traceback (most recent call last):
  File "/usr/local/lib/python2.7/dist-packages/katnip/targets/tcp.py", line 57, in pre_test
    sock.connect((self.host, self.port))
  File "/usr/lib/python2.7/socket.py", line 224, in meth
    return getattr(self._sock,name)(*args)
error: [Errno 111] Connection refused

[2016-11-20 17:14:20,122] [ERROR] [tcp.pre_test] -> Failed to connect to target server, retrying...
[2016-11-20 17:14:21,127] [INFO] [base._test_info] -> Current test: 90
[2016-11-20 17:14:21,130] [INFO] [server.transmit] -> request(87): 474554202f696d67732f6d6f6e6b65795f6c6f676f2e706e6720485454502f312e310d0a486f73743a203132372e302e302e ...
[2016-11-20 17:14:21,558] [INFO] [base._test_info] -> Current test: 91
[2016-11-20 17:14:21,562] [INFO] [server.transmit] -> request(87): 474554202f696d67732f6d6f6e6b65795f6c6f676f2e706e6720485454502f312e310d0a486f73743a203132372e302e302e ...
[2016-11-20 17:14:22,496] [ERROR] [tcp.pre_test] -> Error: Traceback (most recent call last):
  File "/usr/local/lib/python2.7/dist-packages/katnip/targets/tcp.py", line 57, in pre_test
    sock.connect((self.host, self.port))
  File "/usr/lib/python2.7/socket.py", line 224, in meth
    return getattr(self._sock,name)(*args)
error: [Errno 111] Connection refused

[2016-11-20 17:14:22,498] [ERROR] [tcp.pre_test] -> Failed to connect to target server, retrying...
[2016-11-20 17:14:23,502] [INFO] [base._test_info] -> Current test: 92
[2016-11-20 17:14:23,504] [INFO] [server.transmit] -> request(87): 474554202f696d67732f6d6f6e6b65795f6c6f676f2e706e6720485454502f312e310d0a486f73743a203132372e302e302e ...
[2016-11-20 17:14:23,921] [INFO] [base._test_info] -> Current test: 93
[2016-11-20 17:14:23,924] [INFO] [server.transmit] -> request(87): 474554202f696d67732f6d6f6e6b65795f6c6f676f2e706e6720485454502f312e310d0a486f73743a203132372e302e302e ...
[2016-11-20 17:14:24,854] [ERROR] [tcp.pre_test] -> Error: Traceback (most recent call last):
  File "/usr/local/lib/python2.7/dist-packages/katnip/targets/tcp.py", line 57, in pre_test
    sock.connect((self.host, self.port))
  File "/usr/lib/python2.7/socket.py", line 224, in meth
    return getattr(self._sock,name)(*args)
error: [Errno 111] Connection refused

[2016-11-20 17:14:24,855] [ERROR] [tcp.pre_test] -> Failed to connect to target server, retrying...
[2016-11-20 17:14:25,860] [INFO] [base._test_info] -> Current test: 94
[2016-11-20 17:14:25,863] [INFO] [server.transmit] -> request(87): 474554202f696d67732f6d6f6e6b65795f6c6f676f2e706e6720485454502f312e310d0a486f73743a203132372e302e302e ...
[2016-11-20 17:14:26,281] [INFO] [base._test_info] -> Current test: 95
[2016-11-20 17:14:26,284] [INFO] [server.transmit] -> request(87): 474554202f696d67732f6d6f6e6b65795f6c6f676f2e706e6720485454502f312e310d0a486f73743a203132372e302e302e ...
[2016-11-20 17:14:27,213] [ERROR] [tcp.pre_test] -> Error: Traceback (most recent call last):
  File "/usr/local/lib/python2.7/dist-packages/katnip/targets/tcp.py", line 57, in pre_test
    sock.connect((self.host, self.port))
  File "/usr/lib/python2.7/socket.py", line 224, in meth
    return getattr(self._sock,name)(*args)
error: [Errno 111] Connection refused

[2016-11-20 17:14:27,213] [ERROR] [tcp.pre_test] -> Failed to connect to target server, retrying...
[2016-11-20 17:14:28,218] [INFO] [base._test_info] -> Current test: 96
[2016-11-20 17:14:28,220] [INFO] [server.transmit] -> request(87): 474554202f696d67732f6d6f6e6b65795f6c6f676f2e706e6720485454502f312e310d0a486f73743a203132372e302e302e ...
[2016-11-20 17:14:28,639] [INFO] [base._test_info] -> Current test: 97
[2016-11-20 17:14:28,642] [INFO] [server.transmit] -> request(87): 474554202f696d67732f6d6f6e6b65795f6c6f676f2e706e6720485454502f312e310d0a486f73743a203132372e302e302e ...
[2016-11-20 17:14:29,566] [ERROR] [tcp.pre_test] -> Error: Traceback (most recent call last):
  File "/usr/local/lib/python2.7/dist-packages/katnip/targets/tcp.py", line 57, in pre_test
    sock.connect((self.host, self.port))
  File "/usr/lib/python2.7/socket.py", line 224, in meth
    return getattr(self._sock,name)(*args)
error: [Errno 111] Connection refused

[2016-11-20 17:14:29,568] [ERROR] [tcp.pre_test] -> Failed to connect to target server, retrying...
[2016-11-20 17:14:30,572] [INFO] [base._test_info] -> Current test: 98
[2016-11-20 17:14:30,574] [INFO] [server.transmit] -> request(87): 474554202f696d67732f6d6f6e6b65795f6c6f676f2e706e6720485454502f312e310d0a486f73743a203132372e302e302e ...
[2016-11-20 17:14:30,992] [INFO] [base._test_info] -> Current test: 99
[2016-11-20 17:14:30,995] [INFO] [server.transmit] -> request(87): 474554202f696d67732f6d6f6e6b65795f6c6f676f2e706e6720485454502f312e310d0a486f73743a203132372e302e302e ...
[2016-11-20 17:14:31,932] [ERROR] [tcp.pre_test] -> Error: Traceback (most recent call last):
  File "/usr/local/lib/python2.7/dist-packages/katnip/targets/tcp.py", line 57, in pre_test
    sock.connect((self.host, self.port))
  File "/usr/lib/python2.7/socket.py", line 224, in meth
    return getattr(self._sock,name)(*args)
error: [Errno 111] Connection refused

[2016-11-20 17:14:31,933] [ERROR] [tcp.pre_test] -> Failed to connect to target server, retrying...
[2016-11-20 17:14:32,937] [INFO] [base._test_info] -> Current test: 100
[2016-11-20 17:14:32,939] [INFO] [server.transmit] -> request(87): 474554202f696d67732f6d6f6e6b65795f6c6f676f2e706e6720485454502f312e310d0a486f73743a203132372e302e302e ...
[2016-11-20 17:14:33,356] [INFO] [base._test_info] -> Current test: 101
[2016-11-20 17:14:33,358] [INFO] [server.transmit] -> request(87): 474554202f696d67732f6d6f6e6b65795f6c6f676f2e706e6720485454502f312e310d0a486f73743a203132372e302e302e ...
[2016-11-20 17:14:34,283] [ERROR] [tcp.pre_test] -> Error: Traceback (most recent call last):
  File "/usr/local/lib/python2.7/dist-packages/katnip/targets/tcp.py", line 57, in pre_test
    sock.connect((self.host, self.port))
  File "/usr/lib/python2.7/socket.py", line 224, in meth
    return getattr(self._sock,name)(*args)
error: [Errno 111] Connection refused

[2016-11-20 17:14:34,284] [ERROR] [tcp.pre_test] -> Failed to connect to target server, retrying...
[2016-11-20 17:14:35,290] [INFO] [base._test_info] -> Current test: 102
[2016-11-20 17:14:35,294] [INFO] [server.transmit] -> request(87): 474554202f696d67732f6d6f6e6b65795f6c6f676f2e706e6720485454502f312e310d0a486f73743a203132372e302e302e ...
[2016-11-20 17:14:35,720] [INFO] [base._test_info] -> Current test: 103
[2016-11-20 17:14:35,722] [INFO] [server.transmit] -> request(87): 474554202f696d67732f6d6f6e6b65795f6c6f676f2e706e6720485454502f312e310d0a486f73743a203132372e302e302e ...
[2016-11-20 17:14:36,652] [ERROR] [tcp.pre_test] -> Error: Traceback (most recent call last):
  File "/usr/local/lib/python2.7/dist-packages/katnip/targets/tcp.py", line 57, in pre_test
    sock.connect((self.host, self.port))
  File "/usr/lib/python2.7/socket.py", line 224, in meth
    return getattr(self._sock,name)(*args)
error: [Errno 111] Connection refused

[2016-11-20 17:14:36,655] [ERROR] [tcp.pre_test] -> Failed to connect to target server, retrying...
[2016-11-20 17:14:37,659] [INFO] [base._test_info] -> Current test: 104
[2016-11-20 17:14:37,660] [INFO] [server.transmit] -> request(87): 474554202f696d67732f6d6f6e6b65795f6c6f676f2e706e6720485454502f312e310d0a486f73743a203132372e302e302e ...
[2016-11-20 17:14:38,083] [INFO] [base._test_info] -> Current test: 105
[2016-11-20 17:14:38,099] [INFO] [server.transmit] -> request(87): 474554202f696d67732f6d6f6e6b65795f6c6f676f2e706e6720485454502f312e310d0a486f73743a203132372e302e302e ...
[2016-11-20 17:14:38,520] [INFO] [base._test_info] -> Current test: 106
[2016-11-20 17:14:38,522] [INFO] [server.transmit] -> request(87): 474554202f696d67732f6d6f6e6b65795f6c6f676f2e706e6720485454502f312e310d0a486f73743a203132372e302e302e ...
[2016-11-20 17:14:39,447] [ERROR] [tcp.pre_test] -> Error: Traceback (most recent call last):
  File "/usr/local/lib/python2.7/dist-packages/katnip/targets/tcp.py", line 57, in pre_test
    sock.connect((self.host, self.port))
  File "/usr/lib/python2.7/socket.py", line 224, in meth
    return getattr(self._sock,name)(*args)
error: [Errno 111] Connection refused

[2016-11-20 17:14:39,450] [ERROR] [tcp.pre_test] -> Failed to connect to target server, retrying...
[2016-11-20 17:14:40,455] [INFO] [base._test_info] -> Current test: 107
[2016-11-20 17:14:40,457] [INFO] [server.transmit] -> request(87): 474554202f696d67732f6d6f6e6b65795f6c6f676f2e706e6720485454502f312e310d0a486f73743a203132372e302e302e ...
[2016-11-20 17:14:40,887] [INFO] [base._test_info] -> Current test: 108
[2016-11-20 17:14:40,893] [INFO] [server.transmit] -> request(87): 474554202f696d67732f6d6f6e6b65795f6c6f676f2e706e6720485454502f312e310d0a486f73743a203132372e302e302e ...
[2016-11-20 17:14:41,315] [INFO] [base._test_info] -> Current test: 109
[2016-11-20 17:14:41,317] [INFO] [server.transmit] -> request(87): 474554202f696d67732f6d6f6e6b65795f6c6f676f2e706e6720485454502f312e310d0a486f73743a203132372e302e302e ...
[2016-11-20 17:14:42,253] [ERROR] [tcp.pre_test] -> Error: Traceback (most recent call last):
  File "/usr/local/lib/python2.7/dist-packages/katnip/targets/tcp.py", line 57, in pre_test
    sock.connect((self.host, self.port))
  File "/usr/lib/python2.7/socket.py", line 224, in meth
    return getattr(self._sock,name)(*args)
error: [Errno 111] Connection refused

[2016-11-20 17:14:42,263] [ERROR] [tcp.pre_test] -> Failed to connect to target server, retrying...
[2016-11-20 17:14:43,272] [INFO] [base._test_info] -> Current test: 110
[2016-11-20 17:14:43,274] [INFO] [server.transmit] -> request(99): 474554202f696d67732f6d6f6e6b65795f6c6f676f2e706e6720485454502f312e310d0a486f73743a203132372e302e302e ...
[2016-11-20 17:14:43,696] [INFO] [base._test_info] -> Current test: 111
[2016-11-20 17:14:43,699] [INFO] [server.transmit] -> request(107): 474554202f696d67732f6d6f6e6b65795f6c6f676f2e706e6720485454502f312e310d0a486f73743a203132372e302e302e ...
[2016-11-20 17:14:44,678] [INFO] [base._test_info] -> Current test: 112
[2016-11-20 17:14:44,683] [INFO] [server.transmit] -> request(83): 474554202f696d67732f6d6f6e6b65795f6c6f676f2e706e6720485454502f312e310d0a486f73743a203132372e302e302e ...
[2016-11-20 17:14:45,112] [INFO] [base._end_message] -> 
                         --------------------------------------------------
                         Finished fuzzing session
                         Target: TcpTarget

                         Tested 113 mutations
                         Mutation range: 0 to 112
                         Failure count: 0
                         --------------------------------------------------
            
