[2016-11-20 16:21:15,923] [INFO] [base._load_session] -> No session loaded
[2016-11-20 16:21:15,939] [INFO] [graph.hash] -> hash of template HTTP_GET_REQUEST_BYTE_RANGE is -8632720920980739004
[2016-11-20 16:21:15,941] [INFO] [graph.hash] -> hash of model is 6746718840684598993
[2016-11-20 16:21:15,945] [INFO] [base._start_message] -> 
                 --------------------------------------------------
                 Starting fuzzing session
                 Target: TcpTarget
                 UI: WebInterface listening on 0.0.0.0:26000
                 Log: ./kittylogs/kitty_20161120-162109.log

                 Total possible mutation count: 343
                 Fuzzing the mutation range: 0 to 342
                 --------------------------------------------------
                                 Happy hacking
                 --------------------------------------------------
            
[2016-11-20 16:21:15,946] [INFO] [base.start] -> Performing environment test
[2016-11-20 16:21:16,019] [ERROR] [tcp.pre_test] -> Error: Traceback (most recent call last):
  File "/usr/local/lib/python2.7/dist-packages/katnip/targets/tcp.py", line 57, in pre_test
    sock.connect((self.host, self.port))
  File "/usr/lib/python2.7/socket.py", line 224, in meth
    return getattr(self._sock,name)(*args)
error: [Errno 111] Connection refused

[2016-11-20 16:21:16,021] [ERROR] [tcp.pre_test] -> Failed to connect to target server, retrying...
[2016-11-20 16:21:17,024] [INFO] [base._test_info] -> Current test: -1
[2016-11-20 16:21:17,026] [INFO] [server.transmit] -> request(275): 474554202f4269674275636b42756e6e795f333230783138302e6d70340d0a486f73743a207777772e676f6f676c652e636f ...
[2016-11-20 16:21:17,027] [INFO] [server._start] -> should keep running? True
[2016-11-20 16:21:17,059] [INFO] [base._test_info] -> Current test: 0
[2016-11-20 16:21:17,068] [INFO] [server.transmit] -> request(300): 474554202f4269674275636b42756e6e795f333230783138302e6d70342f4269674275636b42756e6e795f33323078313830 ...
[2016-11-20 16:21:17,999] [ERROR] [tcp.pre_test] -> Error: Traceback (most recent call last):
  File "/usr/local/lib/python2.7/dist-packages/katnip/targets/tcp.py", line 57, in pre_test
    sock.connect((self.host, self.port))
  File "/usr/lib/python2.7/socket.py", line 224, in meth
    return getattr(self._sock,name)(*args)
error: [Errno 111] Connection refused

[2016-11-20 16:21:18,000] [ERROR] [tcp.pre_test] -> Failed to connect to target server, retrying...
[2016-11-20 16:21:19,007] [INFO] [base._test_info] -> Current test: 1
[2016-11-20 16:21:19,010] [INFO] [server.transmit] -> request(500): 474554202f4269674275636b42756e6e795f333230783138302e6d70342f4269674275636b42756e6e795f33323078313830 ...
[2016-11-20 16:21:19,431] [INFO] [base._test_info] -> Current test: 2
[2016-11-20 16:21:19,434] [INFO] [server.transmit] -> request(2750): 474554202f4269674275636b42756e6e795f333230783138302e6d70342f4269674275636b42756e6e795f33323078313830 ...
[2016-11-20 16:21:20,368] [ERROR] [tcp.pre_test] -> Error: Traceback (most recent call last):
  File "/usr/local/lib/python2.7/dist-packages/katnip/targets/tcp.py", line 57, in pre_test
    sock.connect((self.host, self.port))
  File "/usr/lib/python2.7/socket.py", line 224, in meth
    return getattr(self._sock,name)(*args)
error: [Errno 111] Connection refused

[2016-11-20 16:21:20,370] [ERROR] [tcp.pre_test] -> Failed to connect to target server, retrying...
[2016-11-20 16:21:21,375] [INFO] [base._test_info] -> Current test: 3
[2016-11-20 16:21:21,377] [INFO] [server.transmit] -> request(276): 474554202f4269674275636b42756e6e795f333230783138302e6d7034fe0d0a486f73743a207777772e676f6f676c652e63 ...
[2016-11-20 16:21:21,796] [INFO] [base._test_info] -> Current test: 4
[2016-11-20 16:21:21,799] [INFO] [server.transmit] -> request(276): 47455420002f4269674275636b42756e6e795f333230783138302e6d70340d0a486f73743a207777772e676f6f676c652e63 ...
[2016-11-20 16:21:22,733] [ERROR] [tcp.pre_test] -> Error: Traceback (most recent call last):
  File "/usr/local/lib/python2.7/dist-packages/katnip/targets/tcp.py", line 57, in pre_test
    sock.connect((self.host, self.port))
  File "/usr/lib/python2.7/socket.py", line 224, in meth
    return getattr(self._sock,name)(*args)
error: [Errno 111] Connection refused

[2016-11-20 16:21:22,734] [ERROR] [tcp.pre_test] -> Failed to connect to target server, retrying...
[2016-11-20 16:21:23,741] [INFO] [base._test_info] -> Current test: 5
[2016-11-20 16:21:23,743] [INFO] [server.transmit] -> request(276): 474554202f4269674275636b42756e6e00795f333230783138302e6d70340d0a486f73743a207777772e676f6f676c652e63 ...
[2016-11-20 16:21:24,164] [INFO] [base._test_info] -> Current test: 6
[2016-11-20 16:21:24,168] [INFO] [server.transmit] -> request(276): 474554202f4269674275636b42756e6e795f333230783138302e6d7034000d0a486f73743a207777772e676f6f676c652e63 ...
[2016-11-20 16:21:25,108] [ERROR] [tcp.pre_test] -> Error: Traceback (most recent call last):
  File "/usr/local/lib/python2.7/dist-packages/katnip/targets/tcp.py", line 57, in pre_test
    sock.connect((self.host, self.port))
  File "/usr/lib/python2.7/socket.py", line 224, in meth
    return getattr(self._sock,name)(*args)
error: [Errno 111] Connection refused

[2016-11-20 16:21:25,109] [ERROR] [tcp.pre_test] -> Failed to connect to target server, retrying...
[2016-11-20 16:21:26,114] [INFO] [base._test_info] -> Current test: 7
[2016-11-20 16:21:26,117] [INFO] [server.transmit] -> request(250): 474554200d0a486f73743a207777772e676f6f676c652e636f6d0d0a557365722d4167656e743a204d6f7a696c6c612f352e ...
[2016-11-20 16:21:26,543] [INFO] [base._test_info] -> Current test: 8
[2016-11-20 16:21:26,547] [INFO] [server.transmit] -> request(2298): 4745542025732573257325732573257325732573257325732573257325732573257325732573257325732573257325732573 ...
[2016-11-20 16:21:27,479] [ERROR] [tcp.pre_test] -> Error: Traceback (most recent call last):
  File "/usr/local/lib/python2.7/dist-packages/katnip/targets/tcp.py", line 57, in pre_test
    sock.connect((self.host, self.port))
  File "/usr/lib/python2.7/socket.py", line 224, in meth
    return getattr(self._sock,name)(*args)
error: [Errno 111] Connection refused

[2016-11-20 16:21:27,484] [ERROR] [tcp.pre_test] -> Failed to connect to target server, retrying...
[2016-11-20 16:21:28,488] [INFO] [base._test_info] -> Current test: 9
[2016-11-20 16:21:28,490] [INFO] [server.transmit] -> request(506): 4745542025732573257325732573257325732573257325732573257325732573257325732573257325732573257325732573 ...
[2016-11-20 16:21:28,912] [INFO] [base._test_info] -> Current test: 10
[2016-11-20 16:21:28,916] [INFO] [server.transmit] -> request(282): 4745542025732573257325732573257325732573257325732573257325732573257325730d0a486f73743a207777772e676f ...
[2016-11-20 16:21:29,846] [ERROR] [tcp.pre_test] -> Error: Traceback (most recent call last):
  File "/usr/local/lib/python2.7/dist-packages/katnip/targets/tcp.py", line 57, in pre_test
    sock.connect((self.host, self.port))
  File "/usr/lib/python2.7/socket.py", line 224, in meth
    return getattr(self._sock,name)(*args)
error: [Errno 111] Connection refused

[2016-11-20 16:21:29,847] [ERROR] [tcp.pre_test] -> Failed to connect to target server, retrying...
