[2016-11-20 16:58:23,661] [INFO] [base._load_session] -> No session loaded
[2016-11-20 16:58:23,667] [INFO] [graph.hash] -> hash of template HTTP_GET_MONKEY_2 is -4048744799976146252
[2016-11-20 16:58:23,667] [INFO] [graph.hash] -> hash of model is 5091681961902625966
[2016-11-20 16:58:23,675] [INFO] [base._start_message] -> 
                 --------------------------------------------------
                 Starting fuzzing session
                 Target: TcpTarget
                 UI: WebInterface listening on 0.0.0.0:26000
                 Log: ./kittylogs/kitty_20161120-165823.log

                 Total possible mutation count: 1064
                 Fuzzing the mutation range: 0 to 1063
                 --------------------------------------------------
                                 Happy hacking
                 --------------------------------------------------
            
[2016-11-20 16:58:23,675] [INFO] [base.start] -> Performing environment test
[2016-11-20 16:58:23,689] [INFO] [base._test_info] -> Current test: -1
[2016-11-20 16:58:23,689] [INFO] [server.transmit] -> request(87): 474554202f696d67732f6d6f6e6b65795f6c6f676f2e706e6720485454502f312e310d0a486f73743a203132372e302e302e ...
[2016-11-20 16:58:24,210] [INFO] [server._start] -> should keep running? True
[2016-11-20 16:58:24,223] [ERROR] [tcp.pre_test] -> Error: Traceback (most recent call last):
  File "/usr/local/lib/python2.7/dist-packages/katnip/targets/tcp.py", line 57, in pre_test
    sock.connect((self.host, self.port))
  File "/usr/lib/python2.7/socket.py", line 224, in meth
    return getattr(self._sock,name)(*args)
error: [Errno 111] Connection refused

[2016-11-20 16:58:24,226] [ERROR] [tcp.pre_test] -> Failed to connect to target server, retrying...
[2016-11-20 16:58:25,231] [INFO] [base._test_info] -> Current test: 0
[2016-11-20 16:58:25,233] [INFO] [server.transmit] -> request(90): 474554474554202f696d67732f6d6f6e6b65795f6c6f676f2e706e6720485454502f312e310d0a486f73743a203132372e30 ...
[2016-11-20 16:58:25,658] [INFO] [base._test_info] -> Current test: 1
[2016-11-20 16:58:25,661] [INFO] [server.transmit] -> request(114): 474554474554474554474554474554474554474554474554474554474554202f696d67732f6d6f6e6b65795f6c6f676f2e70 ...
[2016-11-20 16:58:26,587] [ERROR] [tcp.pre_test] -> Error: Traceback (most recent call last):
  File "/usr/local/lib/python2.7/dist-packages/katnip/targets/tcp.py", line 57, in pre_test
    sock.connect((self.host, self.port))
  File "/usr/lib/python2.7/socket.py", line 224, in meth
    return getattr(self._sock,name)(*args)
error: [Errno 111] Connection refused

[2016-11-20 16:58:26,591] [ERROR] [tcp.pre_test] -> Failed to connect to target server, retrying...
[2016-11-20 16:58:27,595] [INFO] [base._test_info] -> Current test: 2
[2016-11-20 16:58:27,597] [INFO] [server.transmit] -> request(384): 4745544745544745544745544745544745544745544745544745544745544745544745544745544745544745544745544745 ...
[2016-11-20 16:58:28,018] [INFO] [base._test_info] -> Current test: 3
[2016-11-20 16:58:28,021] [INFO] [server.transmit] -> request(88): 474554fe202f696d67732f6d6f6e6b65795f6c6f676f2e706e6720485454502f312e310d0a486f73743a203132372e302e30 ...
