[2016-11-20 16:25:51,568] [INFO] [base._load_session] -> No session loaded
[2016-11-20 16:25:51,578] [INFO] [graph.hash] -> hash of template HTTP_GET_MONKEY_0 is 1904966079126103355
[2016-11-20 16:25:51,579] [INFO] [graph.hash] -> hash of model is 2856277519548850953
[2016-11-20 16:25:51,583] [INFO] [base._start_message] -> 
                 --------------------------------------------------
                 Starting fuzzing session
                 Target: TcpTarget
                 UI: WebInterface listening on 0.0.0.0:26000
                 Log: ./kittylogs/kitty_20161120-162550.log

                 Total possible mutation count: 130
                 Fuzzing the mutation range: 0 to 129
                 --------------------------------------------------
                                 Happy hacking
                 --------------------------------------------------
            
[2016-11-20 16:25:51,586] [INFO] [base.start] -> Performing environment test
[2016-11-20 16:25:51,612] [INFO] [base._test_info] -> Current test: -1
[2016-11-20 16:25:51,614] [INFO] [server.transmit] -> request(28): 474554202f696e6465782e68746d6c20485454502f312e310d0a0d0a
[2016-11-20 16:25:52,143] [INFO] [server._start] -> should keep running? True
[2016-11-20 16:25:52,154] [ERROR] [tcp.pre_test] -> Error: Traceback (most recent call last):
  File "/usr/local/lib/python2.7/dist-packages/katnip/targets/tcp.py", line 57, in pre_test
    sock.connect((self.host, self.port))
  File "/usr/lib/python2.7/socket.py", line 224, in meth
    return getattr(self._sock,name)(*args)
error: [Errno 111] Connection refused

[2016-11-20 16:25:52,155] [ERROR] [tcp.pre_test] -> Failed to connect to target server, retrying...
[2016-11-20 16:25:53,163] [INFO] [base._test_info] -> Current test: 0
[2016-11-20 16:25:53,165] [INFO] [server.transmit] -> request(32): 474554202f696e6465782e68746d6c2048545450485454502f312e310d0a0d0a
[2016-11-20 16:25:53,583] [INFO] [base._test_info] -> Current test: 1
[2016-11-20 16:25:53,585] [INFO] [server.transmit] -> request(64): 474554202f696e6465782e68746d6c2048545450485454504854545048545450485454504854545048545450485454504854 ...
[2016-11-20 16:25:54,513] [INFO] [base._test_info] -> Current test: 2
[2016-11-20 16:25:54,515] [INFO] [server.transmit] -> request(424): 474554202f696e6465782e68746d6c2048545450485454504854545048545450485454504854545048545450485454504854 ...
[2016-11-20 16:25:55,437] [ERROR] [tcp.pre_test] -> Error: Traceback (most recent call last):
  File "/usr/local/lib/python2.7/dist-packages/katnip/targets/tcp.py", line 57, in pre_test
    sock.connect((self.host, self.port))
  File "/usr/lib/python2.7/socket.py", line 224, in meth
    return getattr(self._sock,name)(*args)
error: [Errno 111] Connection refused

[2016-11-20 16:25:55,440] [ERROR] [tcp.pre_test] -> Failed to connect to target server, retrying...
[2016-11-20 16:25:56,443] [INFO] [base._test_info] -> Current test: 3
[2016-11-20 16:25:56,445] [INFO] [server.transmit] -> request(29): 474554202f696e6465782e68746d6c2048545450fe2f312e310d0a0d0a
[2016-11-20 16:25:56,867] [INFO] [base._test_info] -> Current test: 4
[2016-11-20 16:25:56,868] [INFO] [server.transmit] -> request(29): 474554202f696e6465782e68746d6c2000485454502f312e310d0a0d0a
[2016-11-20 16:25:57,792] [ERROR] [tcp.pre_test] -> Error: Traceback (most recent call last):
  File "/usr/local/lib/python2.7/dist-packages/katnip/targets/tcp.py", line 57, in pre_test
    sock.connect((self.host, self.port))
  File "/usr/lib/python2.7/socket.py", line 224, in meth
    return getattr(self._sock,name)(*args)
error: [Errno 111] Connection refused

[2016-11-20 16:25:57,793] [ERROR] [tcp.pre_test] -> Failed to connect to target server, retrying...
[2016-11-20 16:25:58,796] [INFO] [base._test_info] -> Current test: 5
[2016-11-20 16:25:58,798] [INFO] [server.transmit] -> request(29): 474554202f696e6465782e68746d6c2048540054502f312e310d0a0d0a
[2016-11-20 16:25:59,212] [INFO] [base._test_info] -> Current test: 6
[2016-11-20 16:25:59,214] [INFO] [server.transmit] -> request(29): 474554202f696e6465782e68746d6c2048545450002f312e310d0a0d0a
[2016-11-20 16:26:00,141] [INFO] [base._test_info] -> Current test: 7
[2016-11-20 16:26:00,142] [INFO] [server.transmit] -> request(24): 474554202f696e6465782e68746d6c202f312e310d0a0d0a
[2016-11-20 16:26:01,068] [ERROR] [tcp.pre_test] -> Error: Traceback (most recent call last):
  File "/usr/local/lib/python2.7/dist-packages/katnip/targets/tcp.py", line 57, in pre_test
    sock.connect((self.host, self.port))
  File "/usr/lib/python2.7/socket.py", line 224, in meth
    return getattr(self._sock,name)(*args)
error: [Errno 111] Connection refused

[2016-11-20 16:26:01,070] [ERROR] [tcp.pre_test] -> Failed to connect to target server, retrying...
[2016-11-20 16:26:02,075] [INFO] [base._test_info] -> Current test: 8
[2016-11-20 16:26:02,078] [INFO] [server.transmit] -> request(2072): 474554202f696e6465782e68746d6c2025732573257325732573257325732573257325732573257325732573257325732573 ...
[2016-11-20 16:26:02,495] [INFO] [base._test_info] -> Current test: 9
[2016-11-20 16:26:02,499] [INFO] [server.transmit] -> request(280): 474554202f696e6465782e68746d6c2025732573257325732573257325732573257325732573257325732573257325732573 ...
[2016-11-20 16:26:03,424] [ERROR] [tcp.pre_test] -> Error: Traceback (most recent call last):
  File "/usr/local/lib/python2.7/dist-packages/katnip/targets/tcp.py", line 57, in pre_test
    sock.connect((self.host, self.port))
  File "/usr/lib/python2.7/socket.py", line 224, in meth
    return getattr(self._sock,name)(*args)
error: [Errno 111] Connection refused

[2016-11-20 16:26:03,425] [ERROR] [tcp.pre_test] -> Failed to connect to target server, retrying...
[2016-11-20 16:26:04,430] [INFO] [base._test_info] -> Current test: 10
[2016-11-20 16:26:04,431] [INFO] [server.transmit] -> request(56): 474554202f696e6465782e68746d6c2025732573257325732573257325732573257325732573257325732573257325732f31 ...
[2016-11-20 16:26:04,848] [INFO] [base._test_info] -> Current test: 11
[2016-11-20 16:26:04,850] [INFO] [server.transmit] -> request(28): 474554202f696e6465782e68746d6c20257325732f312e310d0a0d0a
[2016-11-20 16:26:05,772] [ERROR] [tcp.pre_test] -> Error: Traceback (most recent call last):
  File "/usr/local/lib/python2.7/dist-packages/katnip/targets/tcp.py", line 57, in pre_test
    sock.connect((self.host, self.port))
  File "/usr/lib/python2.7/socket.py", line 224, in meth
    return getattr(self._sock,name)(*args)
error: [Errno 111] Connection refused

[2016-11-20 16:26:05,773] [ERROR] [tcp.pre_test] -> Failed to connect to target server, retrying...
[2016-11-20 16:26:06,777] [INFO] [base._test_info] -> Current test: 12
[2016-11-20 16:26:06,779] [INFO] [server.transmit] -> request(3096): 474554202f696e6465782e68746d6c2025257325257325257325257325257325257325257325257325257325257325257325 ...
[2016-11-20 16:26:07,197] [INFO] [base._test_info] -> Current test: 13
[2016-11-20 16:26:07,199] [INFO] [server.transmit] -> request(408): 474554202f696e6465782e68746d6c2025257325257325257325257325257325257325257325257325257325257325257325 ...
[2016-11-20 16:26:08,139] [INFO] [base._test_info] -> Current test: 14
[2016-11-20 16:26:08,142] [INFO] [server.transmit] -> request(72): 474554202f696e6465782e68746d6c2025257325257325257325257325257325257325257325257325257325257325257325 ...
[2016-11-20 16:26:09,083] [ERROR] [tcp.pre_test] -> Error: Traceback (most recent call last):
  File "/usr/local/lib/python2.7/dist-packages/katnip/targets/tcp.py", line 57, in pre_test
    sock.connect((self.host, self.port))
  File "/usr/lib/python2.7/socket.py", line 224, in meth
    return getattr(self._sock,name)(*args)
error: [Errno 111] Connection refused

[2016-11-20 16:26:09,084] [ERROR] [tcp.pre_test] -> Failed to connect to target server, retrying...
[2016-11-20 16:26:10,088] [INFO] [base._test_info] -> Current test: 15
[2016-11-20 16:26:10,090] [INFO] [server.transmit] -> request(30): 474554202f696e6465782e68746d6c202525732525732f312e310d0a0d0a
[2016-11-20 16:26:10,508] [INFO] [base._test_info] -> Current test: 16
[2016-11-20 16:26:10,510] [INFO] [server.transmit] -> request(4120): 474554202f696e6465782e68746d6c2022257322222573222225732222257322222573222225732222257322222573222225 ...
[2016-11-20 16:26:11,435] [ERROR] [tcp.pre_test] -> Error: Traceback (most recent call last):
  File "/usr/local/lib/python2.7/dist-packages/katnip/targets/tcp.py", line 57, in pre_test
    sock.connect((self.host, self.port))
  File "/usr/lib/python2.7/socket.py", line 224, in meth
    return getattr(self._sock,name)(*args)
error: [Errno 111] Connection refused

[2016-11-20 16:26:11,437] [ERROR] [tcp.pre_test] -> Failed to connect to target server, retrying...
[2016-11-20 16:26:12,442] [INFO] [base._test_info] -> Current test: 17
[2016-11-20 16:26:12,443] [INFO] [server.transmit] -> request(536): 474554202f696e6465782e68746d6c2022257322222573222225732222257322222573222225732222257322222573222225 ...
[2016-11-20 16:26:12,860] [INFO] [base._test_info] -> Current test: 18
[2016-11-20 16:26:12,862] [INFO] [server.transmit] -> request(88): 474554202f696e6465782e68746d6c2022257322222573222225732222257322222573222225732222257322222573222225 ...
[2016-11-20 16:26:13,786] [ERROR] [tcp.pre_test] -> Error: Traceback (most recent call last):
  File "/usr/local/lib/python2.7/dist-packages/katnip/targets/tcp.py", line 57, in pre_test
    sock.connect((self.host, self.port))
  File "/usr/lib/python2.7/socket.py", line 224, in meth
    return getattr(self._sock,name)(*args)
error: [Errno 111] Connection refused

[2016-11-20 16:26:13,787] [ERROR] [tcp.pre_test] -> Failed to connect to target server, retrying...
[2016-11-20 16:26:14,791] [INFO] [base._test_info] -> Current test: 19
[2016-11-20 16:26:14,792] [INFO] [server.transmit] -> request(32): 474554202f696e6465782e68746d6c2022257322222573222f312e310d0a0d0a
[2016-11-20 16:26:15,207] [INFO] [base._test_info] -> Current test: 20
[2016-11-20 16:26:15,208] [INFO] [server.transmit] -> request(2072): 474554202f696e6465782e68746d6c20256e256e256e256e256e256e256e256e256e256e256e256e256e256e256e256e256e ...
[2016-11-20 16:26:16,135] [INFO] [base._test_info] -> Current test: 21
[2016-11-20 16:26:16,138] [INFO] [server.transmit] -> request(280): 474554202f696e6465782e68746d6c20256e256e256e256e256e256e256e256e256e256e256e256e256e256e256e256e256e ...
[2016-11-20 16:26:17,069] [ERROR] [tcp.pre_test] -> Error: Traceback (most recent call last):
  File "/usr/local/lib/python2.7/dist-packages/katnip/targets/tcp.py", line 57, in pre_test
    sock.connect((self.host, self.port))
  File "/usr/lib/python2.7/socket.py", line 224, in meth
    return getattr(self._sock,name)(*args)
error: [Errno 111] Connection refused

[2016-11-20 16:26:17,070] [ERROR] [tcp.pre_test] -> Failed to connect to target server, retrying...
[2016-11-20 16:26:18,075] [INFO] [base._test_info] -> Current test: 22
[2016-11-20 16:26:18,076] [INFO] [server.transmit] -> request(56): 474554202f696e6465782e68746d6c20256e256e256e256e256e256e256e256e256e256e256e256e256e256e256e256e2f31 ...
[2016-11-20 16:26:18,493] [INFO] [base._test_info] -> Current test: 23
[2016-11-20 16:26:18,494] [INFO] [server.transmit] -> request(28): 474554202f696e6465782e68746d6c20256e256e2f312e310d0a0d0a
[2016-11-20 16:26:19,425] [ERROR] [tcp.pre_test] -> Error: Traceback (most recent call last):
  File "/usr/local/lib/python2.7/dist-packages/katnip/targets/tcp.py", line 57, in pre_test
    sock.connect((self.host, self.port))
  File "/usr/lib/python2.7/socket.py", line 224, in meth
    return getattr(self._sock,name)(*args)
error: [Errno 111] Connection refused

[2016-11-20 16:26:19,426] [ERROR] [tcp.pre_test] -> Failed to connect to target server, retrying...
[2016-11-20 16:26:20,431] [INFO] [base._test_info] -> Current test: 24
[2016-11-20 16:26:20,434] [INFO] [server.transmit] -> request(3096): 474554202f696e6465782e68746d6c2025256e25256e25256e25256e25256e25256e25256e25256e25256e25256e25256e25 ...
[2016-11-20 16:26:20,856] [INFO] [base._test_info] -> Current test: 25
[2016-11-20 16:26:20,859] [INFO] [server.transmit] -> request(408): 474554202f696e6465782e68746d6c2025256e25256e25256e25256e25256e25256e25256e25256e25256e25256e25256e25 ...
[2016-11-20 16:26:21,793] [ERROR] [tcp.pre_test] -> Error: Traceback (most recent call last):
  File "/usr/local/lib/python2.7/dist-packages/katnip/targets/tcp.py", line 57, in pre_test
    sock.connect((self.host, self.port))
  File "/usr/lib/python2.7/socket.py", line 224, in meth
    return getattr(self._sock,name)(*args)
error: [Errno 111] Connection refused

[2016-11-20 16:26:21,794] [ERROR] [tcp.pre_test] -> Failed to connect to target server, retrying...
[2016-11-20 16:26:22,798] [INFO] [base._test_info] -> Current test: 26
[2016-11-20 16:26:22,799] [INFO] [server.transmit] -> request(72): 474554202f696e6465782e68746d6c2025256e25256e25256e25256e25256e25256e25256e25256e25256e25256e25256e25 ...
[2016-11-20 16:26:23,217] [INFO] [base._test_info] -> Current test: 27
[2016-11-20 16:26:23,219] [INFO] [server.transmit] -> request(30): 474554202f696e6465782e68746d6c2025256e25256e2f312e310d0a0d0a
[2016-11-20 16:26:24,160] [ERROR] [tcp.pre_test] -> Error: Traceback (most recent call last):
  File "/usr/local/lib/python2.7/dist-packages/katnip/targets/tcp.py", line 57, in pre_test
    sock.connect((self.host, self.port))
  File "/usr/lib/python2.7/socket.py", line 224, in meth
    return getattr(self._sock,name)(*args)
error: [Errno 111] Connection refused

[2016-11-20 16:26:24,161] [ERROR] [tcp.pre_test] -> Failed to connect to target server, retrying...
[2016-11-20 16:26:25,169] [INFO] [base._test_info] -> Current test: 28
[2016-11-20 16:26:25,170] [INFO] [server.transmit] -> request(4120): 474554202f696e6465782e68746d6c2022256e2222256e2222256e2222256e2222256e2222256e2222256e2222256e222225 ...
[2016-11-20 16:26:25,588] [INFO] [base._test_info] -> Current test: 29
[2016-11-20 16:26:25,590] [INFO] [server.transmit] -> request(536): 474554202f696e6465782e68746d6c2022256e2222256e2222256e2222256e2222256e2222256e2222256e2222256e222225 ...
[2016-11-20 16:26:26,518] [ERROR] [tcp.pre_test] -> Error: Traceback (most recent call last):
  File "/usr/local/lib/python2.7/dist-packages/katnip/targets/tcp.py", line 57, in pre_test
    sock.connect((self.host, self.port))
  File "/usr/lib/python2.7/socket.py", line 224, in meth
    return getattr(self._sock,name)(*args)
error: [Errno 111] Connection refused

[2016-11-20 16:26:26,520] [ERROR] [tcp.pre_test] -> Failed to connect to target server, retrying...
[2016-11-20 16:26:27,525] [INFO] [base._test_info] -> Current test: 30
[2016-11-20 16:26:27,526] [INFO] [server.transmit] -> request(88): 474554202f696e6465782e68746d6c2022256e2222256e2222256e2222256e2222256e2222256e2222256e2222256e222225 ...
[2016-11-20 16:26:27,943] [INFO] [base._test_info] -> Current test: 31
[2016-11-20 16:26:27,946] [INFO] [server.transmit] -> request(32): 474554202f696e6465782e68746d6c2022256e2222256e222f312e310d0a0d0a
[2016-11-20 16:26:28,870] [ERROR] [tcp.pre_test] -> Error: Traceback (most recent call last):
  File "/usr/local/lib/python2.7/dist-packages/katnip/targets/tcp.py", line 57, in pre_test
    sock.connect((self.host, self.port))
  File "/usr/lib/python2.7/socket.py", line 224, in meth
    return getattr(self._sock,name)(*args)
error: [Errno 111] Connection refused

[2016-11-20 16:26:28,871] [ERROR] [tcp.pre_test] -> Failed to connect to target server, retrying...
[2016-11-20 16:26:29,877] [INFO] [base._test_info] -> Current test: 32
[2016-11-20 16:26:29,878] [INFO] [server.transmit] -> request(38): 474554202f696e6465782e68746d6c20252e31363730357525325c24686e2f312e310d0a0d0a
[2016-11-20 16:26:30,314] [INFO] [base._test_info] -> Current test: 33
[2016-11-20 16:26:30,316] [INFO] [server.transmit] -> request(2072): 474554202f696e6465782e68746d6c200d0a0d0a0d0a0d0a0d0a0d0a0d0a0d0a0d0a0d0a0d0a0d0a0d0a0d0a0d0a0d0a0d0a ...
[2016-11-20 16:26:31,244] [INFO] [base._test_info] -> Current test: 34
[2016-11-20 16:26:31,247] [INFO] [server.transmit] -> request(280): 474554202f696e6465782e68746d6c200d0a0d0a0d0a0d0a0d0a0d0a0d0a0d0a0d0a0d0a0d0a0d0a0d0a0d0a0d0a0d0a0d0a ...
[2016-11-20 16:26:32,182] [ERROR] [tcp.pre_test] -> Error: Traceback (most recent call last):
  File "/usr/local/lib/python2.7/dist-packages/katnip/targets/tcp.py", line 57, in pre_test
    sock.connect((self.host, self.port))
  File "/usr/lib/python2.7/socket.py", line 224, in meth
    return getattr(self._sock,name)(*args)
error: [Errno 111] Connection refused

[2016-11-20 16:26:32,184] [ERROR] [tcp.pre_test] -> Failed to connect to target server, retrying...
[2016-11-20 16:26:33,187] [INFO] [base._test_info] -> Current test: 35
[2016-11-20 16:26:33,190] [INFO] [server.transmit] -> request(56): 474554202f696e6465782e68746d6c200d0a0d0a0d0a0d0a0d0a0d0a0d0a0d0a0d0a0d0a0d0a0d0a0d0a0d0a0d0a0d0a2f31 ...
[2016-11-20 16:26:33,609] [INFO] [base._test_info] -> Current test: 36
[2016-11-20 16:26:33,615] [INFO] [server.transmit] -> request(28): 474554202f696e6465782e68746d6c200d0a0d0a2f312e310d0a0d0a
[2016-11-20 16:26:34,546] [INFO] [base._test_info] -> Current test: 37
[2016-11-20 16:26:34,548] [INFO] [server.transmit] -> request(1048): 474554202f696e6465782e68746d6c200a0a0a0a0a0a0a0a0a0a0a0a0a0a0a0a0a0a0a0a0a0a0a0a0a0a0a0a0a0a0a0a0a0a ...
[2016-11-20 16:26:35,477] [ERROR] [tcp.pre_test] -> Error: Traceback (most recent call last):
  File "/usr/local/lib/python2.7/dist-packages/katnip/targets/tcp.py", line 57, in pre_test
    sock.connect((self.host, self.port))
  File "/usr/lib/python2.7/socket.py", line 224, in meth
    return getattr(self._sock,name)(*args)
error: [Errno 111] Connection refused

[2016-11-20 16:26:35,479] [ERROR] [tcp.pre_test] -> Failed to connect to target server, retrying...
[2016-11-20 16:26:36,485] [INFO] [base._test_info] -> Current test: 38
[2016-11-20 16:26:36,486] [INFO] [server.transmit] -> request(152): 474554202f696e6465782e68746d6c200a0a0a0a0a0a0a0a0a0a0a0a0a0a0a0a0a0a0a0a0a0a0a0a0a0a0a0a0a0a0a0a0a0a ...
[2016-11-20 16:26:36,901] [INFO] [base._test_info] -> Current test: 39
[2016-11-20 16:26:36,904] [INFO] [server.transmit] -> request(40): 474554202f696e6465782e68746d6c200a0a0a0a0a0a0a0a0a0a0a0a0a0a0a0a2f312e310d0a0d0a
[2016-11-20 16:26:37,835] [ERROR] [tcp.pre_test] -> Error: Traceback (most recent call last):
  File "/usr/local/lib/python2.7/dist-packages/katnip/targets/tcp.py", line 57, in pre_test
    sock.connect((self.host, self.port))
  File "/usr/lib/python2.7/socket.py", line 224, in meth
    return getattr(self._sock,name)(*args)
error: [Errno 111] Connection refused

[2016-11-20 16:26:37,838] [ERROR] [tcp.pre_test] -> Failed to connect to target server, retrying...
[2016-11-20 16:26:38,840] [INFO] [base._test_info] -> Current test: 40
[2016-11-20 16:26:38,843] [INFO] [server.transmit] -> request(26): 474554202f696e6465782e68746d6c200a0a2f312e310d0a0d0a
[2016-11-20 16:26:39,265] [INFO] [base._test_info] -> Current test: 41
[2016-11-20 16:26:39,268] [INFO] [server.transmit] -> request(4120): 474554202f696e6465782e68746d6c20deadbeefdeadbeefdeadbeefdeadbeefdeadbeefdeadbeefdeadbeefdeadbeefdead ...
[2016-11-20 16:26:40,193] [ERROR] [tcp.pre_test] -> Error: Traceback (most recent call last):
  File "/usr/local/lib/python2.7/dist-packages/katnip/targets/tcp.py", line 57, in pre_test
    sock.connect((self.host, self.port))
  File "/usr/lib/python2.7/socket.py", line 224, in meth
    return getattr(self._sock,name)(*args)
error: [Errno 111] Connection refused

[2016-11-20 16:26:40,195] [ERROR] [tcp.pre_test] -> Failed to connect to target server, retrying...
[2016-11-20 16:26:41,200] [INFO] [base._test_info] -> Current test: 42
[2016-11-20 16:26:41,202] [INFO] [server.transmit] -> request(536): 474554202f696e6465782e68746d6c20deadbeefdeadbeefdeadbeefdeadbeefdeadbeefdeadbeefdeadbeefdeadbeefdead ...
[2016-11-20 16:26:41,620] [INFO] [base._test_info] -> Current test: 43
[2016-11-20 16:26:41,623] [INFO] [server.transmit] -> request(88): 474554202f696e6465782e68746d6c20deadbeefdeadbeefdeadbeefdeadbeefdeadbeefdeadbeefdeadbeefdeadbeefdead ...
[2016-11-20 16:26:42,551] [ERROR] [tcp.pre_test] -> Error: Traceback (most recent call last):
  File "/usr/local/lib/python2.7/dist-packages/katnip/targets/tcp.py", line 57, in pre_test
    sock.connect((self.host, self.port))
  File "/usr/lib/python2.7/socket.py", line 224, in meth
    return getattr(self._sock,name)(*args)
error: [Errno 111] Connection refused

[2016-11-20 16:26:42,554] [ERROR] [tcp.pre_test] -> Failed to connect to target server, retrying...
[2016-11-20 16:26:43,558] [INFO] [base._test_info] -> Current test: 44
[2016-11-20 16:26:43,559] [INFO] [server.transmit] -> request(32): 474554202f696e6465782e68746d6c20deadbeefdeadbeef2f312e310d0a0d0a
[2016-11-20 16:26:43,975] [INFO] [base._test_info] -> Current test: 45
[2016-11-20 16:26:43,978] [INFO] [server.transmit] -> request(41): 474554202f696e6465782e68746d6c207c746f756368202f746d702f4b495454592f312e310d0a0d0a
[2016-11-20 16:26:44,911] [ERROR] [tcp.pre_test] -> Error: Traceback (most recent call last):
  File "/usr/local/lib/python2.7/dist-packages/katnip/targets/tcp.py", line 57, in pre_test
    sock.connect((self.host, self.port))
  File "/usr/lib/python2.7/socket.py", line 224, in meth
    return getattr(self._sock,name)(*args)
error: [Errno 111] Connection refused

[2016-11-20 16:26:44,913] [ERROR] [tcp.pre_test] -> Failed to connect to target server, retrying...
[2016-11-20 16:26:45,919] [INFO] [base._test_info] -> Current test: 46
[2016-11-20 16:26:45,920] [INFO] [server.transmit] -> request(42): 474554202f696e6465782e68746d6c203b746f756368202f746d702f4b495454593b2f312e310d0a0d0a
[2016-11-20 16:26:46,334] [INFO] [base._test_info] -> Current test: 47
[2016-11-20 16:26:46,343] [INFO] [server.transmit] -> request(38): 474554202f696e6465782e68746d6c203b6c733e2f746d702f4b495454592f312e310d0a0d0a
[2016-11-20 16:26:47,273] [ERROR] [tcp.pre_test] -> Error: Traceback (most recent call last):
  File "/usr/local/lib/python2.7/dist-packages/katnip/targets/tcp.py", line 57, in pre_test
    sock.connect((self.host, self.port))
  File "/usr/lib/python2.7/socket.py", line 224, in meth
    return getattr(self._sock,name)(*args)
error: [Errno 111] Connection refused

[2016-11-20 16:26:47,276] [ERROR] [tcp.pre_test] -> Failed to connect to target server, retrying...
[2016-11-20 16:26:48,281] [INFO] [base._test_info] -> Current test: 48
[2016-11-20 16:26:48,282] [INFO] [server.transmit] -> request(53): 474554202f696e6465782e68746d6c20223b6c733e2f746d702f4b495454593b6c733e2f6465762f6e756c6c222f312e310d ...
[2016-11-20 16:26:48,698] [INFO] [base._test_info] -> Current test: 49
[2016-11-20 16:26:48,700] [INFO] [server.transmit] -> request(54): 474554202f696e6465782e68746d6c20273b6c733e2f746d702f4b495454593b6c733e272f6465762f6e756c6c272f312e31 ...
[2016-11-20 16:26:49,634] [ERROR] [tcp.pre_test] -> Error: Traceback (most recent call last):
  File "/usr/local/lib/python2.7/dist-packages/katnip/targets/tcp.py", line 57, in pre_test
    sock.connect((self.host, self.port))
  File "/usr/lib/python2.7/socket.py", line 224, in meth
    return getattr(self._sock,name)(*args)
error: [Errno 111] Connection refused

[2016-11-20 16:26:49,637] [ERROR] [tcp.pre_test] -> Failed to connect to target server, retrying...
[2016-11-20 16:26:50,641] [INFO] [base._test_info] -> Current test: 50
[2016-11-20 16:26:50,642] [INFO] [server.transmit] -> request(39): 474554202f696e6465782e68746d6c20606c733e2f746d702f4b49545459602f312e310d0a0d0a
[2016-11-20 16:26:51,058] [INFO] [base._test_info] -> Current test: 51
[2016-11-20 16:26:51,061] [INFO] [server.transmit] -> request(40): 474554202f696e6465782e68746d6c2020606c733e2f746d702f4b49545459602f312e310d0a0d0a
[2016-11-20 16:26:51,989] [ERROR] [tcp.pre_test] -> Error: Traceback (most recent call last):
  File "/usr/local/lib/python2.7/dist-packages/katnip/targets/tcp.py", line 57, in pre_test
    sock.connect((self.host, self.port))
  File "/usr/lib/python2.7/socket.py", line 224, in meth
    return getattr(self._sock,name)(*args)
error: [Errno 111] Connection refused

[2016-11-20 16:26:51,991] [ERROR] [tcp.pre_test] -> Failed to connect to target server, retrying...
[2016-11-20 16:26:53,001] [INFO] [base._test_info] -> Current test: 52
[2016-11-20 16:26:53,003] [INFO] [server.transmit] -> request(32): 474554202f696e6465782e68746d6c207c6e6f74657061642f312e310d0a0d0a
[2016-11-20 16:26:53,422] [INFO] [base._test_info] -> Current test: 53
[2016-11-20 16:26:53,424] [INFO] [server.transmit] -> request(33): 474554202f696e6465782e68746d6c203b6e6f74657061643b2f312e310d0a0d0a
[2016-11-20 16:26:54,356] [INFO] [base._test_info] -> Current test: 54
[2016-11-20 16:26:54,358] [INFO] [server.transmit] -> request(33): 474554202f696e6465782e68746d6c200a6e6f74657061640a2f312e310d0a0d0a
[2016-11-20 16:26:55,285] [ERROR] [tcp.pre_test] -> Error: Traceback (most recent call last):
  File "/usr/local/lib/python2.7/dist-packages/katnip/targets/tcp.py", line 57, in pre_test
    sock.connect((self.host, self.port))
  File "/usr/lib/python2.7/socket.py", line 224, in meth
    return getattr(self._sock,name)(*args)
error: [Errno 111] Connection refused

[2016-11-20 16:26:55,286] [ERROR] [tcp.pre_test] -> Failed to connect to target server, retrying...
[2016-11-20 16:26:56,292] [INFO] [base._test_info] -> Current test: 55
[2016-11-20 16:26:56,293] [INFO] [server.transmit] -> request(35): 474554202f696e6465782e68746d6c2027206f7220313d31202d2d2f312e310d0a0d0a
[2016-11-20 16:26:56,708] [INFO] [base._test_info] -> Current test: 56
[2016-11-20 16:26:56,710] [INFO] [server.transmit] -> request(41): 474554202f696e6465782e68746d6c20273b20646573632075736572733b202d2d2f312e310d0a0d0a
[2016-11-20 16:26:57,636] [ERROR] [tcp.pre_test] -> Error: Traceback (most recent call last):
  File "/usr/local/lib/python2.7/dist-packages/katnip/targets/tcp.py", line 57, in pre_test
    sock.connect((self.host, self.port))
  File "/usr/lib/python2.7/socket.py", line 224, in meth
    return getattr(self._sock,name)(*args)
error: [Errno 111] Connection refused

[2016-11-20 16:26:57,638] [ERROR] [tcp.pre_test] -> Failed to connect to target server, retrying...
[2016-11-20 16:26:58,642] [INFO] [base._test_info] -> Current test: 57
[2016-11-20 16:26:58,643] [INFO] [server.transmit] -> request(65): 474554202f696e6465782e68746d6c2027206f7220757365726e616d65206973206e6f74204e554c4c206f7220757365726e ...
[2016-11-20 16:26:59,066] [INFO] [base._test_info] -> Current test: 58
[2016-11-20 16:26:59,071] [INFO] [server.transmit] -> request(96): 474554202f696e6465782e68746d6c203120756e696f6e20616c6c2073656c65637420312c322c332c342c352c362c6e616d ...
[2016-11-20 16:27:00,005] [ERROR] [tcp.pre_test] -> Error: Traceback (most recent call last):
  File "/usr/local/lib/python2.7/dist-packages/katnip/targets/tcp.py", line 57, in pre_test
    sock.connect((self.host, self.port))
  File "/usr/lib/python2.7/socket.py", line 224, in meth
    return getattr(self._sock,name)(*args)
error: [Errno 111] Connection refused

[2016-11-20 16:27:00,013] [ERROR] [tcp.pre_test] -> Failed to connect to target server, retrying...
[2016-11-20 16:27:01,020] [INFO] [base._test_info] -> Current test: 59
[2016-11-20 16:27:01,022] [INFO] [server.transmit] -> request(35): 474554202f696e6465782e68746d6c2060206f72206031603d60312f312e310d0a0d0a
[2016-11-20 16:27:01,438] [INFO] [base._test_info] -> Current test: 60
[2016-11-20 16:27:01,442] [INFO] [server.transmit] -> request(35): 474554202f696e6465782e68746d6c2027206f72202731273d27312f312e310d0a0d0a
[2016-11-20 16:27:02,378] [ERROR] [tcp.pre_test] -> Error: Traceback (most recent call last):
  File "/usr/local/lib/python2.7/dist-packages/katnip/targets/tcp.py", line 57, in pre_test
    sock.connect((self.host, self.port))
  File "/usr/lib/python2.7/socket.py", line 224, in meth
    return getattr(self._sock,name)(*args)
error: [Errno 111] Connection refused

[2016-11-20 16:27:02,379] [ERROR] [tcp.pre_test] -> Failed to connect to target server, retrying...
[2016-11-20 16:27:03,384] [INFO] [base._test_info] -> Current test: 61
[2016-11-20 16:27:03,386] [INFO] [server.transmit] -> request(26): 474554202f696e6465782e68746d6c2041412f312e310d0a0d0a
[2016-11-20 16:27:03,802] [INFO] [base._test_info] -> Current test: 62
[2016-11-20 16:27:03,805] [INFO] [server.transmit] -> request(34): 474554202f696e6465782e68746d6c20414141414141414141412f312e310d0a0d0a
[2016-11-20 16:27:04,733] [INFO] [base._test_info] -> Current test: 63
[2016-11-20 16:27:04,735] [INFO] [server.transmit] -> request(124): 474554202f696e6465782e68746d6c2041414141414141414141414141414141414141414141414141414141414141414141 ...
[2016-11-20 16:27:05,657] [INFO] [base._test_info] -> Current test: 64
[2016-11-20 16:27:05,659] [INFO] [server.transmit] -> request(1024): 474554202f696e6465782e68746d6c2041414141414141414141414141414141414141414141414141414141414141414141 ...
[2016-11-20 16:27:06,586] [INFO] [base._test_info] -> Current test: 65
[2016-11-20 16:27:06,590] [INFO] [server.transmit] -> request(5024): 474554202f696e6465782e68746d6c2041414141414141414141414141414141414141414141414141414141414141414141 ...
[2016-11-20 16:27:07,518] [ERROR] [tcp.pre_test] -> Error: Traceback (most recent call last):
  File "/usr/local/lib/python2.7/dist-packages/katnip/targets/tcp.py", line 57, in pre_test
    sock.connect((self.host, self.port))
  File "/usr/lib/python2.7/socket.py", line 224, in meth
    return getattr(self._sock,name)(*args)
error: [Errno 111] Connection refused

[2016-11-20 16:27:07,519] [ERROR] [tcp.pre_test] -> Failed to connect to target server, retrying...
[2016-11-20 16:27:08,524] [INFO] [base._test_info] -> Current test: 66
[2016-11-20 16:27:08,525] [INFO] [server.transmit] -> request(10024): 474554202f696e6465782e68746d6c2041414141414141414141414141414141414141414141414141414141414141414141 ...
[2016-11-20 16:27:08,940] [INFO] [base._test_info] -> Current test: 67
[2016-11-20 16:27:08,942] [INFO] [server.transmit] -> request(35): 474554202f696e6465782e68746d6c202f6574632f7061737377642f312e310d0a0d0a
[2016-11-20 16:27:09,867] [ERROR] [tcp.pre_test] -> Error: Traceback (most recent call last):
  File "/usr/local/lib/python2.7/dist-packages/katnip/targets/tcp.py", line 57, in pre_test
    sock.connect((self.host, self.port))
  File "/usr/lib/python2.7/socket.py", line 224, in meth
    return getattr(self._sock,name)(*args)
error: [Errno 111] Connection refused

[2016-11-20 16:27:09,869] [ERROR] [tcp.pre_test] -> Failed to connect to target server, retrying...
[2016-11-20 16:27:10,874] [INFO] [base._test_info] -> Current test: 68
[2016-11-20 16:27:10,875] [INFO] [server.transmit] -> request(78): 474554202f696e6465782e68746d6c202e2f2e2e2f2e2e2f2e2e2f2e2e2f2e2e2f2e2e2f2e2e2f2e2e2f2e2e2f2e2e2f2e2e ...
[2016-11-20 16:27:11,291] [INFO] [base._test_info] -> Current test: 69
[2016-11-20 16:27:11,293] [INFO] [server.transmit] -> request(76): 474554202f696e6465782e68746d6c202e2e2f2e2e2f2e2e2f2e2e2f2e2e2f2e2e2f2e2e2f2e2e2f2e2e2f2e2e2f2e2e2f2e ...
[2016-11-20 16:27:12,216] [ERROR] [tcp.pre_test] -> Error: Traceback (most recent call last):
  File "/usr/local/lib/python2.7/dist-packages/katnip/targets/tcp.py", line 57, in pre_test
    sock.connect((self.host, self.port))
  File "/usr/lib/python2.7/socket.py", line 224, in meth
    return getattr(self._sock,name)(*args)
error: [Errno 111] Connection refused

[2016-11-20 16:27:12,217] [ERROR] [tcp.pre_test] -> Failed to connect to target server, retrying...
[2016-11-20 16:27:13,224] [INFO] [base._test_info] -> Current test: 70
[2016-11-20 16:27:13,225] [INFO] [server.transmit] -> request(37): 474554202f696e6465782e68746d6c202f70726f632f637075696e666f2f312e310d0a0d0a
[2016-11-20 16:27:13,643] [INFO] [base._test_info] -> Current test: 71
[2016-11-20 16:27:13,646] [INFO] [server.transmit] -> request(80): 474554202f696e6465782e68746d6c202e2f2e2e2f2e2e2f2e2e2f2e2e2f2e2e2f2e2e2f2e2e2f2e2e2f2e2e2f2e2e2f2e2e ...
[2016-11-20 16:27:14,573] [ERROR] [tcp.pre_test] -> Error: Traceback (most recent call last):
  File "/usr/local/lib/python2.7/dist-packages/katnip/targets/tcp.py", line 57, in pre_test
    sock.connect((self.host, self.port))
  File "/usr/lib/python2.7/socket.py", line 224, in meth
    return getattr(self._sock,name)(*args)
error: [Errno 111] Connection refused

[2016-11-20 16:27:14,576] [ERROR] [tcp.pre_test] -> Failed to connect to target server, retrying...
[2016-11-20 16:27:15,581] [INFO] [base._test_info] -> Current test: 72
[2016-11-20 16:27:15,583] [INFO] [server.transmit] -> request(78): 474554202f696e6465782e68746d6c202e2e2f2e2e2f2e2e2f2e2e2f2e2e2f2e2e2f2e2e2f2e2e2f2e2e2f2e2e2f2e2e2f2e ...
[2016-11-20 16:27:16,000] [INFO] [base._test_info] -> Current test: 73
[2016-11-20 16:27:16,002] [INFO] [server.transmit] -> request(34): 474554202f696e6465782e68746d6c207e2f2e70726f66696c652f312e310d0a0d0a
[2016-11-20 16:27:16,935] [ERROR] [tcp.pre_test] -> Error: Traceback (most recent call last):
  File "/usr/local/lib/python2.7/dist-packages/katnip/targets/tcp.py", line 57, in pre_test
    sock.connect((self.host, self.port))
  File "/usr/lib/python2.7/socket.py", line 224, in meth
    return getattr(self._sock,name)(*args)
error: [Errno 111] Connection refused

[2016-11-20 16:27:16,936] [ERROR] [tcp.pre_test] -> Failed to connect to target server, retrying...
[2016-11-20 16:27:17,941] [INFO] [base._test_info] -> Current test: 74
[2016-11-20 16:27:17,942] [INFO] [server.transmit] -> request(38): 474554202f696e6465782e68746d6c2024484f4d452f2e70726f66696c652f312e310d0a0d0a
[2016-11-20 16:27:18,363] [INFO] [base._test_info] -> Current test: 75
[2016-11-20 16:27:18,365] [INFO] [server.transmit] -> request(69): 474554202f696e6465782e68746d6c202f2e2e2f2e2e2f2e2e2f2e2e2f2e2e2f2e2e2f2e2e2f2e2e2f2e2e2f2e2e2f2e2e2f ...
[2016-11-20 16:27:19,289] [ERROR] [tcp.pre_test] -> Error: Traceback (most recent call last):
  File "/usr/local/lib/python2.7/dist-packages/katnip/targets/tcp.py", line 57, in pre_test
    sock.connect((self.host, self.port))
  File "/usr/lib/python2.7/socket.py", line 224, in meth
    return getattr(self._sock,name)(*args)
error: [Errno 111] Connection refused

[2016-11-20 16:27:19,291] [ERROR] [tcp.pre_test] -> Failed to connect to target server, retrying...
[2016-11-20 16:27:20,296] [INFO] [base._test_info] -> Current test: 76
[2016-11-20 16:27:20,298] [INFO] [server.transmit] -> request(1048): 474554202f696e6465782e68746d6c202f5c2f5c2f5c2f5c2f5c2f5c2f5c2f5c2f5c2f5c2f5c2f5c2f5c2f5c2f5c2f5c2f5c ...
[2016-11-20 16:27:20,714] [INFO] [base._test_info] -> Current test: 77
[2016-11-20 16:27:20,716] [INFO] [server.transmit] -> request(152): 474554202f696e6465782e68746d6c202f5c2f5c2f5c2f5c2f5c2f5c2f5c2f5c2f5c2f5c2f5c2f5c2f5c2f5c2f5c2f5c2f5c ...
[2016-11-20 16:27:21,642] [ERROR] [tcp.pre_test] -> Error: Traceback (most recent call last):
  File "/usr/local/lib/python2.7/dist-packages/katnip/targets/tcp.py", line 57, in pre_test
    sock.connect((self.host, self.port))
  File "/usr/lib/python2.7/socket.py", line 224, in meth
    return getattr(self._sock,name)(*args)
error: [Errno 111] Connection refused

[2016-11-20 16:27:21,645] [ERROR] [tcp.pre_test] -> Failed to connect to target server, retrying...
[2016-11-20 16:27:22,650] [INFO] [base._test_info] -> Current test: 78
[2016-11-20 16:27:22,652] [INFO] [server.transmit] -> request(40): 474554202f696e6465782e68746d6c202f5c2f5c2f5c2f5c2f5c2f5c2f5c2f5c2f312e310d0a0d0a
[2016-11-20 16:27:23,083] [INFO] [base._test_info] -> Current test: 79
[2016-11-20 16:27:23,086] [INFO] [server.transmit] -> request(1048): 474554202f696e6465782e68746d6c202f2e2f2e2f2e2f2e2f2e2f2e2f2e2f2e2f2e2f2e2f2e2f2e2f2e2f2e2f2e2f2e2f2e ...
[2016-11-20 16:27:23,506] [INFO] [base._test_info] -> Current test: 80
[2016-11-20 16:27:23,508] [INFO] [server.transmit] -> request(152): 474554202f696e6465782e68746d6c202f2e2f2e2f2e2f2e2f2e2f2e2f2e2f2e2f2e2f2e2f2e2f2e2f2e2f2e2f2e2f2e2f2e ...
[2016-11-20 16:27:24,435] [INFO] [base._test_info] -> Current test: 81
[2016-11-20 16:27:24,438] [INFO] [server.transmit] -> request(40): 474554202f696e6465782e68746d6c202f2e2f2e2f2e2f2e2f2e2f2e2f2e2f2e2f312e310d0a0d0a
[2016-11-20 16:27:25,363] [ERROR] [tcp.pre_test] -> Error: Traceback (most recent call last):
  File "/usr/local/lib/python2.7/dist-packages/katnip/targets/tcp.py", line 57, in pre_test
    sock.connect((self.host, self.port))
  File "/usr/lib/python2.7/socket.py", line 224, in meth
    return getattr(self._sock,name)(*args)
error: [Errno 111] Connection refused

[2016-11-20 16:27:25,364] [ERROR] [tcp.pre_test] -> Failed to connect to target server, retrying...
[2016-11-20 16:27:26,367] [INFO] [base._test_info] -> Current test: 82
[2016-11-20 16:27:26,368] [INFO] [server.transmit] -> request(53): 474554202f696e6465782e68746d6c202140232425255e2324252324402324252424402324255e5e2a2a2828292f312e310d ...
[2016-11-20 16:27:26,783] [INFO] [base._test_info] -> Current test: 83
[2016-11-20 16:27:26,786] [INFO] [server.transmit] -> request(49): 474554202f696e6465782e68746d6c20253031253032253033253034253061253064253061414453462f312e310d0a0d0a
[2016-11-20 16:27:27,710] [ERROR] [tcp.pre_test] -> Error: Traceback (most recent call last):
  File "/usr/local/lib/python2.7/dist-packages/katnip/targets/tcp.py", line 57, in pre_test
    sock.connect((self.host, self.port))
  File "/usr/lib/python2.7/socket.py", line 224, in meth
    return getattr(self._sock,name)(*args)
error: [Errno 111] Connection refused

[2016-11-20 16:27:27,711] [ERROR] [tcp.pre_test] -> Failed to connect to target server, retrying...
[2016-11-20 16:27:28,719] [INFO] [base._test_info] -> Current test: 84
[2016-11-20 16:27:28,722] [INFO] [server.transmit] -> request(50): 474554202f696e6465782e68746d6c2025303125303225303340253034253061253064253061414453462f312e310d0a0d0a ...
[2016-11-20 16:27:29,138] [INFO] [base._test_info] -> Current test: 85
[2016-11-20 16:27:29,142] [INFO] [server.transmit] -> request(29): 474554202f696e6465782e68746d6c202f2530302f2f312e310d0a0d0a
[2016-11-20 16:27:30,078] [ERROR] [tcp.pre_test] -> Error: Traceback (most recent call last):
  File "/usr/local/lib/python2.7/dist-packages/katnip/targets/tcp.py", line 57, in pre_test
    sock.connect((self.host, self.port))
  File "/usr/lib/python2.7/socket.py", line 224, in meth
    return getattr(self._sock,name)(*args)
error: [Errno 111] Connection refused

[2016-11-20 16:27:30,078] [ERROR] [tcp.pre_test] -> Failed to connect to target server, retrying...
[2016-11-20 16:27:31,083] [INFO] [base._test_info] -> Current test: 86
[2016-11-20 16:27:31,084] [INFO] [server.transmit] -> request(28): 474554202f696e6465782e68746d6c202530302f2f312e310d0a0d0a
[2016-11-20 16:27:31,500] [INFO] [base._test_info] -> Current test: 87
[2016-11-20 16:27:31,502] [INFO] [server.transmit] -> request(27): 474554202f696e6465782e68746d6c202530302f312e310d0a0d0a
[2016-11-20 16:27:32,427] [ERROR] [tcp.pre_test] -> Error: Traceback (most recent call last):
  File "/usr/local/lib/python2.7/dist-packages/katnip/targets/tcp.py", line 57, in pre_test
    sock.connect((self.host, self.port))
  File "/usr/lib/python2.7/socket.py", line 224, in meth
    return getattr(self._sock,name)(*args)
error: [Errno 111] Connection refused

[2016-11-20 16:27:32,428] [ERROR] [tcp.pre_test] -> Failed to connect to target server, retrying...
[2016-11-20 16:27:33,433] [INFO] [base._test_info] -> Current test: 88
[2016-11-20 16:27:33,434] [INFO] [server.transmit] -> request(30): 474554202f696e6465782e68746d6c202575303030302f312e310d0a0d0a
[2016-11-20 16:27:33,849] [INFO] [base._test_info] -> Current test: 89
[2016-11-20 16:27:33,851] [INFO] [server.transmit] -> request(216): 474554202f696e6465782e68746d6c2025fef02501ff25fef02501ff25fef02501ff25fef02501ff25fef02501ff25fef025 ...
[2016-11-20 16:27:34,787] [ERROR] [tcp.pre_test] -> Error: Traceback (most recent call last):
  File "/usr/local/lib/python2.7/dist-packages/katnip/targets/tcp.py", line 57, in pre_test
    sock.connect((self.host, self.port))
  File "/usr/lib/python2.7/socket.py", line 224, in meth
    return getattr(self._sock,name)(*args)
error: [Errno 111] Connection refused

[2016-11-20 16:27:34,789] [ERROR] [tcp.pre_test] -> Failed to connect to target server, retrying...
[2016-11-20 16:27:35,794] [INFO] [base._test_info] -> Current test: 90
[2016-11-20 16:27:35,795] [INFO] [server.transmit] -> request(48): 474554202f696e6465782e68746d6c2025fef02501ff25fef02501ff25fef02501ff25fef02501ff2f312e310d0a0d0a
[2016-11-20 16:27:36,210] [INFO] [base._test_info] -> Current test: 91
[2016-11-20 16:27:36,212] [INFO] [server.transmit] -> request(32): 474554202f696e6465782e68746d6c20485454502f312e310d0a0d0a0d0a0d0a
[2016-11-20 16:27:37,138] [ERROR] [tcp.pre_test] -> Error: Traceback (most recent call last):
  File "/usr/local/lib/python2.7/dist-packages/katnip/targets/tcp.py", line 57, in pre_test
    sock.connect((self.host, self.port))
  File "/usr/lib/python2.7/socket.py", line 224, in meth
    return getattr(self._sock,name)(*args)
error: [Errno 111] Connection refused

[2016-11-20 16:27:37,139] [ERROR] [tcp.pre_test] -> Failed to connect to target server, retrying...
[2016-11-20 16:27:38,143] [INFO] [base._test_info] -> Current test: 92
[2016-11-20 16:27:38,144] [INFO] [server.transmit] -> request(64): 474554202f696e6465782e68746d6c20485454502f312e310d0a0d0a0d0a0d0a0d0a0d0a0d0a0d0a0d0a0d0a0d0a0d0a0d0a ...
[2016-11-20 16:27:38,561] [INFO] [base._test_info] -> Current test: 93
[2016-11-20 16:27:38,563] [INFO] [server.transmit] -> request(424): 474554202f696e6465782e68746d6c20485454502f312e310d0a0d0a0d0a0d0a0d0a0d0a0d0a0d0a0d0a0d0a0d0a0d0a0d0a ...
[2016-11-20 16:27:39,488] [INFO] [base._test_info] -> Current test: 94
[2016-11-20 16:27:39,491] [INFO] [server.transmit] -> request(29): 474554202f696e6465782e68746d6c20485454502f312e310d0a0d0afe
[2016-11-20 16:27:40,431] [ERROR] [tcp.pre_test] -> Error: Traceback (most recent call last):
  File "/usr/local/lib/python2.7/dist-packages/katnip/targets/tcp.py", line 57, in pre_test
    sock.connect((self.host, self.port))
  File "/usr/lib/python2.7/socket.py", line 224, in meth
    return getattr(self._sock,name)(*args)
error: [Errno 111] Connection refused

[2016-11-20 16:27:40,431] [ERROR] [tcp.pre_test] -> Failed to connect to target server, retrying...
[2016-11-20 16:27:41,435] [INFO] [base._test_info] -> Current test: 95
[2016-11-20 16:27:41,437] [INFO] [server.transmit] -> request(29): 474554202f696e6465782e68746d6c20485454502f312e31000d0a0d0a
[2016-11-20 16:27:41,852] [INFO] [base._test_info] -> Current test: 96
[2016-11-20 16:27:41,854] [INFO] [server.transmit] -> request(29): 474554202f696e6465782e68746d6c20485454502f312e310d0a000d0a
[2016-11-20 16:27:42,792] [ERROR] [tcp.pre_test] -> Error: Traceback (most recent call last):
  File "/usr/local/lib/python2.7/dist-packages/katnip/targets/tcp.py", line 57, in pre_test
    sock.connect((self.host, self.port))
  File "/usr/lib/python2.7/socket.py", line 224, in meth
    return getattr(self._sock,name)(*args)
error: [Errno 111] Connection refused

[2016-11-20 16:27:42,793] [ERROR] [tcp.pre_test] -> Failed to connect to target server, retrying...
[2016-11-20 16:27:43,797] [INFO] [base._test_info] -> Current test: 97
[2016-11-20 16:27:43,798] [INFO] [server.transmit] -> request(29): 474554202f696e6465782e68746d6c20485454502f312e310d0a0d0a00
[2016-11-20 16:27:44,212] [INFO] [base._test_info] -> Current test: 98
[2016-11-20 16:27:44,214] [INFO] [server.transmit] -> request(28): 474554202f696e6465782e68746d6c20485454502f312e3120202020
[2016-11-20 16:27:45,142] [ERROR] [tcp.pre_test] -> Error: Traceback (most recent call last):
  File "/usr/local/lib/python2.7/dist-packages/katnip/targets/tcp.py", line 57, in pre_test
    sock.connect((self.host, self.port))
  File "/usr/lib/python2.7/socket.py", line 224, in meth
    return getattr(self._sock,name)(*args)
error: [Errno 111] Connection refused

[2016-11-20 16:27:45,143] [ERROR] [tcp.pre_test] -> Failed to connect to target server, retrying...
[2016-11-20 16:27:46,148] [INFO] [base._test_info] -> Current test: 99
[2016-11-20 16:27:46,150] [INFO] [server.transmit] -> request(28): 474554202f696e6465782e68746d6c20485454502f312e3109090909
[2016-11-20 16:27:46,571] [INFO] [base._test_info] -> Current test: 100
[2016-11-20 16:27:46,573] [INFO] [server.transmit] -> request(28): 474554202f696e6465782e68746d6c20485454502f312e3121212121
[2016-11-20 16:27:47,503] [ERROR] [tcp.pre_test] -> Error: Traceback (most recent call last):
  File "/usr/local/lib/python2.7/dist-packages/katnip/targets/tcp.py", line 57, in pre_test
    sock.connect((self.host, self.port))
  File "/usr/lib/python2.7/socket.py", line 224, in meth
    return getattr(self._sock,name)(*args)
error: [Errno 111] Connection refused

[2016-11-20 16:27:47,505] [ERROR] [tcp.pre_test] -> Failed to connect to target server, retrying...
[2016-11-20 16:27:48,509] [INFO] [base._test_info] -> Current test: 101
[2016-11-20 16:27:48,510] [INFO] [server.transmit] -> request(28): 474554202f696e6465782e68746d6c20485454502f312e3140404040
[2016-11-20 16:27:48,929] [INFO] [base._test_info] -> Current test: 102
[2016-11-20 16:27:48,930] [INFO] [server.transmit] -> request(28): 474554202f696e6465782e68746d6c20485454502f312e3123232323
[2016-11-20 16:27:49,856] [ERROR] [tcp.pre_test] -> Error: Traceback (most recent call last):
  File "/usr/local/lib/python2.7/dist-packages/katnip/targets/tcp.py", line 57, in pre_test
    sock.connect((self.host, self.port))
  File "/usr/lib/python2.7/socket.py", line 224, in meth
    return getattr(self._sock,name)(*args)
error: [Errno 111] Connection refused

[2016-11-20 16:27:49,859] [ERROR] [tcp.pre_test] -> Failed to connect to target server, retrying...
[2016-11-20 16:27:50,866] [INFO] [base._test_info] -> Current test: 103
[2016-11-20 16:27:50,870] [INFO] [server.transmit] -> request(28): 474554202f696e6465782e68746d6c20485454502f312e3124242424
[2016-11-20 16:27:51,286] [INFO] [base._test_info] -> Current test: 104
[2016-11-20 16:27:51,288] [INFO] [server.transmit] -> request(28): 474554202f696e6465782e68746d6c20485454502f312e3125252525
[2016-11-20 16:27:52,221] [ERROR] [tcp.pre_test] -> Error: Traceback (most recent call last):
  File "/usr/local/lib/python2.7/dist-packages/katnip/targets/tcp.py", line 57, in pre_test
    sock.connect((self.host, self.port))
  File "/usr/lib/python2.7/socket.py", line 224, in meth
    return getattr(self._sock,name)(*args)
error: [Errno 111] Connection refused

[2016-11-20 16:27:52,222] [ERROR] [tcp.pre_test] -> Failed to connect to target server, retrying...
[2016-11-20 16:27:53,226] [INFO] [base._test_info] -> Current test: 105
[2016-11-20 16:27:53,228] [INFO] [server.transmit] -> request(28): 474554202f696e6465782e68746d6c20485454502f312e315e5e5e5e
[2016-11-20 16:27:53,650] [INFO] [base._test_info] -> Current test: 106
[2016-11-20 16:27:53,652] [INFO] [server.transmit] -> request(28): 474554202f696e6465782e68746d6c20485454502f312e3126262626
[2016-11-20 16:27:54,582] [ERROR] [tcp.pre_test] -> Error: Traceback (most recent call last):
  File "/usr/local/lib/python2.7/dist-packages/katnip/targets/tcp.py", line 57, in pre_test
    sock.connect((self.host, self.port))
  File "/usr/lib/python2.7/socket.py", line 224, in meth
    return getattr(self._sock,name)(*args)
error: [Errno 111] Connection refused

[2016-11-20 16:27:54,585] [ERROR] [tcp.pre_test] -> Failed to connect to target server, retrying...
[2016-11-20 16:27:55,590] [INFO] [base._test_info] -> Current test: 107
[2016-11-20 16:27:55,591] [INFO] [server.transmit] -> request(28): 474554202f696e6465782e68746d6c20485454502f312e312a2a2a2a
[2016-11-20 16:27:56,009] [INFO] [base._test_info] -> Current test: 108
[2016-11-20 16:27:56,012] [INFO] [server.transmit] -> request(28): 474554202f696e6465782e68746d6c20485454502f312e3128282828
[2016-11-20 16:27:56,956] [ERROR] [tcp.pre_test] -> Error: Traceback (most recent call last):
  File "/usr/local/lib/python2.7/dist-packages/katnip/targets/tcp.py", line 57, in pre_test
    sock.connect((self.host, self.port))
  File "/usr/lib/python2.7/socket.py", line 224, in meth
    return getattr(self._sock,name)(*args)
error: [Errno 111] Connection refused

[2016-11-20 16:27:56,957] [ERROR] [tcp.pre_test] -> Failed to connect to target server, retrying...
[2016-11-20 16:27:57,962] [INFO] [base._test_info] -> Current test: 109
[2016-11-20 16:27:57,963] [INFO] [server.transmit] -> request(28): 474554202f696e6465782e68746d6c20485454502f312e3129292929
[2016-11-20 16:27:58,383] [INFO] [base._test_info] -> Current test: 110
[2016-11-20 16:27:58,385] [INFO] [server.transmit] -> request(28): 474554202f696e6465782e68746d6c20485454502f312e312d2d2d2d
[2016-11-20 16:27:59,312] [ERROR] [tcp.pre_test] -> Error: Traceback (most recent call last):
  File "/usr/local/lib/python2.7/dist-packages/katnip/targets/tcp.py", line 57, in pre_test
    sock.connect((self.host, self.port))
  File "/usr/lib/python2.7/socket.py", line 224, in meth
    return getattr(self._sock,name)(*args)
error: [Errno 111] Connection refused

[2016-11-20 16:27:59,314] [ERROR] [tcp.pre_test] -> Failed to connect to target server, retrying...
[2016-11-20 16:28:00,319] [INFO] [base._test_info] -> Current test: 111
[2016-11-20 16:28:00,321] [INFO] [server.transmit] -> request(28): 474554202f696e6465782e68746d6c20485454502f312e315f5f5f5f
[2016-11-20 16:28:00,738] [INFO] [base._test_info] -> Current test: 112
[2016-11-20 16:28:00,742] [INFO] [server.transmit] -> request(28): 474554202f696e6465782e68746d6c20485454502f312e312b2b2b2b
[2016-11-20 16:28:01,666] [INFO] [base._test_info] -> Current test: 113
[2016-11-20 16:28:01,668] [INFO] [server.transmit] -> request(28): 474554202f696e6465782e68746d6c20485454502f312e313d3d3d3d
[2016-11-20 16:28:02,601] [ERROR] [tcp.pre_test] -> Error: Traceback (most recent call last):
  File "/usr/local/lib/python2.7/dist-packages/katnip/targets/tcp.py", line 57, in pre_test
    sock.connect((self.host, self.port))
  File "/usr/lib/python2.7/socket.py", line 224, in meth
    return getattr(self._sock,name)(*args)
error: [Errno 111] Connection refused

[2016-11-20 16:28:02,603] [ERROR] [tcp.pre_test] -> Failed to connect to target server, retrying...
[2016-11-20 16:28:03,608] [INFO] [base._test_info] -> Current test: 114
[2016-11-20 16:28:03,610] [INFO] [server.transmit] -> request(28): 474554202f696e6465782e68746d6c20485454502f312e313a3a3a3a
[2016-11-20 16:28:04,026] [INFO] [base._test_info] -> Current test: 115
[2016-11-20 16:28:04,028] [INFO] [server.transmit] -> request(28): 474554202f696e6465782e68746d6c20485454502f312e313b3b3b3b
[2016-11-20 16:28:04,959] [ERROR] [tcp.pre_test] -> Error: Traceback (most recent call last):
  File "/usr/local/lib/python2.7/dist-packages/katnip/targets/tcp.py", line 57, in pre_test
    sock.connect((self.host, self.port))
  File "/usr/lib/python2.7/socket.py", line 224, in meth
    return getattr(self._sock,name)(*args)
error: [Errno 111] Connection refused

[2016-11-20 16:28:04,961] [ERROR] [tcp.pre_test] -> Failed to connect to target server, retrying...
[2016-11-20 16:28:05,965] [INFO] [base._test_info] -> Current test: 116
[2016-11-20 16:28:05,966] [INFO] [server.transmit] -> request(28): 474554202f696e6465782e68746d6c20485454502f312e3127272727
[2016-11-20 16:28:06,382] [INFO] [base._test_info] -> Current test: 117
[2016-11-20 16:28:06,383] [INFO] [server.transmit] -> request(28): 474554202f696e6465782e68746d6c20485454502f312e3122222222
[2016-11-20 16:28:07,310] [ERROR] [tcp.pre_test] -> Error: Traceback (most recent call last):
  File "/usr/local/lib/python2.7/dist-packages/katnip/targets/tcp.py", line 57, in pre_test
    sock.connect((self.host, self.port))
  File "/usr/lib/python2.7/socket.py", line 224, in meth
    return getattr(self._sock,name)(*args)
error: [Errno 111] Connection refused

[2016-11-20 16:28:07,312] [ERROR] [tcp.pre_test] -> Failed to connect to target server, retrying...
[2016-11-20 16:28:08,318] [INFO] [base._test_info] -> Current test: 118
[2016-11-20 16:28:08,319] [INFO] [server.transmit] -> request(28): 474554202f696e6465782e68746d6c20485454502f312e312f2f2f2f
[2016-11-20 16:28:08,734] [INFO] [base._test_info] -> Current test: 119
[2016-11-20 16:28:08,738] [INFO] [server.transmit] -> request(28): 474554202f696e6465782e68746d6c20485454502f312e315c5c5c5c
[2016-11-20 16:28:09,660] [ERROR] [tcp.pre_test] -> Error: Traceback (most recent call last):
  File "/usr/local/lib/python2.7/dist-packages/katnip/targets/tcp.py", line 57, in pre_test
    sock.connect((self.host, self.port))
  File "/usr/lib/python2.7/socket.py", line 224, in meth
    return getattr(self._sock,name)(*args)
error: [Errno 111] Connection refused

[2016-11-20 16:28:09,661] [ERROR] [tcp.pre_test] -> Failed to connect to target server, retrying...
[2016-11-20 16:28:10,666] [INFO] [base._test_info] -> Current test: 120
[2016-11-20 16:28:10,667] [INFO] [server.transmit] -> request(28): 474554202f696e6465782e68746d6c20485454502f312e313f3f3f3f
[2016-11-20 16:28:11,084] [INFO] [base._test_info] -> Current test: 121
[2016-11-20 16:28:11,088] [INFO] [server.transmit] -> request(28): 474554202f696e6465782e68746d6c20485454502f312e313c3c3c3c
[2016-11-20 16:28:12,011] [ERROR] [tcp.pre_test] -> Error: Traceback (most recent call last):
  File "/usr/local/lib/python2.7/dist-packages/katnip/targets/tcp.py", line 57, in pre_test
    sock.connect((self.host, self.port))
  File "/usr/lib/python2.7/socket.py", line 224, in meth
    return getattr(self._sock,name)(*args)
error: [Errno 111] Connection refused

[2016-11-20 16:28:12,013] [ERROR] [tcp.pre_test] -> Failed to connect to target server, retrying...
[2016-11-20 16:28:13,017] [INFO] [base._test_info] -> Current test: 122
[2016-11-20 16:28:13,018] [INFO] [server.transmit] -> request(28): 474554202f696e6465782e68746d6c20485454502f312e313e3e3e3e
[2016-11-20 16:28:13,432] [INFO] [base._test_info] -> Current test: 123
[2016-11-20 16:28:13,434] [INFO] [server.transmit] -> request(28): 474554202f696e6465782e68746d6c20485454502f312e312e2e2e2e
[2016-11-20 16:28:14,358] [ERROR] [tcp.pre_test] -> Error: Traceback (most recent call last):
  File "/usr/local/lib/python2.7/dist-packages/katnip/targets/tcp.py", line 57, in pre_test
    sock.connect((self.host, self.port))
  File "/usr/lib/python2.7/socket.py", line 224, in meth
    return getattr(self._sock,name)(*args)
error: [Errno 111] Connection refused

[2016-11-20 16:28:14,360] [ERROR] [tcp.pre_test] -> Failed to connect to target server, retrying...
[2016-11-20 16:28:15,363] [INFO] [base._test_info] -> Current test: 124
[2016-11-20 16:28:15,365] [INFO] [server.transmit] -> request(28): 474554202f696e6465782e68746d6c20485454502f312e312c2c2c2c
[2016-11-20 16:28:15,779] [INFO] [base._test_info] -> Current test: 125
[2016-11-20 16:28:15,781] [INFO] [server.transmit] -> request(28): 474554202f696e6465782e68746d6c20485454502f312e310d0d0d0d
[2016-11-20 16:28:16,710] [ERROR] [tcp.pre_test] -> Error: Traceback (most recent call last):
  File "/usr/local/lib/python2.7/dist-packages/katnip/targets/tcp.py", line 57, in pre_test
    sock.connect((self.host, self.port))
  File "/usr/lib/python2.7/socket.py", line 224, in meth
    return getattr(self._sock,name)(*args)
error: [Errno 111] Connection refused

[2016-11-20 16:28:16,712] [ERROR] [tcp.pre_test] -> Failed to connect to target server, retrying...
[2016-11-20 16:28:17,716] [INFO] [base._test_info] -> Current test: 126
[2016-11-20 16:28:17,719] [INFO] [server.transmit] -> request(28): 474554202f696e6465782e68746d6c20485454502f312e310a0a0a0a
[2016-11-20 16:28:18,137] [INFO] [base._test_info] -> Current test: 127
[2016-11-20 16:28:18,139] [INFO] [server.transmit] -> request(40): 474554202f696e6465782e68746d6c20485454502f312e310d0a0d0a0d0a0d0a0d0a0d0a0d0a0d0a
[2016-11-20 16:28:19,075] [ERROR] [tcp.pre_test] -> Error: Traceback (most recent call last):
  File "/usr/local/lib/python2.7/dist-packages/katnip/targets/tcp.py", line 57, in pre_test
    sock.connect((self.host, self.port))
  File "/usr/lib/python2.7/socket.py", line 224, in meth
    return getattr(self._sock,name)(*args)
error: [Errno 111] Connection refused

[2016-11-20 16:28:19,076] [ERROR] [tcp.pre_test] -> Failed to connect to target server, retrying...
[2016-11-20 16:28:20,079] [INFO] [base._test_info] -> Current test: 128
[2016-11-20 16:28:20,081] [INFO] [server.transmit] -> request(48): 474554202f696e6465782e68746d6c20485454502f312e31090d0a090d0a090d0a090d0a090d0a090d0a090d0a090d0a
[2016-11-20 16:28:20,503] [INFO] [base._test_info] -> Current test: 129
[2016-11-20 16:28:20,506] [INFO] [server.transmit] -> request(24): 474554202f696e6465782e68746d6c20485454502f312e31
[2016-11-20 16:28:21,421] [INFO] [base._end_message] -> 
                         --------------------------------------------------
                         Finished fuzzing session
                         Target: TcpTarget

                         Tested 130 mutations
                         Mutation range: 0 to 129
                         Failure count: 0
                         --------------------------------------------------
            
