[2016-11-20 16:31:32,749] [INFO] [base._load_session] -> No session loaded
[2016-11-20 16:31:32,759] [INFO] [graph.hash] -> hash of template HTTP_GET_MONKEY_0 is 4168102103642212340
[2016-11-20 16:31:32,760] [INFO] [graph.hash] -> hash of model is -8069957684332539954
[2016-11-20 16:31:32,763] [INFO] [base._start_message] -> 
                 --------------------------------------------------
                 Starting fuzzing session
                 Target: TcpTarget
                 UI: WebInterface listening on 0.0.0.0:26000
                 Log: ./kittylogs/kitty_20161120-163132.log

                 Total possible mutation count: 39
                 Fuzzing the mutation range: 0 to 38
                 --------------------------------------------------
                                 Happy hacking
                 --------------------------------------------------
            
[2016-11-20 16:31:32,763] [INFO] [base.start] -> Performing environment test
[2016-11-20 16:31:32,785] [INFO] [base._test_info] -> Current test: -1
[2016-11-20 16:31:32,787] [INFO] [server.transmit] -> request(28): 474554202f696e6465782e68746d6c20485454502f312e310d0a0d0a
[2016-11-20 16:31:33,303] [INFO] [server._start] -> should keep running? True
[2016-11-20 16:31:33,318] [INFO] [base._test_info] -> Current test: 0
[2016-11-20 16:31:33,332] [INFO] [server.transmit] -> request(32): 474554202f696e6465782e68746d6c20485454502f312e310d0a0d0a0d0a0d0a
[2016-11-20 16:31:33,756] [INFO] [base._test_info] -> Current test: 1
[2016-11-20 16:31:33,757] [INFO] [server.transmit] -> request(64): 474554202f696e6465782e68746d6c20485454502f312e310d0a0d0a0d0a0d0a0d0a0d0a0d0a0d0a0d0a0d0a0d0a0d0a0d0a ...
[2016-11-20 16:31:34,687] [ERROR] [tcp.pre_test] -> Error: Traceback (most recent call last):
  File "/usr/local/lib/python2.7/dist-packages/katnip/targets/tcp.py", line 57, in pre_test
    sock.connect((self.host, self.port))
  File "/usr/lib/python2.7/socket.py", line 224, in meth
    return getattr(self._sock,name)(*args)
error: [Errno 111] Connection refused

[2016-11-20 16:31:34,689] [ERROR] [tcp.pre_test] -> Failed to connect to target server, retrying...
[2016-11-20 16:31:35,267] [ERROR] [server._start] -> Error occurred while fuzzing: AttributeError("'WebInterface' object has no attribute '_server'",)
[2016-11-20 16:31:35,269] [ERROR] [server._start] -> Traceback (most recent call last):
  File "/usr/local/lib/python2.7/dist-packages/kitty/fuzzers/server.py", line 43, in _start
    self._run_sequence(sequence)
  File "/usr/local/lib/python2.7/dist-packages/kitty/fuzzers/server.py", line 64, in _run_sequence
    self._pre_test()
  File "/usr/local/lib/python2.7/dist-packages/kitty/fuzzers/base.py", line 332, in _pre_test
    self.target.pre_test(self.model.current_index())
  File "/usr/local/lib/python2.7/dist-packages/katnip/targets/tcp.py", line 63, in pre_test
    time.sleep(1)
  File "/usr/local/lib/python2.7/dist-packages/kitty/fuzzers/base.py", line 504, in _exit_now
    self.stop()
  File "/usr/local/lib/python2.7/dist-packages/kitty/fuzzers/base.py", line 440, in stop
    self.user_interface.stop()
  File "/usr/local/lib/python2.7/dist-packages/kitty/interfaces/base.py", line 101, in stop
    self._stop()
  File "/usr/local/lib/python2.7/dist-packages/kitty/interfaces/web.py", line 297, in _stop
    self._server.shutdown()
AttributeError: 'WebInterface' object has no attribute '_server'

[2016-11-20 16:31:35,270] [INFO] [base._end_message] -> 
                         --------------------------------------------------
                         Finished fuzzing session
                         Target: TcpTarget

                         Tested 3 mutations
                         Mutation range: 0 to 2
                         Failure count: 0
                         --------------------------------------------------
            
